Workbook

Sheet Temporada Alta PPT
T2: 2206451.6 | U2: 429032.26 | V2: 2206451.6 | W2: 3064516.1 | X2: 0.4 | Z2: 310000 | AB2: 3519400
C3: =SUM(C5:C114) -> 43 | F3: =SUM(F5:F114) -> 7
A4: Modelo PDV 1 | B4: Tipo | C4: Q | D4: Modelo PDV 2 | E4: Tipo | F4: Q | G4: Sup. Días Se, | H4: Tipo Supervisión | I4: Zona/Ciudad | J4: Cadena | K4: Sucursal | L4: Venta Promedio | M4: Incremento de Venta | N4: Venta Total | O4: Comisión Retail | P4: Margen Tienda | Q4: Supervisión | R4: Vendedor / Reposición 01 | S4: Vendedor / Reposición 02 | T4: Bodegaje | U4: Packing | V4: Picking | W4: Transporte | X4: Costo Mercadería | Y4: Merma | Z4: Muebles | AA4: Margen Operacional | AB4: Gastos de Administración | AC4: Resultado Actual | AD4: Resultado Modelo | AE4: Diferencial
A5: Vendedor 1/2 Full | B5: Outsourcing | C5: 1 | D5: Vendedor 1/2 3 días | E5: Outsourcing | F5: 1 | G5: 2 | H5: Supervisor Regiones | I5: Viña del Mar | J5: Ripley | K5: Marina Arauco | L5: =IFERROR(VLOOKUP(CONCATENATE(J5,K5),Ventas!D:H,4,0),0) -> 3692307.7 | M5: =IF(SUM(C5,F5)>0,L5*0.1,0) -> 369230.77 | N5: =SUM(L5:M5) -> 4061538.5 | O5: =N5*IFERROR(VLOOKUP(J5,Tabla11[],3,0),0) -> 1421538.5 | P5: =N5-O5 -> 2640000 | Q5: =IFERROR(G5/SUMIF(I:I,I5,G:G),0)*VLOOKUP(H5,Modelos[],14,0)+IFERROR(G5/SUMIF(I:I,I5,G:G),0)*VLOOKUP(I5,Tabla13[],2,0) -> 82422.042 | R5: =IFERROR(VLOOKUP(A5,Modelos[],IF(B5="EST",15,14),0),0)*C5 -> 310333.79 | S5: =IFERROR(VLOOKUP(D5,Modelos[],IF(E5="EST",15,14),0),0)*F5 -> 204526.8 | T5: =IF($L5<0,0,IFERROR((T$2*IFERROR(VLOOKUP(J5,Tabla11[],2,0),0))*($L5/SUM($L$5:$L$46)),0)) -> 21188.574 | U5: =IF($L5<0,0,IFERROR((U$2*IFERROR(VLOOKUP(J5,Tabla11[],2,0),0))*($L5/SUM($L$5:$L$46)),0)) -> 4120.0005 | V5: =IF($L5<0,0,IFERROR((V$2*IFERROR(VLOOKUP(J5,Tabla11[],2,0),0))*($L5/SUM($L$5:$L$46)),0)) -> 21188.574 | W5: =IF($L5<0,0,IFERROR((W$2*IFERROR(VLOOKUP(J5,Tabla11[],2,0),0))*($L5/SUM($L$5:$L$46)),0)) -> 29428.575 | X5: =P5*$X$2 -> 1056000 | Y5: =+X5*IFERROR(VLOOKUP(J5,Tabla11[],4,0),0) -> 158400 | Z5: =IF(L5>0,$Z$2/12,0) -> 25833.333 | AA5: =P5-SUM(Q5:Z5) -> 726558.31 | AB5: =IF($L5<0,0,IFERROR((AB$2*IFERROR(VLOOKUP(J5,Tabla11[],2,0),0))*($L5/SUM($L$5:$L$46)),0)) -> 33796.829 | AC5: =L5-L5*IFERROR(VLOOKUP(J5,Tabla11[],3,0),0)-Q5-T5-U5-V5-W5-L5*$X$2-(L5*$X$2)*IFERROR(VLOOKUP(J5,Tabla11[],4,0),0)-AB5-Z5 -> 483560.53 | AD5: =AA5-AB5 -> 692761.48 | AE5: =ROUND(AD5-AC5,9) -> 209200.95
A6: Vendedor 1/2 3 días | B6: Outsourcing | C6: 1 | E6: Outsourcing | G6: 0 | H6: Supervisor Regiones | I6: Puerto Montt | J6: Ripley | K6: M.Costanera P.Montt | L6: =IFERROR(VLOOKUP(CONCATENATE(J6,K6),Ventas!D:H,4,0),0) -> 2895783.1 | M6: =IF(SUM(C6,F6)>0,L6*0.1,0) -> 289578.31 | N6: =SUM(L6:M6) -> 3185361.4 | O6: =N6*IFERROR(VLOOKUP(J6,Tabla11[],3,0),0) -> 1114876.5 | P6: =N6-O6 -> 2070484.9 | Q6: =IFERROR(G6/SUMIF(I:I,I6,G:G),0)*VLOOKUP(H6,Modelos[],14,0)+IFERROR(G6/SUMIF(I:I,I6,G:G),0)*VLOOKUP(I6,Tabla13[],2,0) -> 0 | R6: =IFERROR(VLOOKUP(A6,Modelos[],IF(B6="EST",15,14),0),0)*C6 -> 204526.8 | S6: =IFERROR(VLOOKUP(D6,Modelos[],IF(E6="EST",15,14),0),0)*F6 -> 0 | T6: =IF($L6<0,0,IFERROR((T$2*IFERROR(VLOOKUP(J6,Tabla11[],2,0),0))*($L6/SUM($L$5:$L$46)),0)) -> 16617.66 | U6: =IF($L6<0,0,IFERROR((U$2*IFERROR(VLOOKUP(J6,Tabla11[],2,0),0))*($L6/SUM($L$5:$L$46)),0)) -> 3231.2117 | V6: =IF($L6<0,0,IFERROR((V$2*IFERROR(VLOOKUP(J6,Tabla11[],2,0),0))*($L6/SUM($L$5:$L$46)),0)) -> 16617.66 | W6: =IF($L6<0,0,IFERROR((W$2*IFERROR(VLOOKUP(J6,Tabla11[],2,0),0))*($L6/SUM($L$5:$L$46)),0)) -> 23080.083 | X6: =P6*$X$2 -> 828193.96 | Y6: =+X6*IFERROR(VLOOKUP(J6,Tabla11[],4,0),0) -> 124229.09 | Z6: =IF(L6>0,$Z$2/12,0) -> 25833.333 | AA6: =P6-SUM(Q6:Z6) -> 828155.1 | AB6: =IF($L6<0,0,IFERROR((AB$2*IFERROR(VLOOKUP(J6,Tabla11[],2,0),0))*($L6/SUM($L$5:$L$46)),0)) -> 26505.994 | AC6: =L6-L6*IFERROR(VLOOKUP(J6,Tabla11[],3,0),0)-Q6-T6-U6-V6-W6-L6*$X$2-(L6*$X$2)*IFERROR(VLOOKUP(J6,Tabla11[],4,0),0)-AB6-Z6 -> 438312.84 | AD6: =AA6-AB6 -> 801649.1 | AE6: =ROUND(AD6-AC6,9) -> 363336.26
A7: Vendedor 1/2 Full | B7: Outsourcing | C7: 1 | D7: Vendedor 1/2 3 días | E7: Outsourcing | F7: 1 | G7: 1 | H7: Supervisor Regiones | I7: VI-VII | J7: Ripley | K7: Talca | L7: =IFERROR(VLOOKUP(CONCATENATE(J7,K7),Ventas!D:H,4,0),0) -> 2875784.6 | M7: =IF(SUM(C7,F7)>0,L7*0.1,0) -> 287578.46 | N7: =SUM(L7:M7) -> 3163363.1 | O7: =N7*IFERROR(VLOOKUP(J7,Tabla11[],3,0),0) -> 1107177.1 | P7: =N7-O7 -> 2056186 | Q7: =IFERROR(G7/SUMIF(I:I,I7,G:G),0)*VLOOKUP(H7,Modelos[],14,0)+IFERROR(G7/SUMIF(I:I,I7,G:G),0)*VLOOKUP(I7,Tabla13[],2,0) -> 51647.612 | R7: =IFERROR(VLOOKUP(A7,Modelos[],IF(B7="EST",15,14),0),0)*C7 -> 310333.79 | S7: =IFERROR(VLOOKUP(D7,Modelos[],IF(E7="EST",15,14),0),0)*F7 -> 204526.8 | T7: =IF($L7<0,0,IFERROR((T$2*IFERROR(VLOOKUP(J7,Tabla11[],2,0),0))*($L7/SUM($L$5:$L$46)),0)) -> 16502.897 | U7: =IF($L7<0,0,IFERROR((U$2*IFERROR(VLOOKUP(J7,Tabla11[],2,0),0))*($L7/SUM($L$5:$L$46)),0)) -> 3208.8967 | V7: =IF($L7<0,0,IFERROR((V$2*IFERROR(VLOOKUP(J7,Tabla11[],2,0),0))*($L7/SUM($L$5:$L$46)),0)) -> 16502.897 | W7: =IF($L7<0,0,IFERROR((W$2*IFERROR(VLOOKUP(J7,Tabla11[],2,0),0))*($L7/SUM($L$5:$L$46)),0)) -> 22920.691 | X7: =P7*$X$2 -> 822474.4 | Y7: =+X7*IFERROR(VLOOKUP(J7,Tabla11[],4,0),0) -> 123371.16 | Z7: =IF(L7>0,$Z$2/12,0) -> 25833.333 | AA7: =P7-SUM(Q7:Z7) -> 458863.52 | AB7: =IF($L7<0,0,IFERROR((AB$2*IFERROR(VLOOKUP(J7,Tabla11[],2,0),0))*($L7/SUM($L$5:$L$46)),0)) -> 26322.942 | AC7: =L7-L7*IFERROR(VLOOKUP(J7,Tabla11[],3,0),0)-Q7-T7-U7-V7-W7-L7*$X$2-(L7*$X$2)*IFERROR(VLOOKUP(J7,Tabla11[],4,0),0)-AB7-Z7 -> 383459.81 | AD7: =AA7-AB7 -> 432540.58 | AE7: =ROUND(AD7-AC7,9) -> 49080.774
A8: Vendedor 1/2 Full | B8: Outsourcing | C8: 1 | E8: Outsourcing | G8: 3 | H8: Supervisor Part | I8: Temuco | J8: Ripley | K8: Temuco | L8: =IFERROR(VLOOKUP(CONCATENATE(J8,K8),Ventas!D:H,4,0),0) -> 2814513.8 | M8: =IF(SUM(C8,F8)>0,L8*0.1,0) -> 281451.38 | N8: =SUM(L8:M8) -> 3095965.2 | O8: =N8*IFERROR(VLOOKUP(J8,Tabla11[],3,0),0) -> 1083587.8 | P8: =N8-O8 -> 2012377.4 | Q8: =IFERROR(G8/SUMIF(I:I,I8,G:G),0)*VLOOKUP(H8,Modelos[],14,0)+IFERROR(G8/SUMIF(I:I,I8,G:G),0)*VLOOKUP(I8,Tabla13[],2,0) -> 65246.163 | R8: =IFERROR(VLOOKUP(A8,Modelos[],IF(B8="EST",15,14),0),0)*C8 -> 310333.79 | S8: =IFERROR(VLOOKUP(D8,Modelos[],IF(E8="EST",15,14),0),0)*F8 -> 0 | T8: =IF($L8<0,0,IFERROR((T$2*IFERROR(VLOOKUP(J8,Tabla11[],2,0),0))*($L8/SUM($L$5:$L$46)),0)) -> 16151.291 | U8: =IF($L8<0,0,IFERROR((U$2*IFERROR(VLOOKUP(J8,Tabla11[],2,0),0))*($L8/SUM($L$5:$L$46)),0)) -> 3140.5287 | V8: =IF($L8<0,0,IFERROR((V$2*IFERROR(VLOOKUP(J8,Tabla11[],2,0),0))*($L8/SUM($L$5:$L$46)),0)) -> 16151.291 | W8: =IF($L8<0,0,IFERROR((W$2*IFERROR(VLOOKUP(J8,Tabla11[],2,0),0))*($L8/SUM($L$5:$L$46)),0)) -> 22432.348 | X8: =P8*$X$2 -> 804950.96 | Y8: =+X8*IFERROR(VLOOKUP(J8,Tabla11[],4,0),0) -> 120742.64 | Z8: =IF(L8>0,$Z$2/12,0) -> 25833.333 | AA8: =P8-SUM(Q8:Z8) -> 627395.05 | AB8: =IF($L8<0,0,IFERROR((AB$2*IFERROR(VLOOKUP(J8,Tabla11[],2,0),0))*($L8/SUM($L$5:$L$46)),0)) -> 25762.111 | AC8: =L8-L8*IFERROR(VLOOKUP(J8,Tabla11[],3,0),0)-Q8-T8-U8-V8-W8-L8*$X$2-(L8*$X$2)*IFERROR(VLOOKUP(J8,Tabla11[],4,0),0)-AB8-Z8 -> 360040.57 | AD8: =AA8-AB8 -> 601632.94 | AE8: =ROUND(AD8-AC8,9) -> 241592.38
A9: Vendedor 1/2 Full | B9: Outsourcing | C9: 1 | E9: Outsourcing | G9: 3 | H9: Supervisor Regiones | I9: V° Interior | J9: Ripley | K9: La Calera | L9: =IFERROR(VLOOKUP(CONCATENATE(J9,K9),Ventas!D:H,4,0),0) -> 2704320 | M9: =IF(SUM(C9,F9)>0,L9*0.1,0) -> 270432 | N9: =SUM(L9:M9) -> 2974752 | O9: =N9*IFERROR(VLOOKUP(J9,Tabla11[],3,0),0) -> 1041163.2 | P9: =N9-O9 -> 1933588.8 | Q9: =IFERROR(G9/SUMIF(I:I,I9,G:G),0)*VLOOKUP(H9,Modelos[],14,0)+IFERROR(G9/SUMIF(I:I,I9,G:G),0)*VLOOKUP(I9,Tabla13[],2,0) -> 179573.44 | R9: =IFERROR(VLOOKUP(A9,Modelos[],IF(B9="EST",15,14),0),0)*C9 -> 310333.79 | S9: =IFERROR(VLOOKUP(D9,Modelos[],IF(E9="EST",15,14),0),0)*F9 -> 0 | T9: =IF($L9<0,0,IFERROR((T$2*IFERROR(VLOOKUP(J9,Tabla11[],2,0),0))*($L9/SUM($L$5:$L$46)),0)) -> 15518.935 | U9: =IF($L9<0,0,IFERROR((U$2*IFERROR(VLOOKUP(J9,Tabla11[],2,0),0))*($L9/SUM($L$5:$L$46)),0)) -> 3017.5707 | V9: =IF($L9<0,0,IFERROR((V$2*IFERROR(VLOOKUP(J9,Tabla11[],2,0),0))*($L9/SUM($L$5:$L$46)),0)) -> 15518.935 | W9: =IF($L9<0,0,IFERROR((W$2*IFERROR(VLOOKUP(J9,Tabla11[],2,0),0))*($L9/SUM($L$5:$L$46)),0)) -> 21554.077 | X9: =P9*$X$2 -> 773435.52 | Y9: =+X9*IFERROR(VLOOKUP(J9,Tabla11[],4,0),0) -> 116015.33 | Z9: =IF(L9>0,$Z$2/12,0) -> 25833.333 | AA9: =P9-SUM(Q9:Z9) -> 472787.87 | AB9: =IF($L9<0,0,IFERROR((AB$2*IFERROR(VLOOKUP(J9,Tabla11[],2,0),0))*($L9/SUM($L$5:$L$46)),0)) -> 24753.473 | AC9: =L9-L9*IFERROR(VLOOKUP(J9,Tabla11[],3,0),0)-Q9-T9-U9-V9-W9-L9*$X$2-(L9*$X$2)*IFERROR(VLOOKUP(J9,Tabla11[],4,0),0)-AB9-Z9 -> 228051.03 | AD9: =AA9-AB9 -> 448034.4 | AE9: =ROUND(AD9-AC9,9) -> 219983.36
B10: Outsourcing | E10: Outsourcing | G10: 3 | H10: Supervisor Regiones | I10: Concepción | J10: Ripley | K10: Mall Concepcion | L10: =IFERROR(VLOOKUP(CONCATENATE(J10,K10),Ventas!D:H,4,0),0) -> 2604672.3 | M10: =IF(SUM(C10,F10)>0,L10*0.1,0) -> 0 | N10: =SUM(L10:M10) -> 2604672.3 | O10: =N10*IFERROR(VLOOKUP(J10,Tabla11[],3,0),0) -> 911635.31 | P10: =N10-O10 -> 1693037 | Q10: =IFERROR(G10/SUMIF(I:I,I10,G:G),0)*VLOOKUP(H10,Modelos[],14,0)+IFERROR(G10/SUMIF(I:I,I10,G:G),0)*VLOOKUP(I10,Tabla13[],2,0) -> 106001.17 | R10: =IFERROR(VLOOKUP(A10,Modelos[],IF(B10="EST",15,14),0),0)*C10 -> 0 | S10: =IFERROR(VLOOKUP(D10,Modelos[],IF(E10="EST",15,14),0),0)*F10 -> 0 | T10: =IF($L10<0,0,IFERROR((T$2*IFERROR(VLOOKUP(J10,Tabla11[],2,0),0))*($L10/SUM($L$5:$L$46)),0)) -> 14947.1 | U10: =IF($L10<0,0,IFERROR((U$2*IFERROR(VLOOKUP(J10,Tabla11[],2,0),0))*($L10/SUM($L$5:$L$46)),0)) -> 2906.3805 | V10: =IF($L10<0,0,IFERROR((V$2*IFERROR(VLOOKUP(J10,Tabla11[],2,0),0))*($L10/SUM($L$5:$L$46)),0)) -> 14947.1 | W10: =IF($L10<0,0,IFERROR((W$2*IFERROR(VLOOKUP(J10,Tabla11[],2,0),0))*($L10/SUM($L$5:$L$46)),0)) -> 20759.861 | X10: =P10*$X$2 -> 677214.8 | Y10: =+X10*IFERROR(VLOOKUP(J10,Tabla11[],4,0),0) -> 101582.22 | Z10: =IF(L10>0,$Z$2/12,0) -> 25833.333 | AA10: =P10-SUM(Q10:Z10) -> 728845.03 | AB10: =IF($L10<0,0,IFERROR((AB$2*IFERROR(VLOOKUP(J10,Tabla11[],2,0),0))*($L10/SUM($L$5:$L$46)),0)) -> 23841.367 | AC10: =L10-L10*IFERROR(VLOOKUP(J10,Tabla11[],3,0),0)-Q10-T10-U10-V10-W10-L10*$X$2-(L10*$X$2)*IFERROR(VLOOKUP(J10,Tabla11[],4,0),0)-AB10-Z10 -> 285651.42 | AD10: =AA10-AB10 -> 705003.66 | AE10: =ROUND(AD10-AC10,9) -> 419352.24
A11: Vendedor 1/2 2 días | B11: Outsourcing | C11: 1 | E11: Outsourcing | G11: 2 | H11: Supervisor Regiones | I11: V° Interior | J11: Ripley | K11: Los Andes | L11: =IFERROR(VLOOKUP(CONCATENATE(J11,K11),Ventas!D:H,4,0),0) -> 2542166.2 | M11: =IF(SUM(C11,F11)>0,L11*0.1,0) -> 254216.62 | N11: =SUM(L11:M11) -> 2796382.8 | O11: =N11*IFERROR(VLOOKUP(J11,Tabla11[],3,0),0) -> 978733.97 | P11: =N11-O11 -> 1817648.8 | Q11: =IFERROR(G11/SUMIF(I:I,I11,G:G),0)*VLOOKUP(H11,Modelos[],14,0)+IFERROR(G11/SUMIF(I:I,I11,G:G),0)*VLOOKUP(I11,Tabla13[],2,0) -> 119715.63 | R11: =IFERROR(VLOOKUP(A11,Modelos[],IF(B11="EST",15,14),0),0)*C11 -> 154393.47 | S11: =IFERROR(VLOOKUP(D11,Modelos[],IF(E11="EST",15,14),0),0)*F11 -> 0 | T11: =IF($L11<0,0,IFERROR((T$2*IFERROR(VLOOKUP(J11,Tabla11[],2,0),0))*($L11/SUM($L$5:$L$46)),0)) -> 14588.404 | U11: =IF($L11<0,0,IFERROR((U$2*IFERROR(VLOOKUP(J11,Tabla11[],2,0),0))*($L11/SUM($L$5:$L$46)),0)) -> 2836.6341 | V11: =IF($L11<0,0,IFERROR((V$2*IFERROR(VLOOKUP(J11,Tabla11[],2,0),0))*($L11/SUM($L$5:$L$46)),0)) -> 14588.404 | W11: =IF($L11<0,0,IFERROR((W$2*IFERROR(VLOOKUP(J11,Tabla11[],2,0),0))*($L11/SUM($L$5:$L$46)),0)) -> 20261.672 | X11: =P11*$X$2 -> 727059.52 | Y11: =+X11*IFERROR(VLOOKUP(J11,Tabla11[],4,0),0) -> 109058.93 | Z11: =IF(L11>0,$Z$2/12,0) -> 25833.333 | AA11: =P11-SUM(Q11:Z11) -> 629312.81 | AB11: =IF($L11<0,0,IFERROR((AB$2*IFERROR(VLOOKUP(J11,Tabla11[],2,0),0))*($L11/SUM($L$5:$L$46)),0)) -> 23269.229 | AC11: =L11-L11*IFERROR(VLOOKUP(J11,Tabla11[],3,0),0)-Q11-T11-U11-V11-W11-L11*$X$2-(L11*$X$2)*IFERROR(VLOOKUP(J11,Tabla11[],4,0),0)-AB11-Z11 -> 261918.27 | AD11: =AA11-AB11 -> 606043.58 | AE11: =ROUND(AD11-AC11,9) -> 344125.32
A12: Vendedor Full | B12: Outsourcing | C12: 1 | D12: Vendedor 2 días | E12: Outsourcing | F12: 1 | G12: 2 | H12: Supervisor Santiago | I12: Santiago 01 | J12: Ripley | K12: Costanera Center | L12: =IFERROR(VLOOKUP(CONCATENATE(J12,K12),Ventas!D:H,4,0),0) -> 2331083.1 | M12: =IF(SUM(C12,F12)>0,L12*0.1,0) -> 233108.31 | N12: =SUM(L12:M12) -> 2564191.4 | O12: =N12*IFERROR(VLOOKUP(J12,Tabla11[],3,0),0) -> 897466.98 | P12: =N12-O12 -> 1666724.4 | Q12: =IFERROR(G12/SUMIF(I:I,I12,G:G),0)*VLOOKUP(H12,Modelos[],14,0)+IFERROR(G12/SUMIF(I:I,I12,G:G),0)*VLOOKUP(I12,Tabla13[],2,0) -> 46336.658 | R12: =IFERROR(VLOOKUP(A12,Modelos[],IF(B12="EST",15,14),0),0)*C12 -> 598680.59 | S12: =IFERROR(VLOOKUP(D12,Modelos[],IF(E12="EST",15,14),0),0)*F12 -> 281148.89 | T12: =IF($L12<0,0,IFERROR((T$2*IFERROR(VLOOKUP(J12,Tabla11[],2,0),0))*($L12/SUM($L$5:$L$46)),0)) -> 13377.088 | U12: =IF($L12<0,0,IFERROR((U$2*IFERROR(VLOOKUP(J12,Tabla11[],2,0),0))*($L12/SUM($L$5:$L$46)),0)) -> 2601.1005 | V12: =IF($L12<0,0,IFERROR((V$2*IFERROR(VLOOKUP(J12,Tabla11[],2,0),0))*($L12/SUM($L$5:$L$46)),0)) -> 13377.088 | W12: =IF($L12<0,0,IFERROR((W$2*IFERROR(VLOOKUP(J12,Tabla11[],2,0),0))*($L12/SUM($L$5:$L$46)),0)) -> 18579.289 | X12: =P12*$X$2 -> 666689.76 | Y12: =+X12*IFERROR(VLOOKUP(J12,Tabla11[],4,0),0) -> 100003.46 | Z12: =IF(L12>0,$Z$2/12,0) -> 25833.333 | AA12: =P12-SUM(Q12:Z12) -> -99902.861 | AB12: =IF($L12<0,0,IFERROR((AB$2*IFERROR(VLOOKUP(J12,Tabla11[],2,0),0))*($L12/SUM($L$5:$L$46)),0)) -> 21337.121 | AC12: =L12-L12*IFERROR(VLOOKUP(J12,Tabla11[],3,0),0)-Q12-T12-U12-V12-W12-L12*$X$2-(L12*$X$2)*IFERROR(VLOOKUP(J12,Tabla11[],4,0),0)-AB12-Z12 -> 301464.11 | AD12: =AA12-AB12 -> -121239.98 | AE12: =ROUND(AD12-AC12,9) -> -422704.09
A13: Vendedor 1/2 3 días | B13: Outsourcing | C13: 1 | E13: Outsourcing | G13: 3 | H13: Supervisor Santiago | I13: Santiago 02 | J13: Ripley | K13: Florida Center | L13: =IFERROR(VLOOKUP(CONCATENATE(J13,K13),Ventas!D:H,4,0),0) -> 2069249.2 | M13: =IF(SUM(C13,F13)>0,L13*0.1,0) -> 206924.92 | N13: =SUM(L13:M13) -> 2276174.2 | O13: =N13*IFERROR(VLOOKUP(J13,Tabla11[],3,0),0) -> 796660.95 | P13: =N13-O13 -> 1479513.2 | Q13: =IFERROR(G13/SUMIF(I:I,I13,G:G),0)*VLOOKUP(H13,Modelos[],14,0)+IFERROR(G13/SUMIF(I:I,I13,G:G),0)*VLOOKUP(I13,Tabla13[],2,0) -> 69504.988 | R13: =IFERROR(VLOOKUP(A13,Modelos[],IF(B13="EST",15,14),0),0)*C13 -> 204526.8 | S13: =IFERROR(VLOOKUP(D13,Modelos[],IF(E13="EST",15,14),0),0)*F13 -> 0 | T13: =IF($L13<0,0,IFERROR((T$2*IFERROR(VLOOKUP(J13,Tabla11[],2,0),0))*($L13/SUM($L$5:$L$46)),0)) -> 11874.536 | U13: =IF($L13<0,0,IFERROR((U$2*IFERROR(VLOOKUP(J13,Tabla11[],2,0),0))*($L13/SUM($L$5:$L$46)),0)) -> 2308.9375 | V13: =IF($L13<0,0,IFERROR((V$2*IFERROR(VLOOKUP(J13,Tabla11[],2,0),0))*($L13/SUM($L$5:$L$46)),0)) -> 11874.536 | W13: =IF($L13<0,0,IFERROR((W$2*IFERROR(VLOOKUP(J13,Tabla11[],2,0),0))*($L13/SUM($L$5:$L$46)),0)) -> 16492.411 | X13: =P13*$X$2 -> 591805.28 | Y13: =+X13*IFERROR(VLOOKUP(J13,Tabla11[],4,0),0) -> 88770.792 | Z13: =IF(L13>0,$Z$2/12,0) -> 25833.333 | AA13: =P13-SUM(Q13:Z13) -> 456521.59 | AB13: =IF($L13<0,0,IFERROR((AB$2*IFERROR(VLOOKUP(J13,Tabla11[],2,0),0))*($L13/SUM($L$5:$L$46)),0)) -> 18940.475 | AC13: =L13-L13*IFERROR(VLOOKUP(J13,Tabla11[],3,0),0)-Q13-T13-U13-V13-W13-L13*$X$2-(L13*$X$2)*IFERROR(VLOOKUP(J13,Tabla11[],4,0),0)-AB13-Z13 -> 236328.14 | AD13: =AA13-AB13 -> 437581.11 | AE13: =ROUND(AD13-AC13,9) -> 201252.97
A14: Vendedor 1/2 3 días | B14: Outsourcing | C14: 1 | E14: Outsourcing | G14: 2 | H14: Supervisor Santiago | I14: Santiago 01 | J14: Ripley | K14: Plaza Egana | L14: =IFERROR(VLOOKUP(CONCATENATE(J14,K14),Ventas!D:H,4,0),0) -> 1873333.8 | M14: =IF(SUM(C14,F14)>0,L14*0.1,0) -> 187333.38 | N14: =SUM(L14:M14) -> 2060667.2 | O14: =N14*IFERROR(VLOOKUP(J14,Tabla11[],3,0),0) -> 721233.53 | P14: =N14-O14 -> 1339433.7 | Q14: =IFERROR(G14/SUMIF(I:I,I14,G:G),0)*VLOOKUP(H14,Modelos[],14,0)+IFERROR(G14/SUMIF(I:I,I14,G:G),0)*VLOOKUP(I14,Tabla13[],2,0) -> 46336.658 | R14: =IFERROR(VLOOKUP(A14,Modelos[],IF(B14="EST",15,14),0),0)*C14 -> 204526.8 | S14: =IFERROR(VLOOKUP(D14,Modelos[],IF(E14="EST",15,14),0),0)*F14 -> 0 | T14: =IF($L14<0,0,IFERROR((T$2*IFERROR(VLOOKUP(J14,Tabla11[],2,0),0))*($L14/SUM($L$5:$L$46)),0)) -> 10750.261 | U14: =IF($L14<0,0,IFERROR((U$2*IFERROR(VLOOKUP(J14,Tabla11[],2,0),0))*($L14/SUM($L$5:$L$46)),0)) -> 2090.3286 | V14: =IF($L14<0,0,IFERROR((V$2*IFERROR(VLOOKUP(J14,Tabla11[],2,0),0))*($L14/SUM($L$5:$L$46)),0)) -> 10750.261 | W14: =IF($L14<0,0,IFERROR((W$2*IFERROR(VLOOKUP(J14,Tabla11[],2,0),0))*($L14/SUM($L$5:$L$46)),0)) -> 14930.919 | X14: =P14*$X$2 -> 535773.48 | Y14: =+X14*IFERROR(VLOOKUP(J14,Tabla11[],4,0),0) -> 80366.022 | Z14: =IF(L14>0,$Z$2/12,0) -> 25833.333 | AA14: =P14-SUM(Q14:Z14) -> 408075.64 | AB14: =IF($L14<0,0,IFERROR((AB$2*IFERROR(VLOOKUP(J14,Tabla11[],2,0),0))*($L14/SUM($L$5:$L$46)),0)) -> 17147.201 | AC14: =L14-L14*IFERROR(VLOOKUP(J14,Tabla11[],3,0),0)-Q14-T14-U14-V14-W14-L14*$X$2-(L14*$X$2)*IFERROR(VLOOKUP(J14,Tabla11[],4,0),0)-AB14-Z14 -> 228094.47 | AD14: =AA14-AB14 -> 390928.43 | AE14: =ROUND(AD14-AC14,9) -> 162833.97
A15: Vendedor 1/2 3 días | B15: Outsourcing | C15: 1 | E15: Outsourcing | G15: 3 | H15: Supervisor Regiones | I15: La Serena | J15: Ripley | K15: La Serena | L15: =IFERROR(VLOOKUP(CONCATENATE(J15,K15),Ventas!D:H,4,0),0) -> 1668596.9 | M15: =IF(SUM(C15,F15)>0,L15*0.1,0) -> 166859.69 | N15: =SUM(L15:M15) -> 1835456.6 | O15: =N15*IFERROR(VLOOKUP(J15,Tabla11[],3,0),0) -> 642409.82 | P15: =N15-O15 -> 1193046.8 | Q15: =IFERROR(G15/SUMIF(I:I,I15,G:G),0)*VLOOKUP(H15,Modelos[],14,0)+IFERROR(G15/SUMIF(I:I,I15,G:G),0)*VLOOKUP(I15,Tabla13[],2,0) -> 161601.88 | R15: =IFERROR(VLOOKUP(A15,Modelos[],IF(B15="EST",15,14),0),0)*C15 -> 204526.8 | S15: =IFERROR(VLOOKUP(D15,Modelos[],IF(E15="EST",15,14),0),0)*F15 -> 0 | T15: =IF($L15<0,0,IFERROR((T$2*IFERROR(VLOOKUP(J15,Tabla11[],2,0),0))*($L15/SUM($L$5:$L$46)),0)) -> 9575.3637 | U15: =IF($L15<0,0,IFERROR((U$2*IFERROR(VLOOKUP(J15,Tabla11[],2,0),0))*($L15/SUM($L$5:$L$46)),0)) -> 1861.8763 | V15: =IF($L15<0,0,IFERROR((V$2*IFERROR(VLOOKUP(J15,Tabla11[],2,0),0))*($L15/SUM($L$5:$L$46)),0)) -> 9575.3637 | W15: =IF($L15<0,0,IFERROR((W$2*IFERROR(VLOOKUP(J15,Tabla11[],2,0),0))*($L15/SUM($L$5:$L$46)),0)) -> 13299.116 | X15: =P15*$X$2 -> 477218.72 | Y15: =+X15*IFERROR(VLOOKUP(J15,Tabla11[],4,0),0) -> 71582.808 | Z15: =IF(L15>0,$Z$2/12,0) -> 25833.333 | AA15: =P15-SUM(Q15:Z15) -> 217971.54 | AB15: =IF($L15<0,0,IFERROR((AB$2*IFERROR(VLOOKUP(J15,Tabla11[],2,0),0))*($L15/SUM($L$5:$L$46)),0)) -> 15273.181 | AC15: =L15-L15*IFERROR(VLOOKUP(J15,Tabla11[],3,0),0)-Q15-T15-U15-V15-W15-L15*$X$2-(L15*$X$2)*IFERROR(VLOOKUP(J15,Tabla11[],4,0),0)-AB15-Z15 -> 80013.302 | AD15: =AA15-AB15 -> 202698.36 | AE15: =ROUND(AD15-AC15,9) -> 122685.06
B16: Outsourcing | E16: Outsourcing | G16: 3 | H16: Supervisor Part | I16: Iquique | J16: Ripley | K16: Iquique | L16: =IFERROR(VLOOKUP(CONCATENATE(J16,K16),Ventas!D:H,4,0),0) -> 1667378.5 | M16: =IF(SUM(C16,F16)>0,L16*0.1,0) -> 0 | N16: =SUM(L16:M16) -> 1667378.5 | O16: =N16*IFERROR(VLOOKUP(J16,Tabla11[],3,0),0) -> 583582.46 | P16: =N16-O16 -> 1083796 | Q16: =IFERROR(G16/SUMIF(I:I,I16,G:G),0)*VLOOKUP(H16,Modelos[],14,0)+IFERROR(G16/SUMIF(I:I,I16,G:G),0)*VLOOKUP(I16,Tabla13[],2,0) -> 134909.42 | R16: =IFERROR(VLOOKUP(A16,Modelos[],IF(B16="EST",15,14),0),0)*C16 -> 0 | S16: =IFERROR(VLOOKUP(D16,Modelos[],IF(E16="EST",15,14),0),0)*F16 -> 0 | T16: =IF($L16<0,0,IFERROR((T$2*IFERROR(VLOOKUP(J16,Tabla11[],2,0),0))*($L16/SUM($L$5:$L$46)),0)) -> 9568.3715 | U16: =IF($L16<0,0,IFERROR((U$2*IFERROR(VLOOKUP(J16,Tabla11[],2,0),0))*($L16/SUM($L$5:$L$46)),0)) -> 1860.5167 | V16: =IF($L16<0,0,IFERROR((V$2*IFERROR(VLOOKUP(J16,Tabla11[],2,0),0))*($L16/SUM($L$5:$L$46)),0)) -> 9568.3715 | W16: =IF($L16<0,0,IFERROR((W$2*IFERROR(VLOOKUP(J16,Tabla11[],2,0),0))*($L16/SUM($L$5:$L$46)),0)) -> 13289.405 | X16: =P16*$X$2 -> 433518.4 | Y16: =+X16*IFERROR(VLOOKUP(J16,Tabla11[],4,0),0) -> 65027.76 | Z16: =IF(L16>0,$Z$2/12,0) -> 25833.333 | AA16: =P16-SUM(Q16:Z16) -> 390220.42 | AB16: =IF($L16<0,0,IFERROR((AB$2*IFERROR(VLOOKUP(J16,Tabla11[],2,0),0))*($L16/SUM($L$5:$L$46)),0)) -> 15262.028 | AC16: =L16-L16*IFERROR(VLOOKUP(J16,Tabla11[],3,0),0)-Q16-T16-U16-V16-W16-L16*$X$2-(L16*$X$2)*IFERROR(VLOOKUP(J16,Tabla11[],4,0),0)-AB16-Z16 -> 106510.46 | AD16: =AA16-AB16 -> 374958.4 | AE16: =ROUND(AD16-AC16,9) -> 268447.93
A17: Vendedor 1/2 3 días | B17: Outsourcing | C17: 1 | E17: Outsourcing | G17: 3 | H17: Supervisor Santiago | I17: Santiago 02 | J17: Ripley | K17: Plaza Oeste | L17: =IFERROR(VLOOKUP(CONCATENATE(J17,K17),Ventas!D:H,4,0),0) -> 1665920 | M17: =IF(SUM(C17,F17)>0,L17*0.1,0) -> 166592 | N17: =SUM(L17:M17) -> 1832512 | O17: =N17*IFERROR(VLOOKUP(J17,Tabla11[],3,0),0) -> 641379.2 | P17: =N17-O17 -> 1191132.8 | Q17: =IFERROR(G17/SUMIF(I:I,I17,G:G),0)*VLOOKUP(H17,Modelos[],14,0)+IFERROR(G17/SUMIF(I:I,I17,G:G),0)*VLOOKUP(I17,Tabla13[],2,0) -> 69504.988 | R17: =IFERROR(VLOOKUP(A17,Modelos[],IF(B17="EST",15,14),0),0)*C17 -> 204526.8 | S17: =IFERROR(VLOOKUP(D17,Modelos[],IF(E17="EST",15,14),0),0)*F17 -> 0 | T17: =IF($L17<0,0,IFERROR((T$2*IFERROR(VLOOKUP(J17,Tabla11[],2,0),0))*($L17/SUM($L$5:$L$46)),0)) -> 9560.002 | U17: =IF($L17<0,0,IFERROR((U$2*IFERROR(VLOOKUP(J17,Tabla11[],2,0),0))*($L17/SUM($L$5:$L$46)),0)) -> 1858.8893 | V17: =IF($L17<0,0,IFERROR((V$2*IFERROR(VLOOKUP(J17,Tabla11[],2,0),0))*($L17/SUM($L$5:$L$46)),0)) -> 9560.002 | W17: =IF($L17<0,0,IFERROR((W$2*IFERROR(VLOOKUP(J17,Tabla11[],2,0),0))*($L17/SUM($L$5:$L$46)),0)) -> 13277.781 | X17: =P17*$X$2 -> 476453.12 | Y17: =+X17*IFERROR(VLOOKUP(J17,Tabla11[],4,0),0) -> 71467.968 | Z17: =IF(L17>0,$Z$2/12,0) -> 25833.333 | AA17: =P17-SUM(Q17:Z17) -> 309089.92 | AB17: =IF($L17<0,0,IFERROR((AB$2*IFERROR(VLOOKUP(J17,Tabla11[],2,0),0))*($L17/SUM($L$5:$L$46)),0)) -> 15248.678 | AC17: =L17-L17*IFERROR(VLOOKUP(J17,Tabla11[],3,0),0)-Q17-T17-U17-V17-W17-L17*$X$2-(L17*$X$2)*IFERROR(VLOOKUP(J17,Tabla11[],4,0),0)-AB17-Z17 -> 171681.13 | AD17: =AA17-AB17 -> 293841.24 | AE17: =ROUND(AD17-AC17,9) -> 122160.11
A18: Vendedor 1/2 Full | B18: Outsourcing | C18: 1 | D18: Vendedor 1/2 3 días | E18: Outsourcing | F18: 1 | G18: 3 | H18: Supervisor Santiago | I18: Santiago 02 | J18: Ripley | K18: Plaza Vespucio | L18: =IFERROR(VLOOKUP(CONCATENATE(J18,K18),Ventas!D:H,4,0),0) -> 1610832.3 | M18: =IF(SUM(C18,F18)>0,L18*0.1,0) -> 161083.23 | N18: =SUM(L18:M18) -> 1771915.5 | O18: =N18*IFERROR(VLOOKUP(J18,Tabla11[],3,0),0) -> 620170.44 | P18: =N18-O18 -> 1151745.1 | Q18: =IFERROR(G18/SUMIF(I:I,I18,G:G),0)*VLOOKUP(H18,Modelos[],14,0)+IFERROR(G18/SUMIF(I:I,I18,G:G),0)*VLOOKUP(I18,Tabla13[],2,0) -> 69504.988 | R18: =IFERROR(VLOOKUP(A18,Modelos[],IF(B18="EST",15,14),0),0)*C18 -> 310333.79 | S18: =IFERROR(VLOOKUP(D18,Modelos[],IF(E18="EST",15,14),0),0)*F18 -> 204526.8 | T18: =IF($L18<0,0,IFERROR((T$2*IFERROR(VLOOKUP(J18,Tabla11[],2,0),0))*($L18/SUM($L$5:$L$46)),0)) -> 9243.8773 | U18: =IF($L18<0,0,IFERROR((U$2*IFERROR(VLOOKUP(J18,Tabla11[],2,0),0))*($L18/SUM($L$5:$L$46)),0)) -> 1797.4206 | V18: =IF($L18<0,0,IFERROR((V$2*IFERROR(VLOOKUP(J18,Tabla11[],2,0),0))*($L18/SUM($L$5:$L$46)),0)) -> 9243.8773 | W18: =IF($L18<0,0,IFERROR((W$2*IFERROR(VLOOKUP(J18,Tabla11[],2,0),0))*($L18/SUM($L$5:$L$46)),0)) -> 12838.719 | X18: =P18*$X$2 -> 460698.04 | Y18: =+X18*IFERROR(VLOOKUP(J18,Tabla11[],4,0),0) -> 69104.706 | Z18: =IF(L18>0,$Z$2/12,0) -> 25833.333 | AA18: =P18-SUM(Q18:Z18) -> -21380.45 | AB18: =IF($L18<0,0,IFERROR((AB$2*IFERROR(VLOOKUP(J18,Tabla11[],2,0),0))*($L18/SUM($L$5:$L$46)),0)) -> 14744.444 | AC18: =L18-L18*IFERROR(VLOOKUP(J18,Tabla11[],3,0),0)-Q18-T18-U18-V18-W18-L18*$X$2-(L18*$X$2)*IFERROR(VLOOKUP(J18,Tabla11[],4,0),0)-AB18-Z18 -> 162851.48 | AD18: =AA18-AB18 -> -36124.894 | AE18: =ROUND(AD18-AC18,9) -> -198976.37
A19: Vendedor 1/2 2 días | B19: Outsourcing | C19: 1 | E19: Outsourcing | G19: 3 | H19: Supervisor Regiones | I19: VI-VII | J19: Ripley | K19: Rancagua | L19: =IFERROR(VLOOKUP(CONCATENATE(J19,K19),Ventas!D:H,4,0),0) -> 1504930.8 | M19: =IF(SUM(C19,F19)>0,L19*0.1,0) -> 150493.08 | N19: =SUM(L19:M19) -> 1655423.8 | O19: =N19*IFERROR(VLOOKUP(J19,Tabla11[],3,0),0) -> 579398.35 | P19: =N19-O19 -> 1076025.5 | Q19: =IFERROR(G19/SUMIF(I:I,I19,G:G),0)*VLOOKUP(H19,Modelos[],14,0)+IFERROR(G19/SUMIF(I:I,I19,G:G),0)*VLOOKUP(I19,Tabla13[],2,0) -> 154942.83 | R19: =IFERROR(VLOOKUP(A19,Modelos[],IF(B19="EST",15,14),0),0)*C19 -> 154393.47 | S19: =IFERROR(VLOOKUP(D19,Modelos[],IF(E19="EST",15,14),0),0)*F19 -> 0 | T19: =IF($L19<0,0,IFERROR((T$2*IFERROR(VLOOKUP(J19,Tabla11[],2,0),0))*($L19/SUM($L$5:$L$46)),0)) -> 8636.1537 | U19: =IF($L19<0,0,IFERROR((U$2*IFERROR(VLOOKUP(J19,Tabla11[],2,0),0))*($L19/SUM($L$5:$L$46)),0)) -> 1679.2521 | V19: =IF($L19<0,0,IFERROR((V$2*IFERROR(VLOOKUP(J19,Tabla11[],2,0),0))*($L19/SUM($L$5:$L$46)),0)) -> 8636.1537 | W19: =IF($L19<0,0,IFERROR((W$2*IFERROR(VLOOKUP(J19,Tabla11[],2,0),0))*($L19/SUM($L$5:$L$46)),0)) -> 11994.658 | X19: =P19*$X$2 -> 430410.2 | Y19: =+X19*IFERROR(VLOOKUP(J19,Tabla11[],4,0),0) -> 64561.53 | Z19: =IF(L19>0,$Z$2/12,0) -> 25833.333 | AA19: =P19-SUM(Q19:Z19) -> 214937.92 | AB19: =IF($L19<0,0,IFERROR((AB$2*IFERROR(VLOOKUP(J19,Tabla11[],2,0),0))*($L19/SUM($L$5:$L$46)),0)) -> 13775.094 | AC19: =L19-L19*IFERROR(VLOOKUP(J19,Tabla11[],3,0),0)-Q19-T19-U19-V19-W19-L19*$X$2-(L19*$X$2)*IFERROR(VLOOKUP(J19,Tabla11[],4,0),0)-AB19-Z19 -> 60439.366 | AD19: =AA19-AB19 -> 201162.82 | AE19: =ROUND(AD19-AC19,9) -> 140723.46
A20: Vendedor 1/2 2 días | B20: Outsourcing | C20: 0.5 | E20: Outsourcing | G20: 3 | H20: Supervisor Part | I20: Temuco | J20: Ripley | K20: Portal Temuco | L20: =IFERROR(VLOOKUP(CONCATENATE(J20,K20),Ventas!D:H,4,0),0) -> 1466126.2 | M20: =IF(SUM(C20,F20)>0,L20*0.1,0) -> 146612.62 | N20: =SUM(L20:M20) -> 1612738.8 | O20: =N20*IFERROR(VLOOKUP(J20,Tabla11[],3,0),0) -> 564458.57 | P20: =N20-O20 -> 1048280.2 | Q20: =IFERROR(G20/SUMIF(I:I,I20,G:G),0)*VLOOKUP(H20,Modelos[],14,0)+IFERROR(G20/SUMIF(I:I,I20,G:G),0)*VLOOKUP(I20,Tabla13[],2,0) -> 65246.163 | R20: =IFERROR(VLOOKUP(A20,Modelos[],IF(B20="EST",15,14),0),0)*C20 -> 77196.733 | S20: =IFERROR(VLOOKUP(D20,Modelos[],IF(E20="EST",15,14),0),0)*F20 -> 0 | T20: =IF($L20<0,0,IFERROR((T$2*IFERROR(VLOOKUP(J20,Tabla11[],2,0),0))*($L20/SUM($L$5:$L$46)),0)) -> 8413.4706 | U20: =IF($L20<0,0,IFERROR((U$2*IFERROR(VLOOKUP(J20,Tabla11[],2,0),0))*($L20/SUM($L$5:$L$46)),0)) -> 1635.9526 | V20: =IF($L20<0,0,IFERROR((V$2*IFERROR(VLOOKUP(J20,Tabla11[],2,0),0))*($L20/SUM($L$5:$L$46)),0)) -> 8413.4706 | W20: =IF($L20<0,0,IFERROR((W$2*IFERROR(VLOOKUP(J20,Tabla11[],2,0),0))*($L20/SUM($L$5:$L$46)),0)) -> 11685.376 | X20: =P20*$X$2 -> 419312.08 | Y20: =+X20*IFERROR(VLOOKUP(J20,Tabla11[],4,0),0) -> 62896.812 | Z20: =IF(L20>0,$Z$2/12,0) -> 25833.333 | AA20: =P20-SUM(Q20:Z20) -> 367646.81 | AB20: =IF($L20<0,0,IFERROR((AB$2*IFERROR(VLOOKUP(J20,Tabla11[],2,0),0))*($L20/SUM($L$5:$L$46)),0)) -> 13419.904 | AC20: =L20-L20*IFERROR(VLOOKUP(J20,Tabla11[],3,0),0)-Q20-T20-U20-V20-W20-L20*$X$2-(L20*$X$2)*IFERROR(VLOOKUP(J20,Tabla11[],4,0),0)-AB20-Z20 -> 143916.3 | AD20: =AA20-AB20 -> 354226.91 | AE20: =ROUND(AD20-AC20,9) -> 210310.61
A21: Vendedor 1/2 Full | B21: Outsourcing | C21: 1 | E21: Outsourcing | G21: 3 | H21: Supervisor Part | I21: Antofagasta | J21: Ripley | K21: Antofagasta | L21: =IFERROR(VLOOKUP(CONCATENATE(J21,K21),Ventas!D:H,4,0),0) -> 1413012.3 | M21: =IF(SUM(C21,F21)>0,L21*0.1,0) -> 141301.23 | N21: =SUM(L21:M21) -> 1554313.5 | O21: =N21*IFERROR(VLOOKUP(J21,Tabla11[],3,0),0) -> 544009.74 | P21: =N21-O21 -> 1010303.8 | Q21: =IFERROR(G21/SUMIF(I:I,I21,G:G),0)*VLOOKUP(H21,Modelos[],14,0)+IFERROR(G21/SUMIF(I:I,I21,G:G),0)*VLOOKUP(I21,Tabla13[],2,0) -> 121576.09 | R21: =IFERROR(VLOOKUP(A21,Modelos[],IF(B21="EST",15,14),0),0)*C21 -> 310333.79 | S21: =IFERROR(VLOOKUP(D21,Modelos[],IF(E21="EST",15,14),0),0)*F21 -> 0 | T21: =IF($L21<0,0,IFERROR((T$2*IFERROR(VLOOKUP(J21,Tabla11[],2,0),0))*($L21/SUM($L$5:$L$46)),0)) -> 8108.673 | U21: =IF($L21<0,0,IFERROR((U$2*IFERROR(VLOOKUP(J21,Tabla11[],2,0),0))*($L21/SUM($L$5:$L$46)),0)) -> 1576.6864 | V21: =IF($L21<0,0,IFERROR((V$2*IFERROR(VLOOKUP(J21,Tabla11[],2,0),0))*($L21/SUM($L$5:$L$46)),0)) -> 8108.673 | W21: =IF($L21<0,0,IFERROR((W$2*IFERROR(VLOOKUP(J21,Tabla11[],2,0),0))*($L21/SUM($L$5:$L$46)),0)) -> 11262.046 | X21: =P21*$X$2 -> 404121.52 | Y21: =+X21*IFERROR(VLOOKUP(J21,Tabla11[],4,0),0) -> 60618.228 | Z21: =IF(L21>0,$Z$2/12,0) -> 25833.333 | AA21: =P21-SUM(Q21:Z21) -> 58764.766 | AB21: =IF($L21<0,0,IFERROR((AB$2*IFERROR(VLOOKUP(J21,Tabla11[],2,0),0))*($L21/SUM($L$5:$L$46)),0)) -> 12933.736 | AC21: =L21-L21*IFERROR(VLOOKUP(J21,Tabla11[],3,0),0)-Q21-T21-U21-V21-W21-L21*$X$2-(L21*$X$2)*IFERROR(VLOOKUP(J21,Tabla11[],4,0),0)-AB21-Z21 -> 79073.105 | AD21: =AA21-AB21 -> 45831.03 | AE21: =ROUND(AD21-AC21,9) -> -33242.076
B22: Outsourcing | E22: Outsourcing | G22: 3 | H22: Supervisor Regiones | I22: Concepción | J22: Ripley | K22: El Trebol | L22: =IFERROR(VLOOKUP(CONCATENATE(J22,K22),Ventas!D:H,4,0),0) -> 1302190.8 | M22: =IF(SUM(C22,F22)>0,L22*0.1,0) -> 0 | N22: =SUM(L22:M22) -> 1302190.8 | O22: =N22*IFERROR(VLOOKUP(J22,Tabla11[],3,0),0) -> 455766.77 | P22: =N22-O22 -> 846424 | Q22: =IFERROR(G22/SUMIF(I:I,I22,G:G),0)*VLOOKUP(H22,Modelos[],14,0)+IFERROR(G22/SUMIF(I:I,I22,G:G),0)*VLOOKUP(I22,Tabla13[],2,0) -> 106001.17 | R22: =IFERROR(VLOOKUP(A22,Modelos[],IF(B22="EST",15,14),0),0)*C22 -> 0 | S22: =IFERROR(VLOOKUP(D22,Modelos[],IF(E22="EST",15,14),0),0)*F22 -> 0 | T22: =IF($L22<0,0,IFERROR((T$2*IFERROR(VLOOKUP(J22,Tabla11[],2,0),0))*($L22/SUM($L$5:$L$46)),0)) -> 7472.7156 | U22: =IF($L22<0,0,IFERROR((U$2*IFERROR(VLOOKUP(J22,Tabla11[],2,0),0))*($L22/SUM($L$5:$L$46)),0)) -> 1453.028 | V22: =IF($L22<0,0,IFERROR((V$2*IFERROR(VLOOKUP(J22,Tabla11[],2,0),0))*($L22/SUM($L$5:$L$46)),0)) -> 7472.7156 | W22: =IF($L22<0,0,IFERROR((W$2*IFERROR(VLOOKUP(J22,Tabla11[],2,0),0))*($L22/SUM($L$5:$L$46)),0)) -> 10378.772 | X22: =P22*$X$2 -> 338569.6 | Y22: =+X22*IFERROR(VLOOKUP(J22,Tabla11[],4,0),0) -> 50785.44 | Z22: =IF(L22>0,$Z$2/12,0) -> 25833.333 | AA22: =P22-SUM(Q22:Z22) -> 298457.22 | AB22: =IF($L22<0,0,IFERROR((AB$2*IFERROR(VLOOKUP(J22,Tabla11[],2,0),0))*($L22/SUM($L$5:$L$46)),0)) -> 11919.353 | AC22: =L22-L22*IFERROR(VLOOKUP(J22,Tabla11[],3,0),0)-Q22-T22-U22-V22-W22-L22*$X$2-(L22*$X$2)*IFERROR(VLOOKUP(J22,Tabla11[],4,0),0)-AB22-Z22 -> 76885.155 | AD22: =AA22-AB22 -> 286537.87 | AE22: =ROUND(AD22-AC22,9) -> 209652.71
B23: Outsourcing | E23: Outsourcing | G23: 3 | H23: Supervisor Santiago | I23: Santiago 03 | J23: Ripley | K23: San Bernardo | L23: =IFERROR(VLOOKUP(CONCATENATE(J23,K23),Ventas!D:H,4,0),0) -> 1170487.7 | M23: =IF(SUM(C23,F23)>0,L23*0.1,0) -> 0 | N23: =SUM(L23:M23) -> 1170487.7 | O23: =N23*IFERROR(VLOOKUP(J23,Tabla11[],3,0),0) -> 409670.69 | P23: =N23-O23 -> 760817 | Q23: =IFERROR(G23/SUMIF(I:I,I23,G:G),0)*VLOOKUP(H23,Modelos[],14,0)+IFERROR(G23/SUMIF(I:I,I23,G:G),0)*VLOOKUP(I23,Tabla13[],2,0) -> 73262.014 | R23: =IFERROR(VLOOKUP(A23,Modelos[],IF(B23="EST",15,14),0),0)*C23 -> 0 | S23: =IFERROR(VLOOKUP(D23,Modelos[],IF(E23="EST",15,14),0),0)*F23 -> 0 | T23: =IF($L23<0,0,IFERROR((T$2*IFERROR(VLOOKUP(J23,Tabla11[],2,0),0))*($L23/SUM($L$5:$L$46)),0)) -> 6716.928 | U23: =IF($L23<0,0,IFERROR((U$2*IFERROR(VLOOKUP(J23,Tabla11[],2,0),0))*($L23/SUM($L$5:$L$46)),0)) -> 1306.0693 | V23: =IF($L23<0,0,IFERROR((V$2*IFERROR(VLOOKUP(J23,Tabla11[],2,0),0))*($L23/SUM($L$5:$L$46)),0)) -> 6716.928 | W23: =IF($L23<0,0,IFERROR((W$2*IFERROR(VLOOKUP(J23,Tabla11[],2,0),0))*($L23/SUM($L$5:$L$46)),0)) -> 9329.0667 | X23: =P23*$X$2 -> 304326.8 | Y23: =+X23*IFERROR(VLOOKUP(J23,Tabla11[],4,0),0) -> 45649.02 | Z23: =IF(L23>0,$Z$2/12,0) -> 25833.333 | AA23: =P23-SUM(Q23:Z23) -> 287676.84 | AB23: =IF($L23<0,0,IFERROR((AB$2*IFERROR(VLOOKUP(J23,Tabla11[],2,0),0))*($L23/SUM($L$5:$L$46)),0)) -> 10713.834 | AC23: =L23-L23*IFERROR(VLOOKUP(J23,Tabla11[],3,0),0)-Q23-T23-U23-V23-W23-L23*$X$2-(L23*$X$2)*IFERROR(VLOOKUP(J23,Tabla11[],4,0),0)-AB23-Z23 -> 88514.488 | AD23: =AA23-AB23 -> 276963.01 | AE23: =ROUND(AD23-AC23,9) -> 188448.52
B24: Outsourcing | E24: Outsourcing | G24: 3 | H24: Supervisor Santiago | I24: Santiago 03 | J24: Ripley | K24: Puente | L24: =IFERROR(VLOOKUP(CONCATENATE(J24,K24),Ventas!D:H,4,0),0) -> 1122784.6 | M24: =IF(SUM(C24,F24)>0,L24*0.1,0) -> 0 | N24: =SUM(L24:M24) -> 1122784.6 | O24: =N24*IFERROR(VLOOKUP(J24,Tabla11[],3,0),0) -> 392974.62 | P24: =N24-O24 -> 729810 | Q24: =IFERROR(G24/SUMIF(I:I,I24,G:G),0)*VLOOKUP(H24,Modelos[],14,0)+IFERROR(G24/SUMIF(I:I,I24,G:G),0)*VLOOKUP(I24,Tabla13[],2,0) -> 73262.014 | R24: =IFERROR(VLOOKUP(A24,Modelos[],IF(B24="EST",15,14),0),0)*C24 -> 0 | S24: =IFERROR(VLOOKUP(D24,Modelos[],IF(E24="EST",15,14),0),0)*F24 -> 0 | T24: =IF($L24<0,0,IFERROR((T$2*IFERROR(VLOOKUP(J24,Tabla11[],2,0),0))*($L24/SUM($L$5:$L$46)),0)) -> 6443.1805 | U24: =IF($L24<0,0,IFERROR((U$2*IFERROR(VLOOKUP(J24,Tabla11[],2,0),0))*($L24/SUM($L$5:$L$46)),0)) -> 1252.8406 | V24: =IF($L24<0,0,IFERROR((V$2*IFERROR(VLOOKUP(J24,Tabla11[],2,0),0))*($L24/SUM($L$5:$L$46)),0)) -> 6443.1805 | W24: =IF($L24<0,0,IFERROR((W$2*IFERROR(VLOOKUP(J24,Tabla11[],2,0),0))*($L24/SUM($L$5:$L$46)),0)) -> 8948.8617 | X24: =P24*$X$2 -> 291924 | Y24: =+X24*IFERROR(VLOOKUP(J24,Tabla11[],4,0),0) -> 43788.6 | Z24: =IF(L24>0,$Z$2/12,0) -> 25833.333 | AA24: =P24-SUM(Q24:Z24) -> 271913.99 | AB24: =IF($L24<0,0,IFERROR((AB$2*IFERROR(VLOOKUP(J24,Tabla11[],2,0),0))*($L24/SUM($L$5:$L$46)),0)) -> 10277.193 | AC24: =L24-L24*IFERROR(VLOOKUP(J24,Tabla11[],3,0),0)-Q24-T24-U24-V24-W24-L24*$X$2-(L24*$X$2)*IFERROR(VLOOKUP(J24,Tabla11[],4,0),0)-AB24-Z24 -> 80868.473 | AD24: =AA24-AB24 -> 261636.8 | AE24: =ROUND(AD24-AC24,9) -> 180768.32
A25: Vendedor 1/2 2 días | B25: Outsourcing | C25: 1 | E25: Outsourcing | G25: 1 | H25: Supervisor Regiones | I25: VI-VII | J25: Ripley | K25: Curico | L25: =IFERROR(VLOOKUP(CONCATENATE(J25,K25),Ventas!D:H,4,0),0) -> 1109549.2 | M25: =IF(SUM(C25,F25)>0,L25*0.1,0) -> 110954.92 | N25: =SUM(L25:M25) -> 1220504.2 | O25: =N25*IFERROR(VLOOKUP(J25,Tabla11[],3,0),0) -> 427176.45 | P25: =N25-O25 -> 793327.7 | Q25: =IFERROR(G25/SUMIF(I:I,I25,G:G),0)*VLOOKUP(H25,Modelos[],14,0)+IFERROR(G25/SUMIF(I:I,I25,G:G),0)*VLOOKUP(I25,Tabla13[],2,0) -> 51647.612 | R25: =IFERROR(VLOOKUP(A25,Modelos[],IF(B25="EST",15,14),0),0)*C25 -> 154393.47 | S25: =IFERROR(VLOOKUP(D25,Modelos[],IF(E25="EST",15,14),0),0)*F25 -> 0 | T25: =IF($L25<0,0,IFERROR((T$2*IFERROR(VLOOKUP(J25,Tabla11[],2,0),0))*($L25/SUM($L$5:$L$46)),0)) -> 6367.2282 | U25: =IF($L25<0,0,IFERROR((U$2*IFERROR(VLOOKUP(J25,Tabla11[],2,0),0))*($L25/SUM($L$5:$L$46)),0)) -> 1238.0722 | V25: =IF($L25<0,0,IFERROR((V$2*IFERROR(VLOOKUP(J25,Tabla11[],2,0),0))*($L25/SUM($L$5:$L$46)),0)) -> 6367.2282 | W25: =IF($L25<0,0,IFERROR((W$2*IFERROR(VLOOKUP(J25,Tabla11[],2,0),0))*($L25/SUM($L$5:$L$46)),0)) -> 8843.3726 | X25: =P25*$X$2 -> 317331.08 | Y25: =+X25*IFERROR(VLOOKUP(J25,Tabla11[],4,0),0) -> 47599.662 | Z25: =IF(L25>0,$Z$2/12,0) -> 25833.333 | AA25: =P25-SUM(Q25:Z25) -> 173706.65 | AB25: =IF($L25<0,0,IFERROR((AB$2*IFERROR(VLOOKUP(J25,Tabla11[],2,0),0))*($L25/SUM($L$5:$L$46)),0)) -> 10156.046 | AC25: =L25-L25*IFERROR(VLOOKUP(J25,Tabla11[],3,0),0)-Q25-T25-U25-V25-W25-L25*$X$2-(L25*$X$2)*IFERROR(VLOOKUP(J25,Tabla11[],4,0),0)-AB25-Z25 -> 100361.46 | AD25: =AA25-AB25 -> 163550.6 | AE25: =ROUND(AD25-AC25,9) -> 63189.139
A26: Vendedor 1/2 2 días | B26: Outsourcing | C26: 1 | E26: Outsourcing | G26: 0 | H26: Supervisor Regiones | I26: Valdivia | J26: Ripley | K26: Nueva Valdivia Store | L26: =IFERROR(VLOOKUP(CONCATENATE(J26,K26),Ventas!D:H,4,0),0) -> 1106101.5 | M26: =IF(SUM(C26,F26)>0,L26*0.1,0) -> 110610.15 | N26: =SUM(L26:M26) -> 1216711.7 | O26: =N26*IFERROR(VLOOKUP(J26,Tabla11[],3,0),0) -> 425849.09 | P26: =N26-O26 -> 790862.6 | Q26: =IFERROR(G26/SUMIF(I:I,I26,G:G),0)*VLOOKUP(H26,Modelos[],14,0)+IFERROR(G26/SUMIF(I:I,I26,G:G),0)*VLOOKUP(I26,Tabla13[],2,0) -> 0 | R26: =IFERROR(VLOOKUP(A26,Modelos[],IF(B26="EST",15,14),0),0)*C26 -> 154393.47 | S26: =IFERROR(VLOOKUP(D26,Modelos[],IF(E26="EST",15,14),0),0)*F26 -> 0 | T26: =IF($L26<0,0,IFERROR((T$2*IFERROR(VLOOKUP(J26,Tabla11[],2,0),0))*($L26/SUM($L$5:$L$46)),0)) -> 6347.4434 | U26: =IF($L26<0,0,IFERROR((U$2*IFERROR(VLOOKUP(J26,Tabla11[],2,0),0))*($L26/SUM($L$5:$L$46)),0)) -> 1234.2251 | V26: =IF($L26<0,0,IFERROR((V$2*IFERROR(VLOOKUP(J26,Tabla11[],2,0),0))*($L26/SUM($L$5:$L$46)),0)) -> 6347.4434 | W26: =IF($L26<0,0,IFERROR((W$2*IFERROR(VLOOKUP(J26,Tabla11[],2,0),0))*($L26/SUM($L$5:$L$46)),0)) -> 8815.8936 | X26: =P26*$X$2 -> 316345.04 | Y26: =+X26*IFERROR(VLOOKUP(J26,Tabla11[],4,0),0) -> 47451.756 | Z26: =IF(L26>0,$Z$2/12,0) -> 25833.333 | AA26: =P26-SUM(Q26:Z26) -> 224094 | AB26: =IF($L26<0,0,IFERROR((AB$2*IFERROR(VLOOKUP(J26,Tabla11[],2,0),0))*($L26/SUM($L$5:$L$46)),0)) -> 10124.488 | AC26: =L26-L26*IFERROR(VLOOKUP(J26,Tabla11[],3,0),0)-Q26-T26-U26-V26-W26-L26*$X$2-(L26*$X$2)*IFERROR(VLOOKUP(J26,Tabla11[],4,0),0)-AB26-Z26 -> 151456.47 | AD26: =AA26-AB26 -> 213969.51 | AE26: =ROUND(AD26-AC26,9) -> 62513.046
A27: Vendedor 1/2 2 días | B27: Outsourcing | C27: 1 | E27: Outsourcing | G27: 2 | H27: Supervisor Regiones | I27: Concepción | J27: Ripley | K27: Los Angeles | L27: =IFERROR(VLOOKUP(CONCATENATE(J27,K27),Ventas!D:H,4,0),0) -> 1027076.9 | M27: =IF(SUM(C27,F27)>0,L27*0.1,0) -> 102707.69 | N27: =SUM(L27:M27) -> 1129784.6 | O27: =N27*IFERROR(VLOOKUP(J27,Tabla11[],3,0),0) -> 395424.62 | P27: =N27-O27 -> 734360 | Q27: =IFERROR(G27/SUMIF(I:I,I27,G:G),0)*VLOOKUP(H27,Modelos[],14,0)+IFERROR(G27/SUMIF(I:I,I27,G:G),0)*VLOOKUP(I27,Tabla13[],2,0) -> 70667.45 | R27: =IFERROR(VLOOKUP(A27,Modelos[],IF(B27="EST",15,14),0),0)*C27 -> 154393.47 | S27: =IFERROR(VLOOKUP(D27,Modelos[],IF(E27="EST",15,14),0),0)*F27 -> 0 | T27: =IF($L27<0,0,IFERROR((T$2*IFERROR(VLOOKUP(J27,Tabla11[],2,0),0))*($L27/SUM($L$5:$L$46)),0)) -> 5893.955 | U27: =IF($L27<0,0,IFERROR((U$2*IFERROR(VLOOKUP(J27,Tabla11[],2,0),0))*($L27/SUM($L$5:$L$46)),0)) -> 1146.0468 | V27: =IF($L27<0,0,IFERROR((V$2*IFERROR(VLOOKUP(J27,Tabla11[],2,0),0))*($L27/SUM($L$5:$L$46)),0)) -> 5893.955 | W27: =IF($L27<0,0,IFERROR((W$2*IFERROR(VLOOKUP(J27,Tabla11[],2,0),0))*($L27/SUM($L$5:$L$46)),0)) -> 8186.0486 | X27: =P27*$X$2 -> 293744 | Y27: =+X27*IFERROR(VLOOKUP(J27,Tabla11[],4,0),0) -> 44061.6 | Z27: =IF(L27>0,$Z$2/12,0) -> 25833.333 | AA27: =P27-SUM(Q27:Z27) -> 124540.15 | AB27: =IF($L27<0,0,IFERROR((AB$2*IFERROR(VLOOKUP(J27,Tabla11[],2,0),0))*($L27/SUM($L$5:$L$46)),0)) -> 9401.1511 | AC27: =L27-L27*IFERROR(VLOOKUP(J27,Tabla11[],3,0),0)-Q27-T27-U27-V27-W27-L27*$X$2-(L27*$X$2)*IFERROR(VLOOKUP(J27,Tabla11[],4,0),0)-AB27-Z27 -> 68122.676 | AD27: =AA27-AB27 -> 115138.99 | AE27: =ROUND(AD27-AC27,9) -> 47016.319
B28: Outsourcing | E28: Outsourcing | G28: 3 | H28: Supervisor Santiago | I28: Santiago 02 | J28: Ripley | K28: Maipu | L28: =IFERROR(VLOOKUP(CONCATENATE(J28,K28),Ventas!D:H,4,0),0) -> 977453.85 | M28: =IF(SUM(C28,F28)>0,L28*0.1,0) -> 0 | N28: =SUM(L28:M28) -> 977453.85 | O28: =N28*IFERROR(VLOOKUP(J28,Tabla11[],3,0),0) -> 342108.85 | P28: =N28-O28 -> 635345 | Q28: =IFERROR(G28/SUMIF(I:I,I28,G:G),0)*VLOOKUP(H28,Modelos[],14,0)+IFERROR(G28/SUMIF(I:I,I28,G:G),0)*VLOOKUP(I28,Tabla13[],2,0) -> 69504.988 | R28: =IFERROR(VLOOKUP(A28,Modelos[],IF(B28="EST",15,14),0),0)*C28 -> 0 | S28: =IFERROR(VLOOKUP(D28,Modelos[],IF(E28="EST",15,14),0),0)*F28 -> 0 | T28: =IF($L28<0,0,IFERROR((T$2*IFERROR(VLOOKUP(J28,Tabla11[],2,0),0))*($L28/SUM($L$5:$L$46)),0)) -> 5609.1894 | U28: =IF($L28<0,0,IFERROR((U$2*IFERROR(VLOOKUP(J28,Tabla11[],2,0),0))*($L28/SUM($L$5:$L$46)),0)) -> 1090.6757 | V28: =IF($L28<0,0,IFERROR((V$2*IFERROR(VLOOKUP(J28,Tabla11[],2,0),0))*($L28/SUM($L$5:$L$46)),0)) -> 5609.1894 | W28: =IF($L28<0,0,IFERROR((W$2*IFERROR(VLOOKUP(J28,Tabla11[],2,0),0))*($L28/SUM($L$5:$L$46)),0)) -> 7790.5408 | X28: =P28*$X$2 -> 254138 | Y28: =+X28*IFERROR(VLOOKUP(J28,Tabla11[],4,0),0) -> 38120.7 | Z28: =IF(L28>0,$Z$2/12,0) -> 25833.333 | AA28: =P28-SUM(Q28:Z28) -> 227648.38 | AB28: =IF($L28<0,0,IFERROR((AB$2*IFERROR(VLOOKUP(J28,Tabla11[],2,0),0))*($L28/SUM($L$5:$L$46)),0)) -> 8946.9359 | AC28: =L28-L28*IFERROR(VLOOKUP(J28,Tabla11[],3,0),0)-Q28-T28-U28-V28-W28-L28*$X$2-(L28*$X$2)*IFERROR(VLOOKUP(J28,Tabla11[],4,0),0)-AB28-Z28 -> 61331.379 | AD28: =AA28-AB28 -> 218701.45 | AE28: =ROUND(AD28-AC28,9) -> 157370.07
B29: Outsourcing | E29: Outsourcing | G29: 3 | H29: Supervisor Santiago | I29: Santiago 03 | J29: Ripley | K29: Nueva Alameda | L29: =IFERROR(VLOOKUP(CONCATENATE(J29,K29),Ventas!D:H,4,0),0) -> 965001.54 | M29: =IF(SUM(C29,F29)>0,L29*0.1,0) -> 0 | N29: =SUM(L29:M29) -> 965001.54 | O29: =N29*IFERROR(VLOOKUP(J29,Tabla11[],3,0),0) -> 337750.54 | P29: =N29-O29 -> 627251 | Q29: =IFERROR(G29/SUMIF(I:I,I29,G:G),0)*VLOOKUP(H29,Modelos[],14,0)+IFERROR(G29/SUMIF(I:I,I29,G:G),0)*VLOOKUP(I29,Tabla13[],2,0) -> 73262.014 | R29: =IFERROR(VLOOKUP(A29,Modelos[],IF(B29="EST",15,14),0),0)*C29 -> 0 | S29: =IFERROR(VLOOKUP(D29,Modelos[],IF(E29="EST",15,14),0),0)*F29 -> 0 | T29: =IF($L29<0,0,IFERROR((T$2*IFERROR(VLOOKUP(J29,Tabla11[],2,0),0))*($L29/SUM($L$5:$L$46)),0)) -> 5537.7309 | U29: =IF($L29<0,0,IFERROR((U$2*IFERROR(VLOOKUP(J29,Tabla11[],2,0),0))*($L29/SUM($L$5:$L$46)),0)) -> 1076.781 | V29: =IF($L29<0,0,IFERROR((V$2*IFERROR(VLOOKUP(J29,Tabla11[],2,0),0))*($L29/SUM($L$5:$L$46)),0)) -> 5537.7309 | W29: =IF($L29<0,0,IFERROR((W$2*IFERROR(VLOOKUP(J29,Tabla11[],2,0),0))*($L29/SUM($L$5:$L$46)),0)) -> 7691.2929 | X29: =P29*$X$2 -> 250900.4 | Y29: =+X29*IFERROR(VLOOKUP(J29,Tabla11[],4,0),0) -> 37635.06 | Z29: =IF(L29>0,$Z$2/12,0) -> 25833.333 | AA29: =P29-SUM(Q29:Z29) -> 219776.66 | AB29: =IF($L29<0,0,IFERROR((AB$2*IFERROR(VLOOKUP(J29,Tabla11[],2,0),0))*($L29/SUM($L$5:$L$46)),0)) -> 8832.956 | AC29: =L29-L29*IFERROR(VLOOKUP(J29,Tabla11[],3,0),0)-Q29-T29-U29-V29-W29-L29*$X$2-(L29*$X$2)*IFERROR(VLOOKUP(J29,Tabla11[],4,0),0)-AB29-Z29 -> 55578.453 | AD29: =AA29-AB29 -> 210943.7 | AE29: =ROUND(AD29-AC29,9) -> 155365.25
B30: Outsourcing | E30: Outsourcing | G30: 3 | H30: Supervisor Regiones | I30: Viña del Mar | J30: Ripley | K30: Valparaiso | L30: =IFERROR(VLOOKUP(CONCATENATE(J30,K30),Ventas!D:H,4,0),0) -> 928841.54 | M30: =IF(SUM(C30,F30)>0,L30*0.1,0) -> 0 | N30: =SUM(L30:M30) -> 928841.54 | O30: =N30*IFERROR(VLOOKUP(J30,Tabla11[],3,0),0) -> 325094.54 | P30: =N30-O30 -> 603747 | Q30: =IFERROR(G30/SUMIF(I:I,I30,G:G),0)*VLOOKUP(H30,Modelos[],14,0)+IFERROR(G30/SUMIF(I:I,I30,G:G),0)*VLOOKUP(I30,Tabla13[],2,0) -> 123633.06 | R30: =IFERROR(VLOOKUP(A30,Modelos[],IF(B30="EST",15,14),0),0)*C30 -> 0 | S30: =IFERROR(VLOOKUP(D30,Modelos[],IF(E30="EST",15,14),0),0)*F30 -> 0 | T30: =IF($L30<0,0,IFERROR((T$2*IFERROR(VLOOKUP(J30,Tabla11[],2,0),0))*($L30/SUM($L$5:$L$46)),0)) -> 5330.2241 | U30: =IF($L30<0,0,IFERROR((U$2*IFERROR(VLOOKUP(J30,Tabla11[],2,0),0))*($L30/SUM($L$5:$L$46)),0)) -> 1036.4325 | V30: =IF($L30<0,0,IFERROR((V$2*IFERROR(VLOOKUP(J30,Tabla11[],2,0),0))*($L30/SUM($L$5:$L$46)),0)) -> 5330.2241 | W30: =IF($L30<0,0,IFERROR((W$2*IFERROR(VLOOKUP(J30,Tabla11[],2,0),0))*($L30/SUM($L$5:$L$46)),0)) -> 7403.0891 | X30: =P30*$X$2 -> 241498.8 | Y30: =+X30*IFERROR(VLOOKUP(J30,Tabla11[],4,0),0) -> 36224.82 | Z30: =IF(L30>0,$Z$2/12,0) -> 25833.333 | AA30: =P30-SUM(Q30:Z30) -> 157457.01 | AB30: =IF($L30<0,0,IFERROR((AB$2*IFERROR(VLOOKUP(J30,Tabla11[],2,0),0))*($L30/SUM($L$5:$L$46)),0)) -> 8501.9724 | AC30: =L30-L30*IFERROR(VLOOKUP(J30,Tabla11[],3,0),0)-Q30-T30-U30-V30-W30-L30*$X$2-(L30*$X$2)*IFERROR(VLOOKUP(J30,Tabla11[],4,0),0)-AB30-Z30 -> -588.4458 | AD30: =AA30-AB30 -> 148955.04 | AE30: =ROUND(AD30-AC30,9) -> 149543.49
B31: Outsourcing | E31: Outsourcing | G31: 3 | H31: Supervisor Santiago | I31: Santiago 01 | J31: Ripley | K31: Parque Arauco | L31: =IFERROR(VLOOKUP(CONCATENATE(J31,K31),Ventas!D:H,4,0),0) -> 877984.62 | M31: =IF(SUM(C31,F31)>0,L31*0.1,0) -> 0 | N31: =SUM(L31:M31) -> 877984.62 | O31: =N31*IFERROR(VLOOKUP(J31,Tabla11[],3,0),0) -> 307294.62 | P31: =N31-O31 -> 570690 | Q31: =IFERROR(G31/SUMIF(I:I,I31,G:G),0)*VLOOKUP(H31,Modelos[],14,0)+IFERROR(G31/SUMIF(I:I,I31,G:G),0)*VLOOKUP(I31,Tabla13[],2,0) -> 69504.988 | R31: =IFERROR(VLOOKUP(A31,Modelos[],IF(B31="EST",15,14),0),0)*C31 -> 0 | S31: =IFERROR(VLOOKUP(D31,Modelos[],IF(E31="EST",15,14),0),0)*F31 -> 0 | T31: =IF($L31<0,0,IFERROR((T$2*IFERROR(VLOOKUP(J31,Tabla11[],2,0),0))*($L31/SUM($L$5:$L$46)),0)) -> 5038.378 | U31: =IF($L31<0,0,IFERROR((U$2*IFERROR(VLOOKUP(J31,Tabla11[],2,0),0))*($L31/SUM($L$5:$L$46)),0)) -> 979.68461 | V31: =IF($L31<0,0,IFERROR((V$2*IFERROR(VLOOKUP(J31,Tabla11[],2,0),0))*($L31/SUM($L$5:$L$46)),0)) -> 5038.378 | W31: =IF($L31<0,0,IFERROR((W$2*IFERROR(VLOOKUP(J31,Tabla11[],2,0),0))*($L31/SUM($L$5:$L$46)),0)) -> 6997.7472 | X31: =P31*$X$2 -> 228276 | Y31: =+X31*IFERROR(VLOOKUP(J31,Tabla11[],4,0),0) -> 34241.4 | Z31: =IF(L31>0,$Z$2/12,0) -> 25833.333 | AA31: =P31-SUM(Q31:Z31) -> 194780.09 | AB31: =IF($L31<0,0,IFERROR((AB$2*IFERROR(VLOOKUP(J31,Tabla11[],2,0),0))*($L31/SUM($L$5:$L$46)),0)) -> 8036.4634 | AC31: =L31-L31*IFERROR(VLOOKUP(J31,Tabla11[],3,0),0)-Q31-T31-U31-V31-W31-L31*$X$2-(L31*$X$2)*IFERROR(VLOOKUP(J31,Tabla11[],4,0),0)-AB31-Z31 -> 45388.105 | AD31: =AA31-AB31 -> 186743.63 | AE31: =ROUND(AD31-AC31,9) -> 141355.52
B32: Outsourcing | E32: Outsourcing | G32: 3 | H32: Supervisor Santiago | I32: Santiago 01 | J32: Ripley | K32: Huechuraba | L32: =IFERROR(VLOOKUP(CONCATENATE(J32,K32),Ventas!D:H,4,0),0) -> 850635.38 | M32: =IF(SUM(C32,F32)>0,L32*0.1,0) -> 0 | N32: =SUM(L32:M32) -> 850635.38 | O32: =N32*IFERROR(VLOOKUP(J32,Tabla11[],3,0),0) -> 297722.38 | P32: =N32-O32 -> 552913 | Q32: =IFERROR(G32/SUMIF(I:I,I32,G:G),0)*VLOOKUP(H32,Modelos[],14,0)+IFERROR(G32/SUMIF(I:I,I32,G:G),0)*VLOOKUP(I32,Tabla13[],2,0) -> 69504.988 | R32: =IFERROR(VLOOKUP(A32,Modelos[],IF(B32="EST",15,14),0),0)*C32 -> 0 | S32: =IFERROR(VLOOKUP(D32,Modelos[],IF(E32="EST",15,14),0),0)*F32 -> 0 | T32: =IF($L32<0,0,IFERROR((T$2*IFERROR(VLOOKUP(J32,Tabla11[],2,0),0))*($L32/SUM($L$5:$L$46)),0)) -> 4881.4325 | U32: =IF($L32<0,0,IFERROR((U$2*IFERROR(VLOOKUP(J32,Tabla11[],2,0),0))*($L32/SUM($L$5:$L$46)),0)) -> 949.16743 | V32: =IF($L32<0,0,IFERROR((V$2*IFERROR(VLOOKUP(J32,Tabla11[],2,0),0))*($L32/SUM($L$5:$L$46)),0)) -> 4881.4325 | W32: =IF($L32<0,0,IFERROR((W$2*IFERROR(VLOOKUP(J32,Tabla11[],2,0),0))*($L32/SUM($L$5:$L$46)),0)) -> 6779.7673 | X32: =P32*$X$2 -> 221165.2 | Y32: =+X32*IFERROR(VLOOKUP(J32,Tabla11[],4,0),0) -> 33174.78 | Z32: =IF(L32>0,$Z$2/12,0) -> 25833.333 | AA32: =P32-SUM(Q32:Z32) -> 185742.9 | AB32: =IF($L32<0,0,IFERROR((AB$2*IFERROR(VLOOKUP(J32,Tabla11[],2,0),0))*($L32/SUM($L$5:$L$46)),0)) -> 7786.1274 | AC32: =L32-L32*IFERROR(VLOOKUP(J32,Tabla11[],3,0),0)-Q32-T32-U32-V32-W32-L32*$X$2-(L32*$X$2)*IFERROR(VLOOKUP(J32,Tabla11[],4,0),0)-AB32-Z32 -> 41004.475 | AD32: =AA32-AB32 -> 177956.77 | AE32: =ROUND(AD32-AC32,9) -> 136952.3
B33: Outsourcing | E33: Outsourcing | G33: 3 | H33: Supervisor Part | I33: Copiapó | J33: Ripley | K33: Copiapo | L33: =IFERROR(VLOOKUP(CONCATENATE(J33,K33),Ventas!D:H,4,0),0) -> 827649.23 | M33: =IF(SUM(C33,F33)>0,L33*0.1,0) -> 0 | N33: =SUM(L33:M33) -> 827649.23 | O33: =N33*IFERROR(VLOOKUP(J33,Tabla11[],3,0),0) -> 289677.23 | P33: =N33-O33 -> 537972 | Q33: =IFERROR(G33/SUMIF(I:I,I33,G:G),0)*VLOOKUP(H33,Modelos[],14,0)+IFERROR(G33/SUMIF(I:I,I33,G:G),0)*VLOOKUP(I33,Tabla13[],2,0) -> 128242.75 | R33: =IFERROR(VLOOKUP(A33,Modelos[],IF(B33="EST",15,14),0),0)*C33 -> 0 | S33: =IFERROR(VLOOKUP(D33,Modelos[],IF(E33="EST",15,14),0),0)*F33 -> 0 | T33: =IF($L33<0,0,IFERROR((T$2*IFERROR(VLOOKUP(J33,Tabla11[],2,0),0))*($L33/SUM($L$5:$L$46)),0)) -> 4749.5248 | U33: =IF($L33<0,0,IFERROR((U$2*IFERROR(VLOOKUP(J33,Tabla11[],2,0),0))*($L33/SUM($L$5:$L$46)),0)) -> 923.51871 | V33: =IF($L33<0,0,IFERROR((V$2*IFERROR(VLOOKUP(J33,Tabla11[],2,0),0))*($L33/SUM($L$5:$L$46)),0)) -> 4749.5248 | W33: =IF($L33<0,0,IFERROR((W$2*IFERROR(VLOOKUP(J33,Tabla11[],2,0),0))*($L33/SUM($L$5:$L$46)),0)) -> 6596.5622 | X33: =P33*$X$2 -> 215188.8 | Y33: =+X33*IFERROR(VLOOKUP(J33,Tabla11[],4,0),0) -> 32278.32 | Z33: =IF(L33>0,$Z$2/12,0) -> 25833.333 | AA33: =P33-SUM(Q33:Z33) -> 119409.66 | AB33: =IF($L33<0,0,IFERROR((AB$2*IFERROR(VLOOKUP(J33,Tabla11[],2,0),0))*($L33/SUM($L$5:$L$46)),0)) -> 7575.7281 | AC33: =L33-L33*IFERROR(VLOOKUP(J33,Tabla11[],3,0),0)-Q33-T33-U33-V33-W33-L33*$X$2-(L33*$X$2)*IFERROR(VLOOKUP(J33,Tabla11[],4,0),0)-AB33-Z33 -> -21417.59 | AD33: =AA33-AB33 -> 111833.94 | AE33: =ROUND(AD33-AC33,9) -> 133251.53
B34: Outsourcing | E34: Outsourcing | G34: 3 | H34: Supervisor Regiones | I34: Concepción | J34: Ripley | K34: Concepcion 2 | L34: =IFERROR(VLOOKUP(CONCATENATE(J34,K34),Ventas!D:H,4,0),0) -> 459901.54 | M34: =IF(SUM(C34,F34)>0,L34*0.1,0) -> 0 | N34: =SUM(L34:M34) -> 459901.54 | O34: =N34*IFERROR(VLOOKUP(J34,Tabla11[],3,0),0) -> 160965.54 | P34: =N34-O34 -> 298936 | Q34: =IFERROR(G34/SUMIF(I:I,I34,G:G),0)*VLOOKUP(H34,Modelos[],14,0)+IFERROR(G34/SUMIF(I:I,I34,G:G),0)*VLOOKUP(I34,Tabla13[],2,0) -> 106001.17 | R34: =IFERROR(VLOOKUP(A34,Modelos[],IF(B34="EST",15,14),0),0)*C34 -> 0 | S34: =IFERROR(VLOOKUP(D34,Modelos[],IF(E34="EST",15,14),0),0)*F34 -> 0 | T34: =IF($L34<0,0,IFERROR((T$2*IFERROR(VLOOKUP(J34,Tabla11[],2,0),0))*($L34/SUM($L$5:$L$46)),0)) -> 2639.1781 | U34: =IF($L34<0,0,IFERROR((U$2*IFERROR(VLOOKUP(J34,Tabla11[],2,0),0))*($L34/SUM($L$5:$L$46)),0)) -> 513.17353 | V34: =IF($L34<0,0,IFERROR((V$2*IFERROR(VLOOKUP(J34,Tabla11[],2,0),0))*($L34/SUM($L$5:$L$46)),0)) -> 2639.1781 | W34: =IF($L34<0,0,IFERROR((W$2*IFERROR(VLOOKUP(J34,Tabla11[],2,0),0))*($L34/SUM($L$5:$L$46)),0)) -> 3665.5252 | X34: =P34*$X$2 -> 119574.4 | Y34: =+X34*IFERROR(VLOOKUP(J34,Tabla11[],4,0),0) -> 17936.16 | Z34: =IF(L34>0,$Z$2/12,0) -> 25833.333 | AA34: =P34-SUM(Q34:Z34) -> 20133.877 | AB34: =IF($L34<0,0,IFERROR((AB$2*IFERROR(VLOOKUP(J34,Tabla11[],2,0),0))*($L34/SUM($L$5:$L$46)),0)) -> 4209.6203 | AC34: =L34-L34*IFERROR(VLOOKUP(J34,Tabla11[],3,0),0)-Q34-T34-U34-V34-W34-L34*$X$2-(L34*$X$2)*IFERROR(VLOOKUP(J34,Tabla11[],4,0),0)-AB34-Z34 -> -58119.891 | AD34: =AA34-AB34 -> 15924.257 | AE34: =ROUND(AD34-AC34,9) -> 74044.148
B35: Outsourcing | E35: Outsourcing | G35: 3 | H35: Supervisor Regiones | I35: Viña del Mar | J35: Ripley | K35: Quilpue | L35: =IFERROR(VLOOKUP(CONCATENATE(J35,K35),Ventas!D:H,4,0),0) -> 375944.62 | M35: =IF(SUM(C35,F35)>0,L35*0.1,0) -> 0 | N35: =SUM(L35:M35) -> 375944.62 | O35: =N35*IFERROR(VLOOKUP(J35,Tabla11[],3,0),0) -> 131580.62 | P35: =N35-O35 -> 244364 | Q35: =IFERROR(G35/SUMIF(I:I,I35,G:G),0)*VLOOKUP(H35,Modelos[],14,0)+IFERROR(G35/SUMIF(I:I,I35,G:G),0)*VLOOKUP(I35,Tabla13[],2,0) -> 123633.06 | R35: =IFERROR(VLOOKUP(A35,Modelos[],IF(B35="EST",15,14),0),0)*C35 -> 0 | S35: =IFERROR(VLOOKUP(D35,Modelos[],IF(E35="EST",15,14),0),0)*F35 -> 0 | T35: =IF($L35<0,0,IFERROR((T$2*IFERROR(VLOOKUP(J35,Tabla11[],2,0),0))*($L35/SUM($L$5:$L$46)),0)) -> 2157.3853 | U35: =IF($L35<0,0,IFERROR((U$2*IFERROR(VLOOKUP(J35,Tabla11[],2,0),0))*($L35/SUM($L$5:$L$46)),0)) -> 419.49158 | V35: =IF($L35<0,0,IFERROR((V$2*IFERROR(VLOOKUP(J35,Tabla11[],2,0),0))*($L35/SUM($L$5:$L$46)),0)) -> 2157.3853 | W35: =IF($L35<0,0,IFERROR((W$2*IFERROR(VLOOKUP(J35,Tabla11[],2,0),0))*($L35/SUM($L$5:$L$46)),0)) -> 2996.3684 | X35: =P35*$X$2 -> 97745.6 | Y35: =+X35*IFERROR(VLOOKUP(J35,Tabla11[],4,0),0) -> 14661.84 | Z35: =IF(L35>0,$Z$2/12,0) -> 25833.333 | AA35: =P35-SUM(Q35:Z35) -> -25240.466 | AB35: =IF($L35<0,0,IFERROR((AB$2*IFERROR(VLOOKUP(J35,Tabla11[],2,0),0))*($L35/SUM($L$5:$L$46)),0)) -> 3441.1368 | AC35: =L35-L35*IFERROR(VLOOKUP(J35,Tabla11[],3,0),0)-Q35-T35-U35-V35-W35-L35*$X$2-(L35*$X$2)*IFERROR(VLOOKUP(J35,Tabla11[],4,0),0)-AB35-Z35 -> -89208.686 | AD35: =AA35-AB35 -> -28681.603 | AE35: =ROUND(AD35-AC35,9) -> 60527.083
B36: Outsourcing | E36: Outsourcing | G36: 0 | H36: Supervisor Santiago | I36: Santiago 02 | J36: Ripley | K36: Plaza Tobalaba | L36: =IFERROR(VLOOKUP(CONCATENATE(J36,K36),Ventas!D:H,4,0),0) -> 61570.769 | M36: =IF(SUM(C36,F36)>0,L36*0.1,0) -> 0 | N36: =SUM(L36:M36) -> 61570.769 | O36: =N36*IFERROR(VLOOKUP(J36,Tabla11[],3,0),0) -> 21549.769 | P36: =N36-O36 -> 40021 | Q36: =IFERROR(G36/SUMIF(I:I,I36,G:G),0)*VLOOKUP(H36,Modelos[],14,0)+IFERROR(G36/SUMIF(I:I,I36,G:G),0)*VLOOKUP(I36,Tabla13[],2,0) -> 0 | R36: =IFERROR(VLOOKUP(A36,Modelos[],IF(B36="EST",15,14),0),0)*C36 -> 0 | S36: =IFERROR(VLOOKUP(D36,Modelos[],IF(E36="EST",15,14),0),0)*F36 -> 0 | T36: =IF($L36<0,0,IFERROR((T$2*IFERROR(VLOOKUP(J36,Tabla11[],2,0),0))*($L36/SUM($L$5:$L$46)),0)) -> 353.3283 | U36: =IF($L36<0,0,IFERROR((U$2*IFERROR(VLOOKUP(J36,Tabla11[],2,0),0))*($L36/SUM($L$5:$L$46)),0)) -> 68.702725 | V36: =IF($L36<0,0,IFERROR((V$2*IFERROR(VLOOKUP(J36,Tabla11[],2,0),0))*($L36/SUM($L$5:$L$46)),0)) -> 353.3283 | W36: =IF($L36<0,0,IFERROR((W$2*IFERROR(VLOOKUP(J36,Tabla11[],2,0),0))*($L36/SUM($L$5:$L$46)),0)) -> 490.73375 | X36: =P36*$X$2 -> 16008.4 | Y36: =+X36*IFERROR(VLOOKUP(J36,Tabla11[],4,0),0) -> 2401.26 | Z36: =IF(L36>0,$Z$2/12,0) -> 25833.333 | AA36: =P36-SUM(Q36:Z36) -> -5488.0864 | AB36: =IF($L36<0,0,IFERROR((AB$2*IFERROR(VLOOKUP(J36,Tabla11[],2,0),0))*($L36/SUM($L$5:$L$46)),0)) -> 563.5762 | AC36: =L36-L36*IFERROR(VLOOKUP(J36,Tabla11[],3,0),0)-Q36-T36-U36-V36-W36-L36*$X$2-(L36*$X$2)*IFERROR(VLOOKUP(J36,Tabla11[],4,0),0)-AB36-Z36 -> -15964.556 | AD36: =AA36-AB36 -> -6051.6626 | AE36: =ROUND(AD36-AC36,9) -> 9912.8938
B37: Outsourcing | E37: Outsourcing | G37: 0 | H37: Supervisor Santiago | I37: Santiago 01 | J37: Ripley | K37: Alto las Condes | L37: =IFERROR(VLOOKUP(CONCATENATE(J37,K37),Ventas!D:H,4,0),0) -> 27861.538 | M37: =IF(SUM(C37,F37)>0,L37*0.1,0) -> 0 | N37: =SUM(L37:M37) -> 27861.538 | O37: =N37*IFERROR(VLOOKUP(J37,Tabla11[],3,0),0) -> 9751.5385 | P37: =N37-O37 -> 18110 | Q37: =IFERROR(G37/SUMIF(I:I,I37,G:G),0)*VLOOKUP(H37,Modelos[],14,0)+IFERROR(G37/SUMIF(I:I,I37,G:G),0)*VLOOKUP(I37,Tabla13[],2,0) -> 0 | R37: =IFERROR(VLOOKUP(A37,Modelos[],IF(B37="EST",15,14),0),0)*C37 -> 0 | S37: =IFERROR(VLOOKUP(D37,Modelos[],IF(E37="EST",15,14),0),0)*F37 -> 0 | T37: =IF($L37<0,0,IFERROR((T$2*IFERROR(VLOOKUP(J37,Tabla11[],2,0),0))*($L37/SUM($L$5:$L$46)),0)) -> 159.88545 | U37: =IF($L37<0,0,IFERROR((U$2*IFERROR(VLOOKUP(J37,Tabla11[],2,0),0))*($L37/SUM($L$5:$L$46)),0)) -> 31.088837 | V37: =IF($L37<0,0,IFERROR((V$2*IFERROR(VLOOKUP(J37,Tabla11[],2,0),0))*($L37/SUM($L$5:$L$46)),0)) -> 159.88545 | W37: =IF($L37<0,0,IFERROR((W$2*IFERROR(VLOOKUP(J37,Tabla11[],2,0),0))*($L37/SUM($L$5:$L$46)),0)) -> 222.06312 | X37: =P37*$X$2 -> 7244 | Y37: =+X37*IFERROR(VLOOKUP(J37,Tabla11[],4,0),0) -> 1086.6 | Z37: =IF(L37>0,$Z$2/12,0) -> 25833.333 | AA37: =P37-SUM(Q37:Z37) -> -16626.856 | AB37: =IF($L37<0,0,IFERROR((AB$2*IFERROR(VLOOKUP(J37,Tabla11[],2,0),0))*($L37/SUM($L$5:$L$46)),0)) -> 255.02524 | AC37: =L37-L37*IFERROR(VLOOKUP(J37,Tabla11[],3,0),0)-Q37-T37-U37-V37-W37-L37*$X$2-(L37*$X$2)*IFERROR(VLOOKUP(J37,Tabla11[],4,0),0)-AB37-Z37 -> -21367.589 | AD37: =AA37-AB37 -> -16881.881 | AE37: =ROUND(AD37-AC37,9) -> 4485.7077
A38: Vendedor 1/2 2 días | B38: Outsourcing | C38: 1 | E38: Outsourcing | G38: 3 | H38: Supervisor Regiones | I38: La Serena | J38: Ripley | K38: Coquimbo | L38: 1000000 | M38: =IF(SUM(C38,F38)>0,L38*0.1,0) -> 100000 | N38: =SUM(L38:M38) -> 1100000 | O38: =N38*IFERROR(VLOOKUP(J38,Tabla11[],3,0),0) -> 385000 | P38: =N38-O38 -> 715000 | Q38: =IFERROR(G38/SUMIF(I:I,I38,G:G),0)*VLOOKUP(H38,Modelos[],14,0)+IFERROR(G38/SUMIF(I:I,I38,G:G),0)*VLOOKUP(I38,Tabla13[],2,0) -> 161601.88 | R38: =IFERROR(VLOOKUP(A38,Modelos[],IF(B38="EST",15,14),0),0)*C38 -> 154393.47 | S38: =IFERROR(VLOOKUP(D38,Modelos[],IF(E38="EST",15,14),0),0)*F38 -> 0 | T38: =IF($L38<0,0,IFERROR((T$2*IFERROR(VLOOKUP(J38,Tabla11[],2,0),0))*($L38/SUM($L$5:$L$46)),0)) -> 5738.5721 | U38: =IF($L38<0,0,IFERROR((U$2*IFERROR(VLOOKUP(J38,Tabla11[],2,0),0))*($L38/SUM($L$5:$L$46)),0)) -> 1115.8335 | V38: =IF($L38<0,0,IFERROR((V$2*IFERROR(VLOOKUP(J38,Tabla11[],2,0),0))*($L38/SUM($L$5:$L$46)),0)) -> 5738.5721 | W38: =IF($L38<0,0,IFERROR((W$2*IFERROR(VLOOKUP(J38,Tabla11[],2,0),0))*($L38/SUM($L$5:$L$46)),0)) -> 7970.239 | X38: =P38*$X$2 -> 286000 | Y38: =+X38*IFERROR(VLOOKUP(J38,Tabla11[],4,0),0) -> 42900 | Z38: =IF(L38>0,$Z$2/12,0) -> 25833.333 | AA38: =P38-SUM(Q38:Z38) -> 23708.105 | AB38: =IF($L38<0,0,IFERROR((AB$2*IFERROR(VLOOKUP(J38,Tabla11[],2,0),0))*($L38/SUM($L$5:$L$46)),0)) -> 9153.3077 | AC38: =L38-L38*IFERROR(VLOOKUP(J38,Tabla11[],3,0),0)-Q38-T38-U38-V38-W38-L38*$X$2-(L38*$X$2)*IFERROR(VLOOKUP(J38,Tabla11[],4,0),0)-AB38-Z38 -> -27151.737 | AD38: =AA38-AB38 -> 14554.797 | AE38: =ROUND(AD38-AC38,9) -> 41706.534
A39: Vendedor 1/2 3 días | B39: Outsourcing | C39: 1 | E39: Outsourcing | G39: 3 | H39: Supervisor Part | I39: Arica | J39: Ripley | K39: Arica | L39: 1000000 | M39: =IF(SUM(C39,F39)>0,L39*0.1,0) -> 100000 | N39: =SUM(L39:M39) -> 1100000 | O39: =N39*IFERROR(VLOOKUP(J39,Tabla11[],3,0),0) -> 385000 | P39: =N39-O39 -> 715000 | Q39: =IFERROR(G39/SUMIF(I:I,I39,G:G),0)*VLOOKUP(H39,Modelos[],14,0)+IFERROR(G39/SUMIF(I:I,I39,G:G),0)*VLOOKUP(I39,Tabla13[],2,0) -> 121576.09 | R39: =IFERROR(VLOOKUP(A39,Modelos[],IF(B39="EST",15,14),0),0)*C39 -> 204526.8 | S39: =IFERROR(VLOOKUP(D39,Modelos[],IF(E39="EST",15,14),0),0)*F39 -> 0 | T39: =IF($L39<0,0,IFERROR((T$2*IFERROR(VLOOKUP(J39,Tabla11[],2,0),0))*($L39/SUM($L$5:$L$46)),0)) -> 5738.5721 | U39: =IF($L39<0,0,IFERROR((U$2*IFERROR(VLOOKUP(J39,Tabla11[],2,0),0))*($L39/SUM($L$5:$L$46)),0)) -> 1115.8335 | V39: =IF($L39<0,0,IFERROR((V$2*IFERROR(VLOOKUP(J39,Tabla11[],2,0),0))*($L39/SUM($L$5:$L$46)),0)) -> 5738.5721 | W39: =IF($L39<0,0,IFERROR((W$2*IFERROR(VLOOKUP(J39,Tabla11[],2,0),0))*($L39/SUM($L$5:$L$46)),0)) -> 7970.239 | X39: =P39*$X$2 -> 286000 | Y39: =+X39*IFERROR(VLOOKUP(J39,Tabla11[],4,0),0) -> 42900 | Z39: =IF(L39>0,$Z$2/12,0) -> 25833.333 | AA39: =P39-SUM(Q39:Z39) -> 13600.564 | AB39: =IF($L39<0,0,IFERROR((AB$2*IFERROR(VLOOKUP(J39,Tabla11[],2,0),0))*($L39/SUM($L$5:$L$46)),0)) -> 9153.3077 | AC39: =L39-L39*IFERROR(VLOOKUP(J39,Tabla11[],3,0),0)-Q39-T39-U39-V39-W39-L39*$X$2-(L39*$X$2)*IFERROR(VLOOKUP(J39,Tabla11[],4,0),0)-AB39-Z39 -> 12874.057 | AD39: =AA39-AB39 -> 4447.2565 | AE39: =ROUND(AD39-AC39,9) -> -8426.8004
B40: Outsourcing | E40: Outsourcing | G40: 3 | H40: Supervisor Santiago | I40: Santiago 01 | J40: Ripley | K40: Los Dominicos | L40: 1000000 | M40: =IF(SUM(C40,F40)>0,L40*0.1,0) -> 0 | N40: =SUM(L40:M40) -> 1000000 | O40: =N40*IFERROR(VLOOKUP(J40,Tabla11[],3,0),0) -> 350000 | P40: =N40-O40 -> 650000 | Q40: =IFERROR(G40/SUMIF(I:I,I40,G:G),0)*VLOOKUP(H40,Modelos[],14,0)+IFERROR(G40/SUMIF(I:I,I40,G:G),0)*VLOOKUP(I40,Tabla13[],2,0) -> 69504.988 | R40: =IFERROR(VLOOKUP(A40,Modelos[],IF(B40="EST",15,14),0),0)*C40 -> 0 | S40: =IFERROR(VLOOKUP(D40,Modelos[],IF(E40="EST",15,14),0),0)*F40 -> 0 | T40: =IF($L40<0,0,IFERROR((T$2*IFERROR(VLOOKUP(J40,Tabla11[],2,0),0))*($L40/SUM($L$5:$L$46)),0)) -> 5738.5721 | U40: =IF($L40<0,0,IFERROR((U$2*IFERROR(VLOOKUP(J40,Tabla11[],2,0),0))*($L40/SUM($L$5:$L$46)),0)) -> 1115.8335 | V40: =IF($L40<0,0,IFERROR((V$2*IFERROR(VLOOKUP(J40,Tabla11[],2,0),0))*($L40/SUM($L$5:$L$46)),0)) -> 5738.5721 | W40: =IF($L40<0,0,IFERROR((W$2*IFERROR(VLOOKUP(J40,Tabla11[],2,0),0))*($L40/SUM($L$5:$L$46)),0)) -> 7970.239 | X40: =P40*$X$2 -> 260000 | Y40: =+X40*IFERROR(VLOOKUP(J40,Tabla11[],4,0),0) -> 39000 | Z40: =IF(L40>0,$Z$2/12,0) -> 25833.333 | AA40: =P40-SUM(Q40:Z40) -> 235098.46 | AB40: =IF($L40<0,0,IFERROR((AB$2*IFERROR(VLOOKUP(J40,Tabla11[],2,0),0))*($L40/SUM($L$5:$L$46)),0)) -> 9153.3077 | AC40: =L40-L40*IFERROR(VLOOKUP(J40,Tabla11[],3,0),0)-Q40-T40-U40-V40-W40-L40*$X$2-(L40*$X$2)*IFERROR(VLOOKUP(J40,Tabla11[],4,0),0)-AB40-Z40 -> 64945.155 | AD40: =AA40-AB40 -> 225945.15 | AE40: =ROUND(AD40-AC40,9) -> 161000
