Workbook

Sheet Valores
A1: Feriados | C1: Día | D1: Ventas Semana | E1: % | H1: Día | I1: Cálculo 01 | J1: N° Semana | K1: Año | L1: Cálculo02 | M1: Pondera Día | N1: Calculo03 | O1: Peso Día Final | P1: Plata
A2: 43726 | C2: 1 | D2: 10000 | E2: =Valores!$D2/SUM(Valores!$D$2:$D$8) -> 0.1 | H2: 43709 | I2: =VLOOKUP(WEEKNUM(Valores!$H2,2)-WEEKNUM(EOMONTH(Valores!$H2,-1)+1,2)+1,Valores!$C$11:$F$16,IF((WEEKNUM(EOMONTH(H2,0),2)-WEEKNUM(EOMONTH(H2,-1)+1,2)+1)=4,2,IF((WEEKNUM(EOMONTH(H2,0),2)-WEEKNUM(EOMONTH(H2,-1)+1,2)+1)=5,3,IF((WEEKNUM(EOMONTH(H2,0),2)-WEEKNUM(EOMONTH(H2,-1)+1,2)+1)=6,4,0))),0) -> 0.25 | J2: =WEEKNUM(Valores!$H2,2) -> 35 | K2: 2019 | L2: =WEEKDAY(Valores!$H2,2) -> 7 | M2: 0.07 | N2: =Valores!$I2*Valores!$M2 -> 0.0175 | O2: =Valores!$N2/SUMIFS(Valores!$N$2:$N$154,Valores!$H$2:$H$154,">="&EOMONTH(Valores!$H2,-1)+1,Valores!$H$2:$H$154,"<="&EOMONTH(Valores!$H2,0)) -> 0.028797104 | P2: =Valores!$O2*7754000 -> 223292.74
A3: 43727 | C3: 2 | D3: 10000 | E3: =Valores!$D3/SUM(Valores!$D$2:$D$8) -> 0.1 | H3: 43710 | I3: =VLOOKUP(WEEKNUM(Valores!$H3,2)-WEEKNUM(EOMONTH(Valores!$H3,-1)+1,2)+1,Valores!$C$11:$F$16,IF((WEEKNUM(EOMONTH(H3,0),2)-WEEKNUM(EOMONTH(H3,-1)+1,2)+1)=4,2,IF((WEEKNUM(EOMONTH(H3,0),2)-WEEKNUM(EOMONTH(H3,-1)+1,2)+1)=5,3,IF((WEEKNUM(EOMONTH(H3,0),2)-WEEKNUM(EOMONTH(H3,-1)+1,2)+1)=6,4,0))),0) -> 0.12 | J3: =WEEKNUM(Valores!$H3,2) -> 36 | K3: 2019 | L3: =WEEKDAY(Valores!$H3,2) -> 1 | M3: =VLOOKUP(Valores!$L3,Valores!$C$2:$E$8,3,0) -> 0.1 | N3: =Valores!$I3*Valores!$M3 -> 0.012 | O3: =Valores!$N3/SUMIFS(Valores!$N$2:$N$154,Valores!$H$2:$H$154,">="&EOMONTH(Valores!$H3,-1)+1,Valores!$H$2:$H$154,"<="&EOMONTH(Valores!$H3,0)) -> 0.019746585 | P3: =Valores!$O3*7754000 -> 153115.02
A4: 43728 | C4: 3 | D4: 10000 | E4: =Valores!$D4/SUM(Valores!$D$2:$D$8) -> 0.1 | H4: 43711 | I4: =VLOOKUP(WEEKNUM(Valores!$H4,2)-WEEKNUM(EOMONTH(Valores!$H4,-1)+1,2)+1,Valores!$C$11:$F$16,IF((WEEKNUM(EOMONTH(H4,0),2)-WEEKNUM(EOMONTH(H4,-1)+1,2)+1)=4,2,IF((WEEKNUM(EOMONTH(H4,0),2)-WEEKNUM(EOMONTH(H4,-1)+1,2)+1)=5,3,IF((WEEKNUM(EOMONTH(H4,0),2)-WEEKNUM(EOMONTH(H4,-1)+1,2)+1)=6,4,0))),0) -> 0.12 | J4: =WEEKNUM(Valores!$H4,2) -> 36 | K4: 2019 | L4: =WEEKDAY(Valores!$H4,2) -> 2 | M4: =VLOOKUP(Valores!$L4,Valores!$C$2:$E$8,3,0) -> 0.1 | N4: =Valores!$I4*Valores!$M4 -> 0.012 | O4: =Valores!$N4/SUMIFS(Valores!$N$2:$N$154,Valores!$H$2:$H$154,">="&EOMONTH(Valores!$H4,-1)+1,Valores!$H$2:$H$154,"<="&EOMONTH(Valores!$H4,0)) -> 0.019746585 | P4: =Valores!$O4*7754000 -> 153115.02
A5: 43750 | C5: 4 | D5: 10000 | E5: =Valores!$D5/SUM(Valores!$D$2:$D$8) -> 0.1 | H5: 43712 | I5: =VLOOKUP(WEEKNUM(Valores!$H5,2)-WEEKNUM(EOMONTH(Valores!$H5,-1)+1,2)+1,Valores!$C$11:$F$16,IF((WEEKNUM(EOMONTH(H5,0),2)-WEEKNUM(EOMONTH(H5,-1)+1,2)+1)=4,2,IF((WEEKNUM(EOMONTH(H5,0),2)-WEEKNUM(EOMONTH(H5,-1)+1,2)+1)=5,3,IF((WEEKNUM(EOMONTH(H5,0),2)-WEEKNUM(EOMONTH(H5,-1)+1,2)+1)=6,4,0))),0) -> 0.12 | J5: =WEEKNUM(Valores!$H5,2) -> 36 | K5: 2019 | L5: =WEEKDAY(Valores!$H5,2) -> 3 | M5: =VLOOKUP(Valores!$L5,Valores!$C$2:$E$8,3,0) -> 0.1 | N5: =Valores!$I5*Valores!$M5 -> 0.012 | O5: =Valores!$N5/SUMIFS(Valores!$N$2:$N$154,Valores!$H$2:$H$154,">="&EOMONTH(Valores!$H5,-1)+1,Valores!$H$2:$H$154,"<="&EOMONTH(Valores!$H5,0)) -> 0.019746585 | P5: =Valores!$O5*7754000 -> 153115.02
A6: 43769 | C6: 5 | D6: 20000 | E6: =Valores!$D6/SUM(Valores!$D$2:$D$8) -> 0.2 | H6: 43713 | I6: =VLOOKUP(WEEKNUM(Valores!$H6,2)-WEEKNUM(EOMONTH(Valores!$H6,-1)+1,2)+1,Valores!$C$11:$F$16,IF((WEEKNUM(EOMONTH(H6,0),2)-WEEKNUM(EOMONTH(H6,-1)+1,2)+1)=4,2,IF((WEEKNUM(EOMONTH(H6,0),2)-WEEKNUM(EOMONTH(H6,-1)+1,2)+1)=5,3,IF((WEEKNUM(EOMONTH(H6,0),2)-WEEKNUM(EOMONTH(H6,-1)+1,2)+1)=6,4,0))),0) -> 0.12 | J6: =WEEKNUM(Valores!$H6,2) -> 36 | K6: 2019 | L6: =WEEKDAY(Valores!$H6,2) -> 4 | M6: =VLOOKUP(Valores!$L6,Valores!$C$2:$E$8,3,0) -> 0.1 | N6: =Valores!$I6*Valores!$M6 -> 0.012 | O6: =Valores!$N6/SUMIFS(Valores!$N$2:$N$154,Valores!$H$2:$H$154,">="&EOMONTH(Valores!$H6,-1)+1,Valores!$H$2:$H$154,"<="&EOMONTH(Valores!$H6,0)) -> 0.019746585 | P6: =Valores!$O6*7754000 -> 153115.02
A7: 43770 | C7: 6 | D7: 25000 | E7: =Valores!$D7/SUM(Valores!$D$2:$D$8) -> 0.25 | H7: 43714 | I7: =VLOOKUP(WEEKNUM(Valores!$H7,2)-WEEKNUM(EOMONTH(Valores!$H7,-1)+1,2)+1,Valores!$C$11:$F$16,IF((WEEKNUM(EOMONTH(H7,0),2)-WEEKNUM(EOMONTH(H7,-1)+1,2)+1)=4,2,IF((WEEKNUM(EOMONTH(H7,0),2)-WEEKNUM(EOMONTH(H7,-1)+1,2)+1)=5,3,IF((WEEKNUM(EOMONTH(H7,0),2)-WEEKNUM(EOMONTH(H7,-1)+1,2)+1)=6,4,0))),0) -> 0.12 | J7: =WEEKNUM(Valores!$H7,2) -> 36 | K7: 2019 | L7: =WEEKDAY(Valores!$H7,2) -> 5 | M7: =VLOOKUP(Valores!$L7,Valores!$C$2:$E$8,3,0) -> 0.2 | N7: =Valores!$I7*Valores!$M7 -> 0.024 | O7: =Valores!$N7/SUMIFS(Valores!$N$2:$N$154,Valores!$H$2:$H$154,">="&EOMONTH(Valores!$H7,-1)+1,Valores!$H$2:$H$154,"<="&EOMONTH(Valores!$H7,0)) -> 0.039493171 | P7: =Valores!$O7*7754000 -> 306230.05
A8: 43807 | C8: 7 | D8: 15000 | E8: =Valores!$D8/SUM(Valores!$D$2:$D$8) -> 0.15 | H8: 43715 | I8: =VLOOKUP(WEEKNUM(Valores!$H8,2)-WEEKNUM(EOMONTH(Valores!$H8,-1)+1,2)+1,Valores!$C$11:$F$16,IF((WEEKNUM(EOMONTH(H8,0),2)-WEEKNUM(EOMONTH(H8,-1)+1,2)+1)=4,2,IF((WEEKNUM(EOMONTH(H8,0),2)-WEEKNUM(EOMONTH(H8,-1)+1,2)+1)=5,3,IF((WEEKNUM(EOMONTH(H8,0),2)-WEEKNUM(EOMONTH(H8,-1)+1,2)+1)=6,4,0))),0) -> 0.12 | J8: =WEEKNUM(Valores!$H8,2) -> 36 | K8: 2019 | L8: =WEEKDAY(Valores!$H8,2) -> 6 | M8: =VLOOKUP(Valores!$L8,Valores!$C$2:$E$8,3,0) -> 0.25 | N8: =Valores!$I8*Valores!$M8 -> 0.03 | O8: =Valores!$N8/SUMIFS(Valores!$N$2:$N$154,Valores!$H$2:$H$154,">="&EOMONTH(Valores!$H8,-1)+1,Valores!$H$2:$H$154,"<="&EOMONTH(Valores!$H8,0)) -> 0.049366464 | P8: =Valores!$O8*7754000 -> 382787.56
A9: 43824 | H9: 43716 | I9: =VLOOKUP(WEEKNUM(Valores!$H9,2)-WEEKNUM(EOMONTH(Valores!$H9,-1)+1,2)+1,Valores!$C$11:$F$16,IF((WEEKNUM(EOMONTH(H9,0),2)-WEEKNUM(EOMONTH(H9,-1)+1,2)+1)=4,2,IF((WEEKNUM(EOMONTH(H9,0),2)-WEEKNUM(EOMONTH(H9,-1)+1,2)+1)=5,3,IF((WEEKNUM(EOMONTH(H9,0),2)-WEEKNUM(EOMONTH(H9,-1)+1,2)+1)=6,4,0))),0) -> 0.12 | J9: =WEEKNUM(Valores!$H9,2) -> 36 | K9: 2019 | L9: =WEEKDAY(Valores!$H9,2) -> 7 | M9: =VLOOKUP(Valores!$L9,Valores!$C$2:$E$8,3,0) -> 0.15 | N9: =Valores!$I9*Valores!$M9 -> 0.018 | O9: =Valores!$N9/SUMIFS(Valores!$N$2:$N$154,Valores!$H$2:$H$154,">="&EOMONTH(Valores!$H9,-1)+1,Valores!$H$2:$H$154,"<="&EOMONTH(Valores!$H9,0)) -> 0.029619878 | P9: =Valores!$O9*7754000 -> 229672.54
A10: 43831 | C10: Mes | D10: 4 SEMANAS | E10: 5 SEMANANAS | F10: 6 SEMANAS | H10: 43717 | I10: =VLOOKUP(WEEKNUM(Valores!$H10,2)-WEEKNUM(EOMONTH(Valores!$H10,-1)+1,2)+1,Valores!$C$11:$F$16,IF((WEEKNUM(EOMONTH(H10,0),2)-WEEKNUM(EOMONTH(H10,-1)+1,2)+1)=4,2,IF((WEEKNUM(EOMONTH(H10,0),2)-WEEKNUM(EOMONTH(H10,-1)+1,2)+1)=5,3,IF((WEEKNUM(EOMONTH(H10,0),2)-WEEKNUM(EOMONTH(H10,-1)+1,2)+1)=6,4,0))),0) -> 0.16 | J10: =WEEKNUM(Valores!$H10,2) -> 37 | K10: 2019 | L10: =WEEKDAY(Valores!$H10,2) -> 1 | M10: =VLOOKUP(Valores!$L10,Valores!$C$2:$E$8,3,0) -> 0.1 | N10: =Valores!$I10*Valores!$M10 -> 0.016 | O10: =Valores!$N10/SUMIFS(Valores!$N$2:$N$154,Valores!$H$2:$H$154,">="&EOMONTH(Valores!$H10,-1)+1,Valores!$H$2:$H$154,"<="&EOMONTH(Valores!$H10,0)) -> 0.026328781 | P10: =Valores!$O10*7754000 -> 204153.37
A11: 43931 | C11: 1 | D11: 0.32 | E11: 0.28 | F11: 0.25 | H11: 43718 | I11: =VLOOKUP(WEEKNUM(Valores!$H11,2)-WEEKNUM(EOMONTH(Valores!$H11,-1)+1,2)+1,Valores!$C$11:$F$16,IF((WEEKNUM(EOMONTH(H11,0),2)-WEEKNUM(EOMONTH(H11,-1)+1,2)+1)=4,2,IF((WEEKNUM(EOMONTH(H11,0),2)-WEEKNUM(EOMONTH(H11,-1)+1,2)+1)=5,3,IF((WEEKNUM(EOMONTH(H11,0),2)-WEEKNUM(EOMONTH(H11,-1)+1,2)+1)=6,4,0))),0) -> 0.16 | J11: =WEEKNUM(Valores!$H11,2) -> 37 | K11: 2019 | L11: =WEEKDAY(Valores!$H11,2) -> 2 | M11: =VLOOKUP(Valores!$L11,Valores!$C$2:$E$8,3,0) -> 0.1 | N11: =Valores!$I11*Valores!$M11 -> 0.016 | O11: =Valores!$N11/SUMIFS(Valores!$N$2:$N$154,Valores!$H$2:$H$154,">="&EOMONTH(Valores!$H11,-1)+1,Valores!$H$2:$H$154,"<="&EOMONTH(Valores!$H11,0)) -> 0.026328781 | P11: =Valores!$O11*7754000 -> 204153.37
A12: 43932 | C12: 2 | D12: 0.2 | E12: 0.15 | F12: 0.12 | H12: 43719 | I12: =VLOOKUP(WEEKNUM(Valores!$H12,2)-WEEKNUM(EOMONTH(Valores!$H12,-1)+1,2)+1,Valores!$C$11:$F$16,IF((WEEKNUM(EOMONTH(H12,0),2)-WEEKNUM(EOMONTH(H12,-1)+1,2)+1)=4,2,IF((WEEKNUM(EOMONTH(H12,0),2)-WEEKNUM(EOMONTH(H12,-1)+1,2)+1)=5,3,IF((WEEKNUM(EOMONTH(H12,0),2)-WEEKNUM(EOMONTH(H12,-1)+1,2)+1)=6,4,0))),0) -> 0.16 | J12: =WEEKNUM(Valores!$H12,2) -> 37 | K12: 2019 | L12: =WEEKDAY(Valores!$H12,2) -> 3 | M12: 0.06 | N12: =Valores!$I12*Valores!$M12 -> 0.0096 | O12: =Valores!$N12/SUMIFS(Valores!$N$2:$N$154,Valores!$H$2:$H$154,">="&EOMONTH(Valores!$H12,-1)+1,Valores!$H$2:$H$154,"<="&EOMONTH(Valores!$H12,0)) -> 0.015797268 | P12: =Valores!$O12*7754000 -> 122492.02
A13: 43952 | C13: 3 | D13: 0.23 | E13: 0.15 | F13: 0.16 | H13: 43720 | I13: =VLOOKUP(WEEKNUM(Valores!$H13,2)-WEEKNUM(EOMONTH(Valores!$H13,-1)+1,2)+1,Valores!$C$11:$F$16,IF((WEEKNUM(EOMONTH(H13,0),2)-WEEKNUM(EOMONTH(H13,-1)+1,2)+1)=4,2,IF((WEEKNUM(EOMONTH(H13,0),2)-WEEKNUM(EOMONTH(H13,-1)+1,2)+1)=5,3,IF((WEEKNUM(EOMONTH(H13,0),2)-WEEKNUM(EOMONTH(H13,-1)+1,2)+1)=6,4,0))),0) -> 0.16 | J13: =WEEKNUM(Valores!$H13,2) -> 37 | K13: 2019 | L13: =WEEKDAY(Valores!$H13,2) -> 4 | M13: =VLOOKUP(Valores!$L13,Valores!$C$2:$E$8,3,0) -> 0.1 | N13: =Valores!$I13*Valores!$M13 -> 0.016 | O13: =Valores!$N13/SUMIFS(Valores!$N$2:$N$154,Valores!$H$2:$H$154,">="&EOMONTH(Valores!$H13,-1)+1,Valores!$H$2:$H$154,"<="&EOMONTH(Valores!$H13,0)) -> 0.026328781 | P13: =Valores!$O13*7754000 -> 204153.37
A14: 43972 | C14: 4 | D14: 0.25 | E14: 0.2 | F14: 0.2 | H14: 43721 | I14: =VLOOKUP(WEEKNUM(Valores!$H14,2)-WEEKNUM(EOMONTH(Valores!$H14,-1)+1,2)+1,Valores!$C$11:$F$16,IF((WEEKNUM(EOMONTH(H14,0),2)-WEEKNUM(EOMONTH(H14,-1)+1,2)+1)=4,2,IF((WEEKNUM(EOMONTH(H14,0),2)-WEEKNUM(EOMONTH(H14,-1)+1,2)+1)=5,3,IF((WEEKNUM(EOMONTH(H14,0),2)-WEEKNUM(EOMONTH(H14,-1)+1,2)+1)=6,4,0))),0) -> 0.16 | J14: =WEEKNUM(Valores!$H14,2) -> 37 | K14: 2019 | L14: =WEEKDAY(Valores!$H14,2) -> 5 | M14: =VLOOKUP(Valores!$L14,Valores!$C$2:$E$8,3,0) -> 0.2 | N14: =Valores!$I14*Valores!$M14 -> 0.032 | O14: =Valores!$N14/SUMIFS(Valores!$N$2:$N$154,Valores!$H$2:$H$154,">="&EOMONTH(Valores!$H14,-1)+1,Valores!$H$2:$H$154,"<="&EOMONTH(Valores!$H14,0)) -> 0.052657561 | P14: =Valores!$O14*7754000 -> 408306.73
A15: 44011 | C15: 5 | E15: 0.22 | F15: 0.22 | H15: 43722 | I15: =VLOOKUP(WEEKNUM(Valores!$H15,2)-WEEKNUM(EOMONTH(Valores!$H15,-1)+1,2)+1,Valores!$C$11:$F$16,IF((WEEKNUM(EOMONTH(H15,0),2)-WEEKNUM(EOMONTH(H15,-1)+1,2)+1)=4,2,IF((WEEKNUM(EOMONTH(H15,0),2)-WEEKNUM(EOMONTH(H15,-1)+1,2)+1)=5,3,IF((WEEKNUM(EOMONTH(H15,0),2)-WEEKNUM(EOMONTH(H15,-1)+1,2)+1)=6,4,0))),0) -> 0.16 | J15: =WEEKNUM(Valores!$H15,2) -> 37 | K15: 2019 | L15: =WEEKDAY(Valores!$H15,2) -> 6 | M15: =VLOOKUP(Valores!$L15,Valores!$C$2:$E$8,3,0) -> 0.25 | N15: =Valores!$I15*Valores!$M15 -> 0.04 | O15: =Valores!$N15/SUMIFS(Valores!$N$2:$N$154,Valores!$H$2:$H$154,">="&EOMONTH(Valores!$H15,-1)+1,Valores!$H$2:$H$154,"<="&EOMONTH(Valores!$H15,0)) -> 0.065821952 | P15: =Valores!$O15*7754000 -> 510383.41
A16: 44028 | C16: 6 | F16: 0.05 | H16: 43723 | I16: =VLOOKUP(WEEKNUM(Valores!$H16,2)-WEEKNUM(EOMONTH(Valores!$H16,-1)+1,2)+1,Valores!$C$11:$F$16,IF((WEEKNUM(EOMONTH(H16,0),2)-WEEKNUM(EOMONTH(H16,-1)+1,2)+1)=4,2,IF((WEEKNUM(EOMONTH(H16,0),2)-WEEKNUM(EOMONTH(H16,-1)+1,2)+1)=5,3,IF((WEEKNUM(EOMONTH(H16,0),2)-WEEKNUM(EOMONTH(H16,-1)+1,2)+1)=6,4,0))),0) -> 0.16 | J16: =WEEKNUM(Valores!$H16,2) -> 37 | K16: 2019 | L16: =WEEKDAY(Valores!$H16,2) -> 7 | M16: =VLOOKUP(Valores!$L16,Valores!$C$2:$E$8,3,0) -> 0.15 | N16: =Valores!$I16*Valores!$M16 -> 0.024 | O16: =Valores!$N16/SUMIFS(Valores!$N$2:$N$154,Valores!$H$2:$H$154,">="&EOMONTH(Valores!$H16,-1)+1,Valores!$H$2:$H$154,"<="&EOMONTH(Valores!$H16,0)) -> 0.039493171 | P16: =Valores!$O16*7754000 -> 306230.05
A17: 44058 | C17: Total | D17: =SUBTOTAL(109,Valores!$D$11:$D$16) -> 1 | E17: =SUBTOTAL(109,Valores!$E$11:$E$16) -> 1 | F17: =SUBTOTAL(109,Valores!$F$11:$F$16) -> 1 | H17: 43724 | I17: =VLOOKUP(WEEKNUM(Valores!$H17,2)-WEEKNUM(EOMONTH(Valores!$H17,-1)+1,2)+1,Valores!$C$11:$F$16,IF((WEEKNUM(EOMONTH(H17,0),2)-WEEKNUM(EOMONTH(H17,-1)+1,2)+1)=4,2,IF((WEEKNUM(EOMONTH(H17,0),2)-WEEKNUM(EOMONTH(H17,-1)+1,2)+1)=5,3,IF((WEEKNUM(EOMONTH(H17,0),2)-WEEKNUM(EOMONTH(H17,-1)+1,2)+1)=6,4,0))),0) -> 0.2 | J17: =WEEKNUM(Valores!$H17,2) -> 38 | K17: 2019 | L17: =WEEKDAY(Valores!$H17,2) -> 1 | M17: =VLOOKUP(Valores!$L17,Valores!$C$2:$E$8,3,0) -> 0.1 | N17: =Valores!$I17*Valores!$M17 -> 0.02 | O17: =Valores!$N17/SUMIFS(Valores!$N$2:$N$154,Valores!$H$2:$H$154,">="&EOMONTH(Valores!$H17,-1)+1,Valores!$H$2:$H$154,"<="&EOMONTH(Valores!$H17,0)) -> 0.032910976 | P17: =Valores!$O17*7754000 -> 255191.71
A18: 44092 | H18: 43725 | I18: =VLOOKUP(WEEKNUM(Valores!$H18,2)-WEEKNUM(EOMONTH(Valores!$H18,-1)+1,2)+1,Valores!$C$11:$F$16,IF((WEEKNUM(EOMONTH(H18,0),2)-WEEKNUM(EOMONTH(H18,-1)+1,2)+1)=4,2,IF((WEEKNUM(EOMONTH(H18,0),2)-WEEKNUM(EOMONTH(H18,-1)+1,2)+1)=5,3,IF((WEEKNUM(EOMONTH(H18,0),2)-WEEKNUM(EOMONTH(H18,-1)+1,2)+1)=6,4,0))),0) -> 0.2 | J18: =WEEKNUM(Valores!$H18,2) -> 38 | K18: 2019 | L18: =WEEKDAY(Valores!$H18,2) -> 2 | M18: =VLOOKUP(Valores!$L18,Valores!$C$2:$E$8,3,0) -> 0.1 | N18: =Valores!$I18*Valores!$M18 -> 0.02 | O18: =Valores!$N18/SUMIFS(Valores!$N$2:$N$154,Valores!$H$2:$H$154,">="&EOMONTH(Valores!$H18,-1)+1,Valores!$H$2:$H$154,"<="&EOMONTH(Valores!$H18,0)) -> 0.032910976 | P18: =Valores!$O18*7754000 -> 255191.71
A19: 44093 | H19: 43726 | I19: =VLOOKUP(WEEKNUM(Valores!$H19,2)-WEEKNUM(EOMONTH(Valores!$H19,-1)+1,2)+1,Valores!$C$11:$F$16,IF((WEEKNUM(EOMONTH(H19,0),2)-WEEKNUM(EOMONTH(H19,-1)+1,2)+1)=4,2,IF((WEEKNUM(EOMONTH(H19,0),2)-WEEKNUM(EOMONTH(H19,-1)+1,2)+1)=5,3,IF((WEEKNUM(EOMONTH(H19,0),2)-WEEKNUM(EOMONTH(H19,-1)+1,2)+1)=6,4,0))),0) -> 0.2 | J19: =WEEKNUM(Valores!$H19,2) -> 38 | K19: 2019 | L19: =WEEKDAY(Valores!$H19,2) -> 3 | N19: =Valores!$I19*Valores!$M19 -> 0 | O19: =Valores!$N19/SUMIFS(Valores!$N$2:$N$154,Valores!$H$2:$H$154,">="&EOMONTH(Valores!$H19,-1)+1,Valores!$H$2:$H$154,"<="&EOMONTH(Valores!$H19,0)) -> 0 | P19: =Valores!$O19*7754000 -> 0
H20: 43727 | I20: =VLOOKUP(WEEKNUM(Valores!$H20,2)-WEEKNUM(EOMONTH(Valores!$H20,-1)+1,2)+1,Valores!$C$11:$F$16,IF((WEEKNUM(EOMONTH(H20,0),2)-WEEKNUM(EOMONTH(H20,-1)+1,2)+1)=4,2,IF((WEEKNUM(EOMONTH(H20,0),2)-WEEKNUM(EOMONTH(H20,-1)+1,2)+1)=5,3,IF((WEEKNUM(EOMONTH(H20,0),2)-WEEKNUM(EOMONTH(H20,-1)+1,2)+1)=6,4,0))),0) -> 0.2 | J20: =WEEKNUM(Valores!$H20,2) -> 38 | K20: 2019 | L20: =WEEKDAY(Valores!$H20,2) -> 4 | N20: =Valores!$I20*Valores!$M20 -> 0 | O20: =Valores!$N20/SUMIFS(Valores!$N$2:$N$154,Valores!$H$2:$H$154,">="&EOMONTH(Valores!$H20,-1)+1,Valores!$H$2:$H$154,"<="&EOMONTH(Valores!$H20,0)) -> 0 | P20: =Valores!$O20*7754000 -> 0
H21: 43728 | I21: =VLOOKUP(WEEKNUM(Valores!$H21,2)-WEEKNUM(EOMONTH(Valores!$H21,-1)+1,2)+1,Valores!$C$11:$F$16,IF((WEEKNUM(EOMONTH(H21,0),2)-WEEKNUM(EOMONTH(H21,-1)+1,2)+1)=4,2,IF((WEEKNUM(EOMONTH(H21,0),2)-WEEKNUM(EOMONTH(H21,-1)+1,2)+1)=5,3,IF((WEEKNUM(EOMONTH(H21,0),2)-WEEKNUM(EOMONTH(H21,-1)+1,2)+1)=6,4,0))),0) -> 0.2 | J21: =WEEKNUM(Valores!$H21,2) -> 38 | K21: 2019 | L21: =WEEKDAY(Valores!$H21,2) -> 5 | M21: 0.15 | N21: =Valores!$I21*Valores!$M21 -> 0.03 | O21: =Valores!$N21/SUMIFS(Valores!$N$2:$N$154,Valores!$H$2:$H$154,">="&EOMONTH(Valores!$H21,-1)+1,Valores!$H$2:$H$154,"<="&EOMONTH(Valores!$H21,0)) -> 0.049366464 | P21: =Valores!$O21*7754000 -> 382787.56
H22: 43729 | I22: =VLOOKUP(WEEKNUM(Valores!$H22,2)-WEEKNUM(EOMONTH(Valores!$H22,-1)+1,2)+1,Valores!$C$11:$F$16,IF((WEEKNUM(EOMONTH(H22,0),2)-WEEKNUM(EOMONTH(H22,-1)+1,2)+1)=4,2,IF((WEEKNUM(EOMONTH(H22,0),2)-WEEKNUM(EOMONTH(H22,-1)+1,2)+1)=5,3,IF((WEEKNUM(EOMONTH(H22,0),2)-WEEKNUM(EOMONTH(H22,-1)+1,2)+1)=6,4,0))),0) -> 0.2 | J22: =WEEKNUM(Valores!$H22,2) -> 38 | K22: 2019 | L22: =WEEKDAY(Valores!$H22,2) -> 6 | M22: 0.18 | N22: =Valores!$I22*Valores!$M22 -> 0.036 | O22: =Valores!$N22/SUMIFS(Valores!$N$2:$N$154,Valores!$H$2:$H$154,">="&EOMONTH(Valores!$H22,-1)+1,Valores!$H$2:$H$154,"<="&EOMONTH(Valores!$H22,0)) -> 0.059239756 | P22: =Valores!$O22*7754000 -> 459345.07
H23: 43730 | I23: =VLOOKUP(WEEKNUM(Valores!$H23,2)-WEEKNUM(EOMONTH(Valores!$H23,-1)+1,2)+1,Valores!$C$11:$F$16,IF((WEEKNUM(EOMONTH(H23,0),2)-WEEKNUM(EOMONTH(H23,-1)+1,2)+1)=4,2,IF((WEEKNUM(EOMONTH(H23,0),2)-WEEKNUM(EOMONTH(H23,-1)+1,2)+1)=5,3,IF((WEEKNUM(EOMONTH(H23,0),2)-WEEKNUM(EOMONTH(H23,-1)+1,2)+1)=6,4,0))),0) -> 0.2 | J23: =WEEKNUM(Valores!$H23,2) -> 38 | K23: 2019 | L23: =WEEKDAY(Valores!$H23,2) -> 7 | M23: 0.09 | N23: =Valores!$I23*Valores!$M23 -> 0.018 | O23: =Valores!$N23/SUMIFS(Valores!$N$2:$N$154,Valores!$H$2:$H$154,">="&EOMONTH(Valores!$H23,-1)+1,Valores!$H$2:$H$154,"<="&EOMONTH(Valores!$H23,0)) -> 0.029619878 | P23: =Valores!$O23*7754000 -> 229672.54
H24: 43731 | I24: =VLOOKUP(WEEKNUM(Valores!$H24,2)-WEEKNUM(EOMONTH(Valores!$H24,-1)+1,2)+1,Valores!$C$11:$F$16,IF((WEEKNUM(EOMONTH(H24,0),2)-WEEKNUM(EOMONTH(H24,-1)+1,2)+1)=4,2,IF((WEEKNUM(EOMONTH(H24,0),2)-WEEKNUM(EOMONTH(H24,-1)+1,2)+1)=5,3,IF((WEEKNUM(EOMONTH(H24,0),2)-WEEKNUM(EOMONTH(H24,-1)+1,2)+1)=6,4,0))),0) -> 0.22 | J24: =WEEKNUM(Valores!$H24,2) -> 39 | K24: 2019 | L24: =WEEKDAY(Valores!$H24,2) -> 1 | M24: =VLOOKUP(Valores!$L24,Valores!$C$2:$E$8,3,0) -> 0.1 | N24: =Valores!$I24*Valores!$M24 -> 0.022 | O24: =Valores!$N24/SUMIFS(Valores!$N$2:$N$154,Valores!$H$2:$H$154,">="&EOMONTH(Valores!$H24,-1)+1,Valores!$H$2:$H$154,"<="&EOMONTH(Valores!$H24,0)) -> 0.036202073 | P24: =Valores!$O24*7754000 -> 280710.88
H25: 43732 | I25: =VLOOKUP(WEEKNUM(Valores!$H25,2)-WEEKNUM(EOMONTH(Valores!$H25,-1)+1,2)+1,Valores!$C$11:$F$16,IF((WEEKNUM(EOMONTH(H25,0),2)-WEEKNUM(EOMONTH(H25,-1)+1,2)+1)=4,2,IF((WEEKNUM(EOMONTH(H25,0),2)-WEEKNUM(EOMONTH(H25,-1)+1,2)+1)=5,3,IF((WEEKNUM(EOMONTH(H25,0),2)-WEEKNUM(EOMONTH(H25,-1)+1,2)+1)=6,4,0))),0) -> 0.22 | J25: =WEEKNUM(Valores!$H25,2) -> 39 | K25: 2019 | L25: =WEEKDAY(Valores!$H25,2) -> 2 | M25: =VLOOKUP(Valores!$L25,Valores!$C$2:$E$8,3,0) -> 0.1 | N25: =Valores!$I25*Valores!$M25 -> 0.022 | O25: =Valores!$N25/SUMIFS(Valores!$N$2:$N$154,Valores!$H$2:$H$154,">="&EOMONTH(Valores!$H25,-1)+1,Valores!$H$2:$H$154,"<="&EOMONTH(Valores!$H25,0)) -> 0.036202073 | P25: =Valores!$O25*7754000 -> 280710.88
H26: 43733 | I26: =VLOOKUP(WEEKNUM(Valores!$H26,2)-WEEKNUM(EOMONTH(Valores!$H26,-1)+1,2)+1,Valores!$C$11:$F$16,IF((WEEKNUM(EOMONTH(H26,0),2)-WEEKNUM(EOMONTH(H26,-1)+1,2)+1)=4,2,IF((WEEKNUM(EOMONTH(H26,0),2)-WEEKNUM(EOMONTH(H26,-1)+1,2)+1)=5,3,IF((WEEKNUM(EOMONTH(H26,0),2)-WEEKNUM(EOMONTH(H26,-1)+1,2)+1)=6,4,0))),0) -> 0.22 | J26: =WEEKNUM(Valores!$H26,2) -> 39 | K26: 2019 | L26: =WEEKDAY(Valores!$H26,2) -> 3 | M26: =VLOOKUP(Valores!$L26,Valores!$C$2:$E$8,3,0) -> 0.1 | N26: =Valores!$I26*Valores!$M26 -> 0.022 | O26: =Valores!$N26/SUMIFS(Valores!$N$2:$N$154,Valores!$H$2:$H$154,">="&EOMONTH(Valores!$H26,-1)+1,Valores!$H$2:$H$154,"<="&EOMONTH(Valores!$H26,0)) -> 0.036202073 | P26: =Valores!$O26*7754000 -> 280710.88
H27: 43734 | I27: =VLOOKUP(WEEKNUM(Valores!$H27,2)-WEEKNUM(EOMONTH(Valores!$H27,-1)+1,2)+1,Valores!$C$11:$F$16,IF((WEEKNUM(EOMONTH(H27,0),2)-WEEKNUM(EOMONTH(H27,-1)+1,2)+1)=4,2,IF((WEEKNUM(EOMONTH(H27,0),2)-WEEKNUM(EOMONTH(H27,-1)+1,2)+1)=5,3,IF((WEEKNUM(EOMONTH(H27,0),2)-WEEKNUM(EOMONTH(H27,-1)+1,2)+1)=6,4,0))),0) -> 0.22 | J27: =WEEKNUM(Valores!$H27,2) -> 39 | K27: 2019 | L27: =WEEKDAY(Valores!$H27,2) -> 4 | M27: =VLOOKUP(Valores!$L27,Valores!$C$2:$E$8,3,0) -> 0.1 | N27: =Valores!$I27*Valores!$M27 -> 0.022 | O27: =Valores!$N27/SUMIFS(Valores!$N$2:$N$154,Valores!$H$2:$H$154,">="&EOMONTH(Valores!$H27,-1)+1,Valores!$H$2:$H$154,"<="&EOMONTH(Valores!$H27,0)) -> 0.036202073 | P27: =Valores!$O27*7754000 -> 280710.88
H28: 43735 | I28: =VLOOKUP(WEEKNUM(Valores!$H28,2)-WEEKNUM(EOMONTH(Valores!$H28,-1)+1,2)+1,Valores!$C$11:$F$16,IF((WEEKNUM(EOMONTH(H28,0),2)-WEEKNUM(EOMONTH(H28,-1)+1,2)+1)=4,2,IF((WEEKNUM(EOMONTH(H28,0),2)-WEEKNUM(EOMONTH(H28,-1)+1,2)+1)=5,3,IF((WEEKNUM(EOMONTH(H28,0),2)-WEEKNUM(EOMONTH(H28,-1)+1,2)+1)=6,4,0))),0) -> 0.22 | J28: =WEEKNUM(Valores!$H28,2) -> 39 | K28: 2019 | L28: =WEEKDAY(Valores!$H28,2) -> 5 | M28: 0.16 | N28: =Valores!$I28*Valores!$M28 -> 0.0352 | O28: =Valores!$N28/SUMIFS(Valores!$N$2:$N$154,Valores!$H$2:$H$154,">="&EOMONTH(Valores!$H28,-1)+1,Valores!$H$2:$H$154,"<="&EOMONTH(Valores!$H28,0)) -> 0.057923317 | P28: =Valores!$O28*7754000 -> 449137.4
H29: 43736 | I29: =VLOOKUP(WEEKNUM(Valores!$H29,2)-WEEKNUM(EOMONTH(Valores!$H29,-1)+1,2)+1,Valores!$C$11:$F$16,IF((WEEKNUM(EOMONTH(H29,0),2)-WEEKNUM(EOMONTH(H29,-1)+1,2)+1)=4,2,IF((WEEKNUM(EOMONTH(H29,0),2)-WEEKNUM(EOMONTH(H29,-1)+1,2)+1)=5,3,IF((WEEKNUM(EOMONTH(H29,0),2)-WEEKNUM(EOMONTH(H29,-1)+1,2)+1)=6,4,0))),0) -> 0.22 | J29: =WEEKNUM(Valores!$H29,2) -> 39 | K29: 2019 | L29: =WEEKDAY(Valores!$H29,2) -> 6 | M29: 0.2 | N29: =Valores!$I29*Valores!$M29 -> 0.044 | O29: =Valores!$N29/SUMIFS(Valores!$N$2:$N$154,Valores!$H$2:$H$154,">="&EOMONTH(Valores!$H29,-1)+1,Valores!$H$2:$H$154,"<="&EOMONTH(Valores!$H29,0)) -> 0.072404147 | P29: =Valores!$O29*7754000 -> 561421.75
H30: 43737 | I30: =VLOOKUP(WEEKNUM(Valores!$H30,2)-WEEKNUM(EOMONTH(Valores!$H30,-1)+1,2)+1,Valores!$C$11:$F$16,IF((WEEKNUM(EOMONTH(H30,0),2)-WEEKNUM(EOMONTH(H30,-1)+1,2)+1)=4,2,IF((WEEKNUM(EOMONTH(H30,0),2)-WEEKNUM(EOMONTH(H30,-1)+1,2)+1)=5,3,IF((WEEKNUM(EOMONTH(H30,0),2)-WEEKNUM(EOMONTH(H30,-1)+1,2)+1)=6,4,0))),0) -> 0.22 | J30: =WEEKNUM(Valores!$H30,2) -> 39 | K30: 2019 | L30: =WEEKDAY(Valores!$H30,2) -> 7 | M30: 0.07 | N30: =Valores!$I30*Valores!$M30 -> 0.0154 | O30: =Valores!$N30/SUMIFS(Valores!$N$2:$N$154,Valores!$H$2:$H$154,">="&EOMONTH(Valores!$H30,-1)+1,Valores!$H$2:$H$154,"<="&EOMONTH(Valores!$H30,0)) -> 0.025341451 | P30: =Valores!$O30*7754000 -> 196497.61
H31: 43738 | I31: =VLOOKUP(WEEKNUM(Valores!$H31,2)-WEEKNUM(EOMONTH(Valores!$H31,-1)+1,2)+1,Valores!$C$11:$F$16,IF((WEEKNUM(EOMONTH(H31,0),2)-WEEKNUM(EOMONTH(H31,-1)+1,2)+1)=4,2,IF((WEEKNUM(EOMONTH(H31,0),2)-WEEKNUM(EOMONTH(H31,-1)+1,2)+1)=5,3,IF((WEEKNUM(EOMONTH(H31,0),2)-WEEKNUM(EOMONTH(H31,-1)+1,2)+1)=6,4,0))),0) -> 0.05 | J31: =WEEKNUM(Valores!$H31,2) -> 40 | K31: 2019 | L31: =WEEKDAY(Valores!$H31,2) -> 1 | M31: 0.2 | N31: =Valores!$I31*Valores!$M31 -> 0.01 | O31: =Valores!$N31/SUMIFS(Valores!$N$2:$N$154,Valores!$H$2:$H$154,">="&EOMONTH(Valores!$H31,-1)+1,Valores!$H$2:$H$154,"<="&EOMONTH(Valores!$H31,0)) -> 0.016455488 | P31: =Valores!$O31*7754000 -> 127595.85
H32: 43739 | I32: =VLOOKUP(WEEKNUM(Valores!$H32,2)-WEEKNUM(EOMONTH(Valores!$H32,-1)+1,2)+1,Valores!$C$11:$F$16,IF((WEEKNUM(EOMONTH(H32,0),2)-WEEKNUM(EOMONTH(H32,-1)+1,2)+1)=4,2,IF((WEEKNUM(EOMONTH(H32,0),2)-WEEKNUM(EOMONTH(H32,-1)+1,2)+1)=5,3,IF((WEEKNUM(EOMONTH(H32,0),2)-WEEKNUM(EOMONTH(H32,-1)+1,2)+1)=6,4,0))),0) -> 0.28 | J32: =WEEKNUM(Valores!$H32,2) -> 40 | K32: 2019 | L32: =WEEKDAY(Valores!$H32,2) -> 2 | M32: =VLOOKUP(Valores!$L32,Valores!$C$2:$E$8,3,0) -> 0.1 | N32: =Valores!$I32*Valores!$M32 -> 0.028 | O32: =Valores!$N32/SUMIFS(Valores!$N$2:$N$154,Valores!$H$2:$H$154,">="&EOMONTH(Valores!$H32,-1)+1,Valores!$H$2:$H$154,"<="&EOMONTH(Valores!$H32,0)) -> 0.033342066 | P32: =Valores!$O32*7754000 -> 258534.38
H33: 43740 | I33: =VLOOKUP(WEEKNUM(Valores!$H33,2)-WEEKNUM(EOMONTH(Valores!$H33,-1)+1,2)+1,Valores!$C$11:$F$16,IF((WEEKNUM(EOMONTH(H33,0),2)-WEEKNUM(EOMONTH(H33,-1)+1,2)+1)=4,2,IF((WEEKNUM(EOMONTH(H33,0),2)-WEEKNUM(EOMONTH(H33,-1)+1,2)+1)=5,3,IF((WEEKNUM(EOMONTH(H33,0),2)-WEEKNUM(EOMONTH(H33,-1)+1,2)+1)=6,4,0))),0) -> 0.28 | J33: =WEEKNUM(Valores!$H33,2) -> 40 | K33: 2019 | L33: =WEEKDAY(Valores!$H33,2) -> 3 | M33: =VLOOKUP(Valores!$L33,Valores!$C$2:$E$8,3,0) -> 0.1 | N33: =Valores!$I33*Valores!$M33 -> 0.028 | O33: =Valores!$N33/SUMIFS(Valores!$N$2:$N$154,Valores!$H$2:$H$154,">="&EOMONTH(Valores!$H33,-1)+1,Valores!$H$2:$H$154,"<="&EOMONTH(Valores!$H33,0)) -> 0.033342066 | P33: =Valores!$O33*7754000 -> 258534.38
H34: 43741 | I34: =VLOOKUP(WEEKNUM(Valores!$H34,2)-WEEKNUM(EOMONTH(Valores!$H34,-1)+1,2)+1,Valores!$C$11:$F$16,IF((WEEKNUM(EOMONTH(H34,0),2)-WEEKNUM(EOMONTH(H34,-1)+1,2)+1)=4,2,IF((WEEKNUM(EOMONTH(H34,0),2)-WEEKNUM(EOMONTH(H34,-1)+1,2)+1)=5,3,IF((WEEKNUM(EOMONTH(H34,0),2)-WEEKNUM(EOMONTH(H34,-1)+1,2)+1)=6,4,0))),0) -> 0.28 | J34: =WEEKNUM(Valores!$H34,2) -> 40 | K34: 2019 | L34: =WEEKDAY(Valores!$H34,2) -> 4 | M34: =VLOOKUP(Valores!$L34,Valores!$C$2:$E$8,3,0) -> 0.1 | N34: =Valores!$I34*Valores!$M34 -> 0.028 | O34: =Valores!$N34/SUMIFS(Valores!$N$2:$N$154,Valores!$H$2:$H$154,">="&EOMONTH(Valores!$H34,-1)+1,Valores!$H$2:$H$154,"<="&EOMONTH(Valores!$H34,0)) -> 0.033342066 | P34: =Valores!$O34*7754000 -> 258534.38
H35: 43742 | I35: =VLOOKUP(WEEKNUM(Valores!$H35,2)-WEEKNUM(EOMONTH(Valores!$H35,-1)+1,2)+1,Valores!$C$11:$F$16,IF((WEEKNUM(EOMONTH(H35,0),2)-WEEKNUM(EOMONTH(H35,-1)+1,2)+1)=4,2,IF((WEEKNUM(EOMONTH(H35,0),2)-WEEKNUM(EOMONTH(H35,-1)+1,2)+1)=5,3,IF((WEEKNUM(EOMONTH(H35,0),2)-WEEKNUM(EOMONTH(H35,-1)+1,2)+1)=6,4,0))),0) -> 0.28 | J35: =WEEKNUM(Valores!$H35,2) -> 40 | K35: 2019 | L35: =WEEKDAY(Valores!$H35,2) -> 5 | M35: =VLOOKUP(Valores!$L35,Valores!$C$2:$E$8,3,0) -> 0.2 | N35: =Valores!$I35*Valores!$M35 -> 0.056 | O35: =Valores!$N35/SUMIFS(Valores!$N$2:$N$154,Valores!$H$2:$H$154,">="&EOMONTH(Valores!$H35,-1)+1,Valores!$H$2:$H$154,"<="&EOMONTH(Valores!$H35,0)) -> 0.066684132 | P35: =Valores!$O35*7754000 -> 517068.76
H36: 43743 | I36: =VLOOKUP(WEEKNUM(Valores!$H36,2)-WEEKNUM(EOMONTH(Valores!$H36,-1)+1,2)+1,Valores!$C$11:$F$16,IF((WEEKNUM(EOMONTH(H36,0),2)-WEEKNUM(EOMONTH(H36,-1)+1,2)+1)=4,2,IF((WEEKNUM(EOMONTH(H36,0),2)-WEEKNUM(EOMONTH(H36,-1)+1,2)+1)=5,3,IF((WEEKNUM(EOMONTH(H36,0),2)-WEEKNUM(EOMONTH(H36,-1)+1,2)+1)=6,4,0))),0) -> 0.28 | J36: =WEEKNUM(Valores!$H36,2) -> 40 | K36: 2019 | L36: =WEEKDAY(Valores!$H36,2) -> 6 | M36: =VLOOKUP(Valores!$L36,Valores!$C$2:$E$8,3,0) -> 0.25 | N36: =Valores!$I36*Valores!$M36 -> 0.07 | O36: =Valores!$N36/SUMIFS(Valores!$N$2:$N$154,Valores!$H$2:$H$154,">="&EOMONTH(Valores!$H36,-1)+1,Valores!$H$2:$H$154,"<="&EOMONTH(Valores!$H36,0)) -> 0.083355164 | P36: =Valores!$O36*7754000 -> 646335.95
H37: 43744 | I37: =VLOOKUP(WEEKNUM(Valores!$H37,2)-WEEKNUM(EOMONTH(Valores!$H37,-1)+1,2)+1,Valores!$C$11:$F$16,IF((WEEKNUM(EOMONTH(H37,0),2)-WEEKNUM(EOMONTH(H37,-1)+1,2)+1)=4,2,IF((WEEKNUM(EOMONTH(H37,0),2)-WEEKNUM(EOMONTH(H37,-1)+1,2)+1)=5,3,IF((WEEKNUM(EOMONTH(H37,0),2)-WEEKNUM(EOMONTH(H37,-1)+1,2)+1)=6,4,0))),0) -> 0.28 | J37: =WEEKNUM(Valores!$H37,2) -> 40 | K37: 2019 | L37: =WEEKDAY(Valores!$H37,2) -> 7 | M37: =VLOOKUP(Valores!$L37,Valores!$C$2:$E$8,3,0) -> 0.15 | N37: =Valores!$I37*Valores!$M37 -> 0.042 | O37: =Valores!$N37/SUMIFS(Valores!$N$2:$N$154,Valores!$H$2:$H$154,">="&EOMONTH(Valores!$H37,-1)+1,Valores!$H$2:$H$154,"<="&EOMONTH(Valores!$H37,0)) -> 0.050013099 | P37: =Valores!$O37*7754000 -> 387801.57
H38: 43745 | I38: =VLOOKUP(WEEKNUM(Valores!$H38,2)-WEEKNUM(EOMONTH(Valores!$H38,-1)+1,2)+1,Valores!$C$11:$F$16,IF((WEEKNUM(EOMONTH(H38,0),2)-WEEKNUM(EOMONTH(H38,-1)+1,2)+1)=4,2,IF((WEEKNUM(EOMONTH(H38,0),2)-WEEKNUM(EOMONTH(H38,-1)+1,2)+1)=5,3,IF((WEEKNUM(EOMONTH(H38,0),2)-WEEKNUM(EOMONTH(H38,-1)+1,2)+1)=6,4,0))),0) -> 0.15 | J38: =WEEKNUM(Valores!$H38,2) -> 41 | K38: 2019 | L38: =WEEKDAY(Valores!$H38,2) -> 1 | M38: =VLOOKUP(Valores!$L38,Valores!$C$2:$E$8,3,0) -> 0.1 | N38: =Valores!$I38*Valores!$M38 -> 0.015 | O38: =Valores!$N38/SUMIFS(Valores!$N$2:$N$154,Valores!$H$2:$H$154,">="&EOMONTH(Valores!$H38,-1)+1,Valores!$H$2:$H$154,"<="&EOMONTH(Valores!$H38,0)) -> 0.017861821 | P38: =Valores!$O38*7754000 -> 138500.56
H39: 43746 | I39: =VLOOKUP(WEEKNUM(Valores!$H39,2)-WEEKNUM(EOMONTH(Valores!$H39,-1)+1,2)+1,Valores!$C$11:$F$16,IF((WEEKNUM(EOMONTH(H39,0),2)-WEEKNUM(EOMONTH(H39,-1)+1,2)+1)=4,2,IF((WEEKNUM(EOMONTH(H39,0),2)-WEEKNUM(EOMONTH(H39,-1)+1,2)+1)=5,3,IF((WEEKNUM(EOMONTH(H39,0),2)-WEEKNUM(EOMONTH(H39,-1)+1,2)+1)=6,4,0))),0) -> 0.15 | J39: =WEEKNUM(Valores!$H39,2) -> 41 | K39: 2019 | L39: =WEEKDAY(Valores!$H39,2) -> 2 | M39: =VLOOKUP(Valores!$L39,Valores!$C$2:$E$8,3,0) -> 0.1 | N39: =Valores!$I39*Valores!$M39 -> 0.015 | O39: =Valores!$N39/SUMIFS(Valores!$N$2:$N$154,Valores!$H$2:$H$154,">="&EOMONTH(Valores!$H39,-1)+1,Valores!$H$2:$H$154,"<="&EOMONTH(Valores!$H39,0)) -> 0.017861821 | P39: =Valores!$O39*7754000 -> 138500.56
H40: 43747 | I40: =VLOOKUP(WEEKNUM(Valores!$H40,2)-WEEKNUM(EOMONTH(Valores!$H40,-1)+1,2)+1,Valores!$C$11:$F$16,IF((WEEKNUM(EOMONTH(H40,0),2)-WEEKNUM(EOMONTH(H40,-1)+1,2)+1)=4,2,IF((WEEKNUM(EOMONTH(H40,0),2)-WEEKNUM(EOMONTH(H40,-1)+1,2)+1)=5,3,IF((WEEKNUM(EOMONTH(H40,0),2)-WEEKNUM(EOMONTH(H40,-1)+1,2)+1)=6,4,0))),0) -> 0.15 | J40: =WEEKNUM(Valores!$H40,2) -> 41 | K40: 2019 | L40: =WEEKDAY(Valores!$H40,2) -> 3 | M40: =VLOOKUP(Valores!$L40,Valores!$C$2:$E$8,3,0) -> 0.1 | N40: =Valores!$I40*Valores!$M40 -> 0.015 | O40: =Valores!$N40/SUMIFS(Valores!$N$2:$N$154,Valores!$H$2:$H$154,">="&EOMONTH(Valores!$H40,-1)+1,Valores!$H$2:$H$154,"<="&EOMONTH(Valores!$H40,0)) -> 0.017861821 | P40: =Valores!$O40*7754000 -> 138500.56
...

Sheet Matríz Tiendas
A1: Cadena | B1: Tienda | C1: Meta | D1: Meta | E1: Meta | F1: Meta | G1: SEPTIEMBRE 2019 | AK1: OCTUBRE 2019 | BP1: NOVIEMBRE 2019 | CT1: 43800
C2: 43709 | D2: 43739 | E2: 43770 | F2: 43800 | G2: 43709 | H2: 43710 | I2: 43711 | J2: 43712 | K2: 43713 | L2: 43714 | M2: 43715 | N2: 43716 | O2: 43717 | P2: 43718 | Q2: 43719 | R2: 43720 | S2: 43721 | T2: 43722 | U2: 43723 | V2: 43724 | W2: 43725 | X2: 43726 | Y2: 43727 | Z2: 43728 | AA2: 43729 | AB2: 43730 | AC2: 43731 | AD2: 43732 | AE2: 43733 | AF2: 43734 | AG2: 43735 | AH2: 43736 | AI2: 43737 | AJ2: 43738 | AK2: 43739 | AL2: 43740 | AM2: 43741 | AN2: 43742 | AO2: 43743 | AP2: 43744 | AQ2: 43745 | AR2: 43746 | AS2: 43747 | AT2: 43748 | AU2: 43749 | AV2: 43750 | AW2: 43751 | AX2: 43752 | AY2: 43753 | AZ2: 43754 | BA2: 43755 | BB2: 43756 | BC2: 43757 | BD2: 43758 | BE2: 43759 | BF2: 43760 | BG2: 43761 | BH2: 43762 | BI2: 43763 | BJ2: 43764 | BK2: 43765 | BL2: 43766 | BM2: 43767 | BN2: 43768 | BO2: 43769 | BP2: 43770 | BQ2: 43771 | BR2: 43772 | BS2: 43773 | BT2: 43774 | BU2: 43775 | BV2: 43776 | BW2: 43777 | BX2: 43778 | BY2: 43779 | BZ2: 43780 | CA2: 43781 | CB2: 43782 | CC2: 43783 | CD2: 43784 | CE2: 43785 | CF2: 43786 | CG2: 43787 | CH2: 43788 | CI2: 43789 | CJ2: 43790 | CK2: 43791 | CL2: 43792 | CM2: 43793 | CN2: 43794 | CO2: 43795 | CP2: 43796 | CQ2: 43797 | CR2: 43798 | CS2: 43799 | CT2: 43800 | CU2: 43801 | CV2: 43802 | CW2: 43803 | CX2: 43804 | CY2: 43805 | CZ2: 43806 | DA2: 43807 | DB2: 43808 | DC2: 43809 | DD2: 43810 | DE2: 43811 | DF2: 43812 | DG2: 43813 | DH2: 43814 | DI2: 43815 | DJ2: 43816 | DK2: 43817 | DL2: 43818 | DM2: 43819 | DN2: 43820 | DO2: 43821 | DP2: 43822 | DQ2: 43823 | DR2: 43824 | DS2: 43825 | DT2: 43826 | DU2: 43827 | DV2: 43828 | DW2: 43829 | DX2: 43830
A3: Ripley | B3: Talca | C3: 3154790 | D3: 2839311 | E3: 2555379.9 | F3: 10000000 | G3: =SUMIF($C$2:$F$2,EOMONTH(G$2,-1)+1,$C3:$F3)*VLOOKUP(G$2,Valores!$H$2:$P$154,8,0) -> 90848.815 | H3: =SUMIF($C$2:$F$2,EOMONTH(H$2,-1)+1,$C3:$F3)*VLOOKUP(H$2,Valores!$H$2:$P$154,8,0) -> 62296.33 | I3: =SUMIF($C$2:$F$2,EOMONTH(I$2,-1)+1,$C3:$F3)*VLOOKUP(I$2,Valores!$H$2:$P$154,8,0) -> 62296.33 | J3: =SUMIF($C$2:$F$2,EOMONTH(J$2,-1)+1,$C3:$F3)*VLOOKUP(J$2,Valores!$H$2:$P$154,8,0) -> 62296.33 | K3: =SUMIF($C$2:$F$2,EOMONTH(K$2,-1)+1,$C3:$F3)*VLOOKUP(K$2,Valores!$H$2:$P$154,8,0) -> 62296.33 | L3: =SUMIF($C$2:$F$2,EOMONTH(L$2,-1)+1,$C3:$F3)*VLOOKUP(L$2,Valores!$H$2:$P$154,8,0) -> 124592.66 | M3: =SUMIF($C$2:$F$2,EOMONTH(M$2,-1)+1,$C3:$F3)*VLOOKUP(M$2,Valores!$H$2:$P$154,8,0) -> 155740.83 | N3: =SUMIF($C$2:$F$2,EOMONTH(N$2,-1)+1,$C3:$F3)*VLOOKUP(N$2,Valores!$H$2:$P$154,8,0) -> 93444.496 | ... DX3: =SUMIF($C$2:$F$2,EOMONTH(DX$2,-1)+1,$C3:$F3)*VLOOKUP(DX$2,Valores!$H$2:$P$154,8,0) -> #VALUE!
A4: Ripley | B4: Temuco | C4: 3075077 | D4: 2767569.3 | E4: 2490812.4 | F4: 2241731.1 | G4: =SUMIF($C$2:$F$2,EOMONTH(G$2,-1)+1,$C4:$F4)*VLOOKUP(G$2,Valores!$H$2:$P$154,8,0) -> 88553.312 | H4: =SUMIF($C$2:$F$2,EOMONTH(H$2,-1)+1,$C4:$F4)*VLOOKUP(H$2,Valores!$H$2:$P$154,8,0) -> 60722.271 | I4: =SUMIF($C$2:$F$2,EOMONTH(I$2,-1)+1,$C4:$F4)*VLOOKUP(I$2,Valores!$H$2:$P$154,8,0) -> 60722.271 | J4: =SUMIF($C$2:$F$2,EOMONTH(J$2,-1)+1,$C4:$F4)*VLOOKUP(J$2,Valores!$H$2:$P$154,8,0) -> 60722.271 | K4: =SUMIF($C$2:$F$2,EOMONTH(K$2,-1)+1,$C4:$F4)*VLOOKUP(K$2,Valores!$H$2:$P$154,8,0) -> 60722.271 | L4: =SUMIF($C$2:$F$2,EOMONTH(L$2,-1)+1,$C4:$F4)*VLOOKUP(L$2,Valores!$H$2:$P$154,8,0) -> 121444.54 | M4: =SUMIF($C$2:$F$2,EOMONTH(M$2,-1)+1,$C4:$F4)*VLOOKUP(M$2,Valores!$H$2:$P$154,8,0) -> 151805.68 | N4: =SUMIF($C$2:$F$2,EOMONTH(N$2,-1)+1,$C4:$F4)*VLOOKUP(N$2,Valores!$H$2:$P$154,8,0) -> 91083.406 | ... DX4: =SUMIF($C$2:$F$2,EOMONTH(DX$2,-1)+1,$C4:$F4)*VLOOKUP(DX$2,Valores!$H$2:$P$154,8,0) -> #VALUE!
A5: Ripley | B5: La Calera | C5: 2882749 | D5: 2594474.1 | E5: 2335026.7 | F5: 2101524 | G5: =SUMIF($C$2:$F$2,EOMONTH(G$2,-1)+1,$C5:$F5)*VLOOKUP(G$2,Valores!$H$2:$P$154,8,0) -> 83014.822 | H5: =SUMIF($C$2:$F$2,EOMONTH(H$2,-1)+1,$C5:$F5)*VLOOKUP(H$2,Valores!$H$2:$P$154,8,0) -> 56924.45 | I5: =SUMIF($C$2:$F$2,EOMONTH(I$2,-1)+1,$C5:$F5)*VLOOKUP(I$2,Valores!$H$2:$P$154,8,0) -> 56924.45 | J5: =SUMIF($C$2:$F$2,EOMONTH(J$2,-1)+1,$C5:$F5)*VLOOKUP(J$2,Valores!$H$2:$P$154,8,0) -> 56924.45 | K5: =SUMIF($C$2:$F$2,EOMONTH(K$2,-1)+1,$C5:$F5)*VLOOKUP(K$2,Valores!$H$2:$P$154,8,0) -> 56924.45 | L5: =SUMIF($C$2:$F$2,EOMONTH(L$2,-1)+1,$C5:$F5)*VLOOKUP(L$2,Valores!$H$2:$P$154,8,0) -> 113848.9 | M5: =SUMIF($C$2:$F$2,EOMONTH(M$2,-1)+1,$C5:$F5)*VLOOKUP(M$2,Valores!$H$2:$P$154,8,0) -> 142311.12 | N5: =SUMIF($C$2:$F$2,EOMONTH(N$2,-1)+1,$C5:$F5)*VLOOKUP(N$2,Valores!$H$2:$P$154,8,0) -> 85386.674 | ... DX5: =SUMIF($C$2:$F$2,EOMONTH(DX$2,-1)+1,$C5:$F5)*VLOOKUP(DX$2,Valores!$H$2:$P$154,8,0) -> #VALUE!
A6: Ripley | B6: Costanera Center | C6: 2658456 | D6: 2392610.4 | E6: 2153349.4 | F6: 1938014.4 | G6: =SUMIF($C$2:$F$2,EOMONTH(G$2,-1)+1,$C6:$F6)*VLOOKUP(G$2,Valores!$H$2:$P$154,8,0) -> 76555.833 | H6: =SUMIF($C$2:$F$2,EOMONTH(H$2,-1)+1,$C6:$F6)*VLOOKUP(H$2,Valores!$H$2:$P$154,8,0) -> 52495.429 | I6: =SUMIF($C$2:$F$2,EOMONTH(I$2,-1)+1,$C6:$F6)*VLOOKUP(I$2,Valores!$H$2:$P$154,8,0) -> 52495.429 | J6: =SUMIF($C$2:$F$2,EOMONTH(J$2,-1)+1,$C6:$F6)*VLOOKUP(J$2,Valores!$H$2:$P$154,8,0) -> 52495.429 | K6: =SUMIF($C$2:$F$2,EOMONTH(K$2,-1)+1,$C6:$F6)*VLOOKUP(K$2,Valores!$H$2:$P$154,8,0) -> 52495.429 | L6: =SUMIF($C$2:$F$2,EOMONTH(L$2,-1)+1,$C6:$F6)*VLOOKUP(L$2,Valores!$H$2:$P$154,8,0) -> 104990.86 | M6: =SUMIF($C$2:$F$2,EOMONTH(M$2,-1)+1,$C6:$F6)*VLOOKUP(M$2,Valores!$H$2:$P$154,8,0) -> 131238.57 | N6: =SUMIF($C$2:$F$2,EOMONTH(N$2,-1)+1,$C6:$F6)*VLOOKUP(N$2,Valores!$H$2:$P$154,8,0) -> 78743.143 | ... DX6: =SUMIF($C$2:$F$2,EOMONTH(DX$2,-1)+1,$C6:$F6)*VLOOKUP(DX$2,Valores!$H$2:$P$154,8,0) -> #VALUE!
A7: Ripley | B7: Curico | C7: 2250873 | D7: 2025785.7 | E7: 1823207.1 | F7: 1640886.4 | G7: =SUMIF($C$2:$F$2,EOMONTH(G$2,-1)+1,$C7:$F7)*VLOOKUP(G$2,Valores!$H$2:$P$154,8,0) -> 64818.623 | H7: =SUMIF($C$2:$F$2,EOMONTH(H$2,-1)+1,$C7:$F7)*VLOOKUP(H$2,Valores!$H$2:$P$154,8,0) -> 44447.056 | I7: =SUMIF($C$2:$F$2,EOMONTH(I$2,-1)+1,$C7:$F7)*VLOOKUP(I$2,Valores!$H$2:$P$154,8,0) -> 44447.056 | J7: =SUMIF($C$2:$F$2,EOMONTH(J$2,-1)+1,$C7:$F7)*VLOOKUP(J$2,Valores!$H$2:$P$154,8,0) -> 44447.056 | K7: =SUMIF($C$2:$F$2,EOMONTH(K$2,-1)+1,$C7:$F7)*VLOOKUP(K$2,Valores!$H$2:$P$154,8,0) -> 44447.056 | L7: =SUMIF($C$2:$F$2,EOMONTH(L$2,-1)+1,$C7:$F7)*VLOOKUP(L$2,Valores!$H$2:$P$154,8,0) -> 88894.112 | M7: =SUMIF($C$2:$F$2,EOMONTH(M$2,-1)+1,$C7:$F7)*VLOOKUP(M$2,Valores!$H$2:$P$154,8,0) -> 111117.64 | N7: =SUMIF($C$2:$F$2,EOMONTH(N$2,-1)+1,$C7:$F7)*VLOOKUP(N$2,Valores!$H$2:$P$154,8,0) -> 66670.584 | ... DX7: =SUMIF($C$2:$F$2,EOMONTH(DX$2,-1)+1,$C7:$F7)*VLOOKUP(DX$2,Valores!$H$2:$P$154,8,0) -> #VALUE!
A8: Ripley | B8: Marina Arauco | C8: 2164213 | D8: 1947791.7 | E8: 1753012.5 | F8: 1577711.3 | G8: =SUMIF($C$2:$F$2,EOMONTH(G$2,-1)+1,$C8:$F8)*VLOOKUP(G$2,Valores!$H$2:$P$154,8,0) -> 62323.066 | H8: =SUMIF($C$2:$F$2,EOMONTH(H$2,-1)+1,$C8:$F8)*VLOOKUP(H$2,Valores!$H$2:$P$154,8,0) -> 42735.817 | I8: =SUMIF($C$2:$F$2,EOMONTH(I$2,-1)+1,$C8:$F8)*VLOOKUP(I$2,Valores!$H$2:$P$154,8,0) -> 42735.817 | J8: =SUMIF($C$2:$F$2,EOMONTH(J$2,-1)+1,$C8:$F8)*VLOOKUP(J$2,Valores!$H$2:$P$154,8,0) -> 42735.817 | K8: =SUMIF($C$2:$F$2,EOMONTH(K$2,-1)+1,$C8:$F8)*VLOOKUP(K$2,Valores!$H$2:$P$154,8,0) -> 42735.817 | L8: =SUMIF($C$2:$F$2,EOMONTH(L$2,-1)+1,$C8:$F8)*VLOOKUP(L$2,Valores!$H$2:$P$154,8,0) -> 85471.634 | M8: =SUMIF($C$2:$F$2,EOMONTH(M$2,-1)+1,$C8:$F8)*VLOOKUP(M$2,Valores!$H$2:$P$154,8,0) -> 106839.54 | N8: =SUMIF($C$2:$F$2,EOMONTH(N$2,-1)+1,$C8:$F8)*VLOOKUP(N$2,Valores!$H$2:$P$154,8,0) -> 64103.726 | ... DX8: =SUMIF($C$2:$F$2,EOMONTH(DX$2,-1)+1,$C8:$F8)*VLOOKUP(DX$2,Valores!$H$2:$P$154,8,0) -> #VALUE!
A9: Ripley | B9: Plaza Oeste | C9: 1650337 | D9: 1485303.3 | E9: 1336773 | F9: 1203095.7 | G9: =SUMIF($C$2:$F$2,EOMONTH(G$2,-1)+1,$C9:$F9)*VLOOKUP(G$2,Valores!$H$2:$P$154,8,0) -> 47524.926 | H9: =SUMIF($C$2:$F$2,EOMONTH(H$2,-1)+1,$C9:$F9)*VLOOKUP(H$2,Valores!$H$2:$P$154,8,0) -> 32588.521 | I9: =SUMIF($C$2:$F$2,EOMONTH(I$2,-1)+1,$C9:$F9)*VLOOKUP(I$2,Valores!$H$2:$P$154,8,0) -> 32588.521 | J9: =SUMIF($C$2:$F$2,EOMONTH(J$2,-1)+1,$C9:$F9)*VLOOKUP(J$2,Valores!$H$2:$P$154,8,0) -> 32588.521 | K9: =SUMIF($C$2:$F$2,EOMONTH(K$2,-1)+1,$C9:$F9)*VLOOKUP(K$2,Valores!$H$2:$P$154,8,0) -> 32588.521 | L9: =SUMIF($C$2:$F$2,EOMONTH(L$2,-1)+1,$C9:$F9)*VLOOKUP(L$2,Valores!$H$2:$P$154,8,0) -> 65177.041 | M9: =SUMIF($C$2:$F$2,EOMONTH(M$2,-1)+1,$C9:$F9)*VLOOKUP(M$2,Valores!$H$2:$P$154,8,0) -> 81471.302 | N9: =SUMIF($C$2:$F$2,EOMONTH(N$2,-1)+1,$C9:$F9)*VLOOKUP(N$2,Valores!$H$2:$P$154,8,0) -> 48882.781 | ... DX9: =SUMIF($C$2:$F$2,EOMONTH(DX$2,-1)+1,$C9:$F9)*VLOOKUP(DX$2,Valores!$H$2:$P$154,8,0) -> #VALUE!
A10: Ripley | B10: Arica | C10: 1605177 | D10: 1444659.3 | E10: 1300193.4 | F10: 1170174 | G10: =SUMIF($C$2:$F$2,EOMONTH(G$2,-1)+1,$C10:$F10)*VLOOKUP(G$2,Valores!$H$2:$P$154,8,0) -> 46224.449 | H10: =SUMIF($C$2:$F$2,EOMONTH(H$2,-1)+1,$C10:$F10)*VLOOKUP(H$2,Valores!$H$2:$P$154,8,0) -> 31696.765 | I10: =SUMIF($C$2:$F$2,EOMONTH(I$2,-1)+1,$C10:$F10)*VLOOKUP(I$2,Valores!$H$2:$P$154,8,0) -> 31696.765 | J10: =SUMIF($C$2:$F$2,EOMONTH(J$2,-1)+1,$C10:$F10)*VLOOKUP(J$2,Valores!$H$2:$P$154,8,0) -> 31696.765 | K10: =SUMIF($C$2:$F$2,EOMONTH(K$2,-1)+1,$C10:$F10)*VLOOKUP(K$2,Valores!$H$2:$P$154,8,0) -> 31696.765 | L10: =SUMIF($C$2:$F$2,EOMONTH(L$2,-1)+1,$C10:$F10)*VLOOKUP(L$2,Valores!$H$2:$P$154,8,0) -> 63393.53 | M10: =SUMIF($C$2:$F$2,EOMONTH(M$2,-1)+1,$C10:$F10)*VLOOKUP(M$2,Valores!$H$2:$P$154,8,0) -> 79241.912 | N10: =SUMIF($C$2:$F$2,EOMONTH(N$2,-1)+1,$C10:$F10)*VLOOKUP(N$2,Valores!$H$2:$P$154,8,0) -> 47545.147 | ... DX10: =SUMIF($C$2:$F$2,EOMONTH(DX$2,-1)+1,$C10:$F10)*VLOOKUP(DX$2,Valores!$H$2:$P$154,8,0) -> #VALUE!
A11: Ripley | B11: Copiapo | C11: 1512890 | D11: 1361601 | E11: 1225440.9 | F11: 1102896.8 | G11: =SUMIF($C$2:$F$2,EOMONTH(G$2,-1)+1,$C11:$F11)*VLOOKUP(G$2,Valores!$H$2:$P$154,8,0) -> 43566.85 | H11: =SUMIF($C$2:$F$2,EOMONTH(H$2,-1)+1,$C11:$F11)*VLOOKUP(H$2,Valores!$H$2:$P$154,8,0) -> 29874.412 | I11: =SUMIF($C$2:$F$2,EOMONTH(I$2,-1)+1,$C11:$F11)*VLOOKUP(I$2,Valores!$H$2:$P$154,8,0) -> 29874.412 | J11: =SUMIF($C$2:$F$2,EOMONTH(J$2,-1)+1,$C11:$F11)*VLOOKUP(J$2,Valores!$H$2:$P$154,8,0) -> 29874.412 | K11: =SUMIF($C$2:$F$2,EOMONTH(K$2,-1)+1,$C11:$F11)*VLOOKUP(K$2,Valores!$H$2:$P$154,8,0) -> 29874.412 | L11: =SUMIF($C$2:$F$2,EOMONTH(L$2,-1)+1,$C11:$F11)*VLOOKUP(L$2,Valores!$H$2:$P$154,8,0) -> 59748.823 | M11: =SUMIF($C$2:$F$2,EOMONTH(M$2,-1)+1,$C11:$F11)*VLOOKUP(M$2,Valores!$H$2:$P$154,8,0) -> 74686.029 | N11: =SUMIF($C$2:$F$2,EOMONTH(N$2,-1)+1,$C11:$F11)*VLOOKUP(N$2,Valores!$H$2:$P$154,8,0) -> 44811.618 | ... DX11: =SUMIF($C$2:$F$2,EOMONTH(DX$2,-1)+1,$C11:$F11)*VLOOKUP(DX$2,Valores!$H$2:$P$154,8,0) -> #VALUE!
A12: Ripley | B12: Antofagasta | C12: 1711581 | D12: 1540422.9 | E12: 1386380.6 | F12: 1247742.5 | G12: =SUMIF($C$2:$F$2,EOMONTH(G$2,-1)+1,$C12:$F12)*VLOOKUP(G$2,Valores!$H$2:$P$154,8,0) -> 49288.576 | H12: =SUMIF($C$2:$F$2,EOMONTH(H$2,-1)+1,$C12:$F12)*VLOOKUP(H$2,Valores!$H$2:$P$154,8,0) -> 33797.881 | I12: =SUMIF($C$2:$F$2,EOMONTH(I$2,-1)+1,$C12:$F12)*VLOOKUP(I$2,Valores!$H$2:$P$154,8,0) -> 33797.881 | J12: =SUMIF($C$2:$F$2,EOMONTH(J$2,-1)+1,$C12:$F12)*VLOOKUP(J$2,Valores!$H$2:$P$154,8,0) -> 33797.881 | K12: =SUMIF($C$2:$F$2,EOMONTH(K$2,-1)+1,$C12:$F12)*VLOOKUP(K$2,Valores!$H$2:$P$154,8,0) -> 33797.881 | L12: =SUMIF($C$2:$F$2,EOMONTH(L$2,-1)+1,$C12:$F12)*VLOOKUP(L$2,Valores!$H$2:$P$154,8,0) -> 67595.761 | M12: =SUMIF($C$2:$F$2,EOMONTH(M$2,-1)+1,$C12:$F12)*VLOOKUP(M$2,Valores!$H$2:$P$154,8,0) -> 84494.701 | N12: =SUMIF($C$2:$F$2,EOMONTH(N$2,-1)+1,$C12:$F12)*VLOOKUP(N$2,Valores!$H$2:$P$154,8,0) -> 50696.821 | ... DX12: =SUMIF($C$2:$F$2,EOMONTH(DX$2,-1)+1,$C12:$F12)*VLOOKUP(DX$2,Valores!$H$2:$P$154,8,0) -> #VALUE!
A13: Ripley | B13: Mall Concepcion | C13: 1379235 | D13: 1241311.5 | E13: 1117180.4 | F13: 1005462.3 | G13: =SUMIF($C$2:$F$2,EOMONTH(G$2,-1)+1,$C13:$F13)*VLOOKUP(G$2,Valores!$H$2:$P$154,8,0) -> 39717.974 | H13: =SUMIF($C$2:$F$2,EOMONTH(H$2,-1)+1,$C13:$F13)*VLOOKUP(H$2,Valores!$H$2:$P$154,8,0) -> 27235.182 | I13: =SUMIF($C$2:$F$2,EOMONTH(I$2,-1)+1,$C13:$F13)*VLOOKUP(I$2,Valores!$H$2:$P$154,8,0) -> 27235.182 | J13: =SUMIF($C$2:$F$2,EOMONTH(J$2,-1)+1,$C13:$F13)*VLOOKUP(J$2,Valores!$H$2:$P$154,8,0) -> 27235.182 | K13: =SUMIF($C$2:$F$2,EOMONTH(K$2,-1)+1,$C13:$F13)*VLOOKUP(K$2,Valores!$H$2:$P$154,8,0) -> 27235.182 | L13: =SUMIF($C$2:$F$2,EOMONTH(L$2,-1)+1,$C13:$F13)*VLOOKUP(L$2,Valores!$H$2:$P$154,8,0) -> 54470.364 | M13: =SUMIF($C$2:$F$2,EOMONTH(M$2,-1)+1,$C13:$F13)*VLOOKUP(M$2,Valores!$H$2:$P$154,8,0) -> 68087.955 | N13: =SUMIF($C$2:$F$2,EOMONTH(N$2,-1)+1,$C13:$F13)*VLOOKUP(N$2,Valores!$H$2:$P$154,8,0) -> 40852.773 | ... DX13: =SUMIF($C$2:$F$2,EOMONTH(DX$2,-1)+1,$C13:$F13)*VLOOKUP(DX$2,Valores!$H$2:$P$154,8,0) -> #VALUE!
A14: Ripley | B14: Rancagua | C14: 1286417 | D14: 1157775.3 | E14: 1041997.8 | F14: 937797.99 | G14: =SUMIF($C$2:$F$2,EOMONTH(G$2,-1)+1,$C14:$F14)*VLOOKUP(G$2,Valores!$H$2:$P$154,8,0) -> 37045.084 | H14: =SUMIF($C$2:$F$2,EOMONTH(H$2,-1)+1,$C14:$F14)*VLOOKUP(H$2,Valores!$H$2:$P$154,8,0) -> 25402.343 | I14: =SUMIF($C$2:$F$2,EOMONTH(I$2,-1)+1,$C14:$F14)*VLOOKUP(I$2,Valores!$H$2:$P$154,8,0) -> 25402.343 | J14: =SUMIF($C$2:$F$2,EOMONTH(J$2,-1)+1,$C14:$F14)*VLOOKUP(J$2,Valores!$H$2:$P$154,8,0) -> 25402.343 | K14: =SUMIF($C$2:$F$2,EOMONTH(K$2,-1)+1,$C14:$F14)*VLOOKUP(K$2,Valores!$H$2:$P$154,8,0) -> 25402.343 | L14: =SUMIF($C$2:$F$2,EOMONTH(L$2,-1)+1,$C14:$F14)*VLOOKUP(L$2,Valores!$H$2:$P$154,8,0) -> 50804.687 | M14: =SUMIF($C$2:$F$2,EOMONTH(M$2,-1)+1,$C14:$F14)*VLOOKUP(M$2,Valores!$H$2:$P$154,8,0) -> 63505.858 | N14: =SUMIF($C$2:$F$2,EOMONTH(N$2,-1)+1,$C14:$F14)*VLOOKUP(N$2,Valores!$H$2:$P$154,8,0) -> 38103.515 | ... DX14: =SUMIF($C$2:$F$2,EOMONTH(DX$2,-1)+1,$C14:$F14)*VLOOKUP(DX$2,Valores!$H$2:$P$154,8,0) -> #VALUE!
... A94: Johnson | B94: Johnson Linares | C94: 340004 | D94: 306003.6 | E94: 275403.24 | F94: 247862.92 | G94: =SUMIF($C$2:$F$2,EOMONTH(G$2,-1)+1,$C94:$F94)*VLOOKUP(G$2,Valores!$H$2:$P$154,8,0) -> 9791.1305 | H94: =SUMIF($C$2:$F$2,EOMONTH(H$2,-1)+1,$C94:$F94)*VLOOKUP(H$2,Valores!$H$2:$P$154,8,0) -> 6713.9181 | I94: =SUMIF($C$2:$F$2,EOMONTH(I$2,-1)+1,$C94:$F94)*VLOOKUP(I$2,Valores!$H$2:$P$154,8,0) -> 6713.9181 | J94: =SUMIF($C$2:$F$2,EOMONTH(J$2,-1)+1,$C94:$F94)*VLOOKUP(J$2,Valores!$H$2:$P$154,8,0) -> 6713.9181 | K94: =SUMIF($C$2:$F$2,EOMONTH(K$2,-1)+1,$C94:$F94)*VLOOKUP(K$2,Valores!$H$2:$P$154,8,0) -> 6713.9181 | L94: =SUMIF($C$2:$F$2,EOMONTH(L$2,-1)+1,$C94:$F94)*VLOOKUP(L$2,Valores!$H$2:$P$154,8,0) -> 13427.836 | M94: =SUMIF($C$2:$F$2,EOMONTH(M$2,-1)+1,$C94:$F94)*VLOOKUP(M$2,Valores!$H$2:$P$154,8,0) -> 16784.795 | N94: =SUMIF($C$2:$F$2,EOMONTH(N$2,-1)+1,$C94:$F94)*VLOOKUP(N$2,Valores!$H$2:$P$154,8,0) -> 10070.877 | ... DX94: =SUMIF($C$2:$F$2,EOMONTH(DX$2,-1)+1,$C94:$F94)*VLOOKUP(DX$2,Valores!$H$2:$P$154,8,0) -> #VALUE!
G95: =SUMIF($C$2:$F$2,EOMONTH(G$2,-1)+1,$C95:$F95)*VLOOKUP(G$2,Valores!$H$2:$P$154,8,0) -> 0 | H95: =SUMIF($C$2:$F$2,EOMONTH(H$2,-1)+1,$C95:$F95)*VLOOKUP(H$2,Valores!$H$2:$P$154,8,0) -> 0 | I95: =SUMIF($C$2:$F$2,EOMONTH(I$2,-1)+1,$C95:$F95)*VLOOKUP(I$2,Valores!$H$2:$P$154,8,0) -> 0 | J95: =SUMIF($C$2:$F$2,EOMONTH(J$2,-1)+1,$C95:$F95)*VLOOKUP(J$2,Valores!$H$2:$P$154,8,0) -> 0 | K95: =SUMIF($C$2:$F$2,EOMONTH(K$2,-1)+1,$C95:$F95)*VLOOKUP(K$2,Valores!$H$2:$P$154,8,0) -> 0 | L95: =SUMIF($C$2:$F$2,EOMONTH(L$2,-1)+1,$C95:$F95)*VLOOKUP(L$2,Valores!$H$2:$P$154,8,0) -> 0 | M95: =SUMIF($C$2:$F$2,EOMONTH(M$2,-1)+1,$C95:$F95)*VLOOKUP(M$2,Valores!$H$2:$P$154,8,0) -> 0 | N95: =SUMIF($C$2:$F$2,EOMONTH(N$2,-1)+1,$C95:$F95)*VLOOKUP(N$2,Valores!$H$2:$P$154,8,0) -> 0 | ... DX95: =SUMIF($C$2:$F$2,EOMONTH(DX$2,-1)+1,$C95:$F95)*VLOOKUP(DX$2,Valores!$H$2:$P$154,8,0) -> #VALUE!
G96: =SUMIF($C$2:$F$2,EOMONTH(G$2,-1)+1,$C96:$F96)*VLOOKUP(G$2,Valores!$H$2:$P$154,8,0) -> 0 | H96: =SUMIF($C$2:$F$2,EOMONTH(H$2,-1)+1,$C96:$F96)*VLOOKUP(H$2,Valores!$H$2:$P$154,8,0) -> 0 | I96: =SUMIF($C$2:$F$2,EOMONTH(I$2,-1)+1,$C96:$F96)*VLOOKUP(I$2,Valores!$H$2:$P$154,8,0) -> 0 | J96: =SUMIF($C$2:$F$2,EOMONTH(J$2,-1)+1,$C96:$F96)*VLOOKUP(J$2,Valores!$H$2:$P$154,8,0) -> 0 | K96: =SUMIF($C$2:$F$2,EOMONTH(K$2,-1)+1,$C96:$F96)*VLOOKUP(K$2,Valores!$H$2:$P$154,8,0) -> 0 | L96: =SUMIF($C$2:$F$2,EOMONTH(L$2,-1)+1,$C96:$F96)*VLOOKUP(L$2,Valores!$H$2:$P$154,8,0) -> 0 | M96: =SUMIF($C$2:$F$2,EOMONTH(M$2,-1)+1,$C96:$F96)*VLOOKUP(M$2,Valores!$H$2:$P$154,8,0) -> 0 | N96: =SUMIF($C$2:$F$2,EOMONTH(N$2,-1)+1,$C96:$F96)*VLOOKUP(N$2,Valores!$H$2:$P$154,8,0) -> 0 | ... DX96: =SUMIF($C$2:$F$2,EOMONTH(DX$2,-1)+1,$C96:$F96)*VLOOKUP(DX$2,Valores!$H$2:$P$154,8,0) -> #VALUE!
G97: =SUMIF($C$2:$F$2,EOMONTH(G$2,-1)+1,$C97:$F97)*VLOOKUP(G$2,Valores!$H$2:$P$154,8,0) -> 0 | H97: =SUMIF($C$2:$F$2,EOMONTH(H$2,-1)+1,$C97:$F97)*VLOOKUP(H$2,Valores!$H$2:$P$154,8,0) -> 0 | I97: =SUMIF($C$2:$F$2,EOMONTH(I$2,-1)+1,$C97:$F97)*VLOOKUP(I$2,Valores!$H$2:$P$154,8,0) -> 0 | J97: =SUMIF($C$2:$F$2,EOMONTH(J$2,-1)+1,$C97:$F97)*VLOOKUP(J$2,Valores!$H$2:$P$154,8,0) -> 0 | K97: =SUMIF($C$2:$F$2,EOMONTH(K$2,-1)+1,$C97:$F97)*VLOOKUP(K$2,Valores!$H$2:$P$154,8,0) -> 0 | L97: =SUMIF($C$2:$F$2,EOMONTH(L$2,-1)+1,$C97:$F97)*VLOOKUP(L$2,Valores!$H$2:$P$154,8,0) -> 0 | M97: =SUMIF($C$2:$F$2,EOMONTH(M$2,-1)+1,$C97:$F97)*VLOOKUP(M$2,Valores!$H$2:$P$154,8,0) -> 0 | N97: =SUMIF($C$2:$F$2,EOMONTH(N$2,-1)+1,$C97:$F97)*VLOOKUP(N$2,Valores!$H$2:$P$154,8,0) -> 0 | ... DX97: =SUMIF($C$2:$F$2,EOMONTH(DX$2,-1)+1,$C97:$F97)*VLOOKUP(DX$2,Valores!$H$2:$P$154,8,0) -> #VALUE!
G98: =SUMIF($C$2:$F$2,EOMONTH(G$2,-1)+1,$C98:$F98)*VLOOKUP(G$2,Valores!$H$2:$P$154,8,0) -> 0 | H98: =SUMIF($C$2:$F$2,EOMONTH(H$2,-1)+1,$C98:$F98)*VLOOKUP(H$2,Valores!$H$2:$P$154,8,0) -> 0 | I98: =SUMIF($C$2:$F$2,EOMONTH(I$2,-1)+1,$C98:$F98)*VLOOKUP(I$2,Valores!$H$2:$P$154,8,0) -> 0 | J98: =SUMIF($C$2:$F$2,EOMONTH(J$2,-1)+1,$C98:$F98)*VLOOKUP(J$2,Valores!$H$2:$P$154,8,0) -> 0 | K98: =SUMIF($C$2:$F$2,EOMONTH(K$2,-1)+1,$C98:$F98)*VLOOKUP(K$2,Valores!$H$2:$P$154,8,0) -> 0 | L98: =SUMIF($C$2:$F$2,EOMONTH(L$2,-1)+1,$C98:$F98)*VLOOKUP(L$2,Valores!$H$2:$P$154,8,0) -> 0 | M98: =SUMIF($C$2:$F$2,EOMONTH(M$2,-1)+1,$C98:$F98)*VLOOKUP(M$2,Valores!$H$2:$P$154,8,0) -> 0 | N98: =SUMIF($C$2:$F$2,EOMONTH(N$2,-1)+1,$C98:$F98)*VLOOKUP(N$2,Valores!$H$2:$P$154,8,0) -> 0 | ... DX98: =SUMIF($C$2:$F$2,EOMONTH(DX$2,-1)+1,$C98:$F98)*VLOOKUP(DX$2,Valores!$H$2:$P$154,8,0) -> #VALUE!
G99: =SUMIF($C$2:$F$2,EOMONTH(G$2,-1)+1,$C99:$F99)*VLOOKUP(G$2,Valores!$H$2:$P$154,8,0) -> 0 | H99: =SUMIF($C$2:$F$2,EOMONTH(H$2,-1)+1,$C99:$F99)*VLOOKUP(H$2,Valores!$H$2:$P$154,8,0) -> 0 | I99: =SUMIF($C$2:$F$2,EOMONTH(I$2,-1)+1,$C99:$F99)*VLOOKUP(I$2,Valores!$H$2:$P$154,8,0) -> 0 | J99: =SUMIF($C$2:$F$2,EOMONTH(J$2,-1)+1,$C99:$F99)*VLOOKUP(J$2,Valores!$H$2:$P$154,8,0) -> 0 | K99: =SUMIF($C$2:$F$2,EOMONTH(K$2,-1)+1,$C99:$F99)*VLOOKUP(K$2,Valores!$H$2:$P$154,8,0) -> 0 | L99: =SUMIF($C$2:$F$2,EOMONTH(L$2,-1)+1,$C99:$F99)*VLOOKUP(L$2,Valores!$H$2:$P$154,8,0) -> 0 | M99: =SUMIF($C$2:$F$2,EOMONTH(M$2,-1)+1,$C99:$F99)*VLOOKUP(M$2,Valores!$H$2:$P$154,8,0) -> 0 | N99: =SUMIF($C$2:$F$2,EOMONTH(N$2,-1)+1,$C99:$F99)*VLOOKUP(N$2,Valores!$H$2:$P$154,8,0) -> 0 | ... DX99: =SUMIF($C$2:$F$2,EOMONTH(DX$2,-1)+1,$C99:$F99)*VLOOKUP(DX$2,Valores!$H$2:$P$154,8,0) -> #VALUE!
G100: =SUMIF($C$2:$F$2,EOMONTH(G$2,-1)+1,$C100:$F100)*VLOOKUP(G$2,Valores!$H$2:$P$154,8,0) -> 0 | H100: =SUMIF($C$2:$F$2,EOMONTH(H$2,-1)+1,$C100:$F100)*VLOOKUP(H$2,Valores!$H$2:$P$154,8,0) -> 0 | I100: =SUMIF($C$2:$F$2,EOMONTH(I$2,-1)+1,$C100:$F100)*VLOOKUP(I$2,Valores!$H$2:$P$154,8,0) -> 0 | J100: =SUMIF($C$2:$F$2,EOMONTH(J$2,-1)+1,$C100:$F100)*VLOOKUP(J$2,Valores!$H$2:$P$154,8,0) -> 0 | K100: =SUMIF($C$2:$F$2,EOMONTH(K$2,-1)+1,$C100:$F100)*VLOOKUP(K$2,Valores!$H$2:$P$154,8,0) -> 0 | L100: =SUMIF($C$2:$F$2,EOMONTH(L$2,-1)+1,$C100:$F100)*VLOOKUP(L$2,Valores!$H$2:$P$154,8,0) -> 0 | M100: =SUMIF($C$2:$F$2,EOMONTH(M$2,-1)+1,$C100:$F100)*VLOOKUP(M$2,Valores!$H$2:$P$154,8,0) -> 0 | N100: =SUMIF($C$2:$F$2,EOMONTH(N$2,-1)+1,$C100:$F100)*VLOOKUP(N$2,Valores!$H$2:$P$154,8,0) -> 0 | ... DX100: =SUMIF($C$2:$F$2,EOMONTH(DX$2,-1)+1,$C100:$F100)*VLOOKUP(DX$2,Valores!$H$2:$P$154,8,0) -> #VALUE!
G101: =SUMIF($C$2:$F$2,EOMONTH(G$2,-1)+1,$C101:$F101)*VLOOKUP(G$2,Valores!$H$2:$P$154,8,0) -> 0 | H101: =SUMIF($C$2:$F$2,EOMONTH(H$2,-1)+1,$C101:$F101)*VLOOKUP(H$2,Valores!$H$2:$P$154,8,0) -> 0 | I101: =SUMIF($C$2:$F$2,EOMONTH(I$2,-1)+1,$C101:$F101)*VLOOKUP(I$2,Valores!$H$2:$P$154,8,0) -> 0 | J101: =SUMIF($C$2:$F$2,EOMONTH(J$2,-1)+1,$C101:$F101)*VLOOKUP(J$2,Valores!$H$2:$P$154,8,0) -> 0 | K101: =SUMIF($C$2:$F$2,EOMONTH(K$2,-1)+1,$C101:$F101)*VLOOKUP(K$2,Valores!$H$2:$P$154,8,0) -> 0 | L101: =SUMIF($C$2:$F$2,EOMONTH(L$2,-1)+1,$C101:$F101)*VLOOKUP(L$2,Valores!$H$2:$P$154,8,0) -> 0 | M101: =SUMIF($C$2:$F$2,EOMONTH(M$2,-1)+1,$C101:$F101)*VLOOKUP(M$2,Valores!$H$2:$P$154,8,0) -> 0 | N101: =SUMIF($C$2:$F$2,EOMONTH(N$2,-1)+1,$C101:$F101)*VLOOKUP(N$2,Valores!$H$2:$P$154,8,0) -> 0 | ... DX101: =SUMIF($C$2:$F$2,EOMONTH(DX$2,-1)+1,$C101:$F101)*VLOOKUP(DX$2,Valores!$H$2:$P$154,8,0) -> #VALUE!
G102: =SUMIF($C$2:$F$2,EOMONTH(G$2,-1)+1,$C102:$F102)*VLOOKUP(G$2,Valores!$H$2:$P$154,8,0) -> 0 | H102: =SUMIF($C$2:$F$2,EOMONTH(H$2,-1)+1,$C102:$F102)*VLOOKUP(H$2,Valores!$H$2:$P$154,8,0) -> 0 | I102: =SUMIF($C$2:$F$2,EOMONTH(I$2,-1)+1,$C102:$F102)*VLOOKUP(I$2,Valores!$H$2:$P$154,8,0) -> 0 | J102: =SUMIF($C$2:$F$2,EOMONTH(J$2,-1)+1,$C102:$F102)*VLOOKUP(J$2,Valores!$H$2:$P$154,8,0) -> 0 | K102: =SUMIF($C$2:$F$2,EOMONTH(K$2,-1)+1,$C102:$F102)*VLOOKUP(K$2,Valores!$H$2:$P$154,8,0) -> 0 | L102: =SUMIF($C$2:$F$2,EOMONTH(L$2,-1)+1,$C102:$F102)*VLOOKUP(L$2,Valores!$H$2:$P$154,8,0) -> 0 | M102: =SUMIF($C$2:$F$2,EOMONTH(M$2,-1)+1,$C102:$F102)*VLOOKUP(M$2,Valores!$H$2:$P$154,8,0) -> 0 | N102: =SUMIF($C$2:$F$2,EOMONTH(N$2,-1)+1,$C102:$F102)*VLOOKUP(N$2,Valores!$H$2:$P$154,8,0) -> 0 | ... DX102: =SUMIF($C$2:$F$2,EOMONTH(DX$2,-1)+1,$C102:$F102)*VLOOKUP(DX$2,Valores!$H$2:$P$154,8,0) -> #VALUE!
G103: =SUMIF($C$2:$F$2,EOMONTH(G$2,-1)+1,$C103:$F103)*VLOOKUP(G$2,Valores!$H$2:$P$154,8,0) -> 0 | H103: =SUMIF($C$2:$F$2,EOMONTH(H$2,-1)+1,$C103:$F103)*VLOOKUP(H$2,Valores!$H$2:$P$154,8,0) -> 0 | I103: =SUMIF($C$2:$F$2,EOMONTH(I$2,-1)+1,$C103:$F103)*VLOOKUP(I$2,Valores!$H$2:$P$154,8,0) -> 0 | J103: =SUMIF($C$2:$F$2,EOMONTH(J$2,-1)+1,$C103:$F103)*VLOOKUP(J$2,Valores!$H$2:$P$154,8,0) -> 0 | K103: =SUMIF($C$2:$F$2,EOMONTH(K$2,-1)+1,$C103:$F103)*VLOOKUP(K$2,Valores!$H$2:$P$154,8,0) -> 0 | L103: =SUMIF($C$2:$F$2,EOMONTH(L$2,-1)+1,$C103:$F103)*VLOOKUP(L$2,Valores!$H$2:$P$154,8,0) -> 0 | M103: =SUMIF($C$2:$F$2,EOMONTH(M$2,-1)+1,$C103:$F103)*VLOOKUP(M$2,Valores!$H$2:$P$154,8,0) -> 0 | N103: =SUMIF($C$2:$F$2,EOMONTH(N$2,-1)+1,$C103:$F103)*VLOOKUP(N$2,Valores!$H$2:$P$154,8,0) -> 0 | ... DX103: =SUMIF($C$2:$F$2,EOMONTH(DX$2,-1)+1,$C103:$F103)*VLOOKUP(DX$2,Valores!$H$2:$P$154,8,0) -> #VALUE!
G104: =SUMIF($C$2:$F$2,EOMONTH(G$2,-1)+1,$C104:$F104)*VLOOKUP(G$2,Valores!$H$2:$P$154,8,0) -> 0 | H104: =SUMIF($C$2:$F$2,EOMONTH(H$2,-1)+1,$C104:$F104)*VLOOKUP(H$2,Valores!$H$2:$P$154,8,0) -> 0 | I104: =SUMIF($C$2:$F$2,EOMONTH(I$2,-1)+1,$C104:$F104)*VLOOKUP(I$2,Valores!$H$2:$P$154,8,0) -> 0 | J104: =SUMIF($C$2:$F$2,EOMONTH(J$2,-1)+1,$C104:$F104)*VLOOKUP(J$2,Valores!$H$2:$P$154,8,0) -> 0 | K104: =SUMIF($C$2:$F$2,EOMONTH(K$2,-1)+1,$C104:$F104)*VLOOKUP(K$2,Valores!$H$2:$P$154,8,0) -> 0 | L104: =SUMIF($C$2:$F$2,EOMONTH(L$2,-1)+1,$C104:$F104)*VLOOKUP(L$2,Valores!$H$2:$P$154,8,0) -> 0 | M104: =SUMIF($C$2:$F$2,EOMONTH(M$2,-1)+1,$C104:$F104)*VLOOKUP(M$2,Valores!$H$2:$P$154,8,0) -> 0 | N104: =SUMIF($C$2:$F$2,EOMONTH(N$2,-1)+1,$C104:$F104)*VLOOKUP(N$2,Valores!$H$2:$P$154,8,0) -> 0 | ... DX104: =SUMIF($C$2:$F$2,EOMONTH(DX$2,-1)+1,$C104:$F104)*VLOOKUP(DX$2,Valores!$H$2:$P$154,8,0) -> #VALUE!
G105: =SUMIF($C$2:$F$2,EOMONTH(G$2,-1)+1,$C105:$F105)*VLOOKUP(G$2,Valores!$H$2:$P$154,8,0) -> 0 | H105: =SUMIF($C$2:$F$2,EOMONTH(H$2,-1)+1,$C105:$F105)*VLOOKUP(H$2,Valores!$H$2:$P$154,8,0) -> 0 | I105: =SUMIF($C$2:$F$2,EOMONTH(I$2,-1)+1,$C105:$F105)*VLOOKUP(I$2,Valores!$H$2:$P$154,8,0) -> 0 | J105: =SUMIF($C$2:$F$2,EOMONTH(J$2,-1)+1,$C105:$F105)*VLOOKUP(J$2,Valores!$H$2:$P$154,8,0) -> 0 | K105: =SUMIF($C$2:$F$2,EOMONTH(K$2,-1)+1,$C105:$F105)*VLOOKUP(K$2,Valores!$H$2:$P$154,8,0) -> 0 | L105: =SUMIF($C$2:$F$2,EOMONTH(L$2,-1)+1,$C105:$F105)*VLOOKUP(L$2,Valores!$H$2:$P$154,8,0) -> 0 | M105: =SUMIF($C$2:$F$2,EOMONTH(M$2,-1)+1,$C105:$F105)*VLOOKUP(M$2,Valores!$H$2:$P$154,8,0) -> 0 | N105: =SUMIF($C$2:$F$2,EOMONTH(N$2,-1)+1,$C105:$F105)*VLOOKUP(N$2,Valores!$H$2:$P$154,8,0) -> 0 | ... DX105: =SUMIF($C$2:$F$2,EOMONTH(DX$2,-1)+1,$C105:$F105)*VLOOKUP(DX$2,Valores!$H$2:$P$154,8,0) -> #VALUE!
G106: =SUMIF($C$2:$F$2,EOMONTH(G$2,-1)+1,$C106:$F106)*VLOOKUP(G$2,Valores!$H$2:$P$154,8,0) -> 0 | H106: =SUMIF($C$2:$F$2,EOMONTH(H$2,-1)+1,$C106:$F106)*VLOOKUP(H$2,Valores!$H$2:$P$154,8,0) -> 0 | I106: =SUMIF($C$2:$F$2,EOMONTH(I$2,-1)+1,$C106:$F106)*VLOOKUP(I$2,Valores!$H$2:$P$154,8,0) -> 0 | J106: =SUMIF($C$2:$F$2,EOMONTH(J$2,-1)+1,$C106:$F106)*VLOOKUP(J$2,Valores!$H$2:$P$154,8,0) -> 0 | K106: =SUMIF($C$2:$F$2,EOMONTH(K$2,-1)+1,$C106:$F106)*VLOOKUP(K$2,Valores!$H$2:$P$154,8,0) -> 0 | L106: =SUMIF($C$2:$F$2,EOMONTH(L$2,-1)+1,$C106:$F106)*VLOOKUP(L$2,Valores!$H$2:$P$154,8,0) -> 0 | M106: =SUMIF($C$2:$F$2,EOMONTH(M$2,-1)+1,$C106:$F106)*VLOOKUP(M$2,Valores!$H$2:$P$154,8,0) -> 0 | N106: =SUMIF($C$2:$F$2,EOMONTH(N$2,-1)+1,$C106:$F106)*VLOOKUP(N$2,Valores!$H$2:$P$154,8,0) -> 0 | ... DX106: =SUMIF($C$2:$F$2,EOMONTH(DX$2,-1)+1,$C106:$F106)*VLOOKUP(DX$2,Valores!$H$2:$P$154,8,0) -> #VALUE!
... G163: =SUMIF($C$2:$F$2,EOMONTH(G$2,-1)+1,$C163:$F163)*VLOOKUP(G$2,Valores!$H$2:$P$154,8,0) -> 0 | H163: =SUMIF($C$2:$F$2,EOMONTH(H$2,-1)+1,$C163:$F163)*VLOOKUP(H$2,Valores!$H$2:$P$154,8,0) -> 0 | I163: =SUMIF($C$2:$F$2,EOMONTH(I$2,-1)+1,$C163:$F163)*VLOOKUP(I$2,Valores!$H$2:$P$154,8,0) -> 0 | J163: =SUMIF($C$2:$F$2,EOMONTH(J$2,-1)+1,$C163:$F163)*VLOOKUP(J$2,Valores!$H$2:$P$154,8,0) -> 0 | K163: =SUMIF($C$2:$F$2,EOMONTH(K$2,-1)+1,$C163:$F163)*VLOOKUP(K$2,Valores!$H$2:$P$154,8,0) -> 0 | L163: =SUMIF($C$2:$F$2,EOMONTH(L$2,-1)+1,$C163:$F163)*VLOOKUP(L$2,Valores!$H$2:$P$154,8,0) -> 0 | M163: =SUMIF($C$2:$F$2,EOMONTH(M$2,-1)+1,$C163:$F163)*VLOOKUP(M$2,Valores!$H$2:$P$154,8,0) -> 0 | N163: =SUMIF($C$2:$F$2,EOMONTH(N$2,-1)+1,$C163:$F163)*VLOOKUP(N$2,Valores!$H$2:$P$154,8,0) -> 0 | ... DX163: =SUMIF($C$2:$F$2,EOMONTH(DX$2,-1)+1,$C163:$F163)*VLOOKUP(DX$2,Valores!$H$2:$P$154,8,0) -> #VALUE!
